File: inner experiment data/Mn3.2/2-4-4.txt
#EXPORTTYPE:DATA SINGLE
#FILE:B&D.ngb-sla
#FORMAT:NETZSCH5
#FTYPE:ANSI
#IDENTITY:B
#DECIMAL:POINT
#SEPARATOR:SEMICOLON
#MTYPE:DIL
#INSTRUMENT:NETZSCH DIL 402SE
#PROJECT:1
#DATE/TIME:10.12.2019 16:07
#CORR. FILE:
#TEMPCAL:TCALZERO.TMX
#LABORATORY:1
#OPERATOR:1
#REMARK:
#SAMPLE:B
#SAMPLE LENGTH /mm:16.56
#MATERIAL:Ã’¥…
#MEASMODE:Standard Expansion
#M.RANGE /¶Ãm:20000
#CORR. CODE:010
#RANGE:-110°„C/5.0(K/min)/200°„C
#SEGMENT:S1/1
#SEG. 1:-110°„C/5.0(K/min)/200°„C

##Temp./°„C	Time/min	dL/Lo
-100	2.14097	-8.90067E-05
-99.8	2.17909	-8.79969E-05
-99.6	2.21719	-8.69959E-05
-99.4	2.25541	-8.57184E-05
-99.2	2.29369	-8.48058E-05
-99	2.33216	-8.35393E-05
-98.8	2.37079	-8.26045E-05
-98.6	2.40959	-8.09695E-05
-98.4	2.44866	-7.98785E-05
-98.2	2.48796	-7.8337E-05
-98	2.52744	-7.70916E-05
-97.8	2.56718	-7.56678E-05
-97.6	2.60723	-7.42241E-05
-97.4	2.64741	-7.26797E-05
-97.2	2.68779	-7.12398E-05
-97	2.72824	-6.94755E-05
-96.8	2.76886	-6.79977E-05
-96.6	2.80961	-6.6331E-05
-96.4	2.85043	-6.46337E-05
-96.2	2.89132	-6.28853E-05
-96	2.93228	-6.12607E-05
-95.8	2.97321	-5.92781E-05
-95.6	3.01404	-5.8166E-05
-95.4	3.05489	-5.63387E-05
-95.2	3.09571	-5.41269E-05
-95	3.13653	-5.22202E-05
-94.8	3.1772	-5.0976E-05
-94.6	3.21786	-4.85393E-05
-94.4	3.25839	-4.63765E-05
-94.2	3.29885	-4.44309E-05
-94	3.33923	-4.25548E-05
-93.8	3.37957	-4.05946E-05
-93.6	3.4199	-3.86827E-05
-93.4	3.46019	-3.65172E-05
-93.2	3.50044	-3.45054E-05
-93	3.54069	-3.25322E-05
-92.8	3.58095	-3.04591E-05
-92.6	3.62119	-2.83078E-05
-92.4	3.6615	-2.60883E-05
-92.2	3.70183	-2.40827E-05
-92	3.74213	-2.18087E-05
-91.8	3.78247	-1.9701E-05
-91.6	3.82285	-1.73891E-05
-91.4	3.86317	-1.54053E-05
-91.2	3.90354	-1.30183E-05
-91	3.94385	-1.08258E-05
-90.8	3.98419	-8.37066E-06
-90.6	4.02452	-6.23507E-06
-90.4	4.06483	-3.92026E-06
-90.2	4.1051	-1.65984E-06
-90	4.14535	8.26321E-07
-89.8	4.18556	2.90937E-06
-89.6	4.22575	5.47462E-06
-89.4	4.26593	7.72033E-06
-89.2	4.30607	1.02672E-05
-89	4.34619	1.24061E-05
-88.8	4.38629	1.48976E-05
-88.6	4.42637	1.73289E-05
-88.4	4.46638	1.9749E-05
-88.2	4.50639	2.20593E-05
-88	4.54638	2.46055E-05
-87.8	4.58636	2.7094E-05
-87.6	4.62631	2.93302E-05
-87.4	4.66621	3.18223E-05
-87.2	4.70611	3.42981E-05
-87	4.74598	3.67171E-05
-86.8	4.78584	3.90111E-05
-86.6	4.82571	4.17972E-05
-86.4	4.86555	4.41357E-05
-86.2	4.90535	4.65776E-05
-86	4.94517	4.89235E-05
-85.8	4.98495	5.14308E-05
-85.6	5.02468	5.38205E-05
-85.4	5.06445	5.64108E-05
-85.2	5.10417	5.87778E-05
-85	5.14387	6.15318E-05
-84.8	5.18355	6.38531E-05
-84.6	5.22322	6.63939E-05
-84.4	5.26281	6.8829E-05
-84.2	5.30241	7.14658E-05
-84	5.34196	7.38734E-05
-83.8	5.3815	7.65495E-05
-83.6	5.42102	7.89357E-05
-83.4	5.46055	8.15368E-05
-83.2	5.50005	8.39291E-05
-83	5.53954	8.65421E-05
-82.8	5.57904	8.91206E-05
-82.6	5.61852	9.16006E-05
-82.4	5.65801	9.42221E-05
-82.2	5.69748	9.65948E-05
-82	5.73697	9.92406E-05
-81.8	5.77645	0.000101712
-81.6	5.81587	0.000104387
-81.4	5.85537	0.000106797
-81.2	5.89486	0.000109502
-81	5.93437	0.000111871
-80.8	5.97388	0.00011456
-80.6	6.01337	0.000116783
-80.4	6.05286	0.000119547
-80.2	6.09237	0.000121888
-80	6.13185	0.000124486
-79.8	6.17138	0.00012701
-79.6	6.2109	0.00012964
-79.4	6.25042	0.000131942
-79.2	6.28989	0.000134725
-79	6.32929	0.000137091
-78.8	6.3687	0.000139812
-78.6	6.40809	0.000142075
-78.4	6.44749	0.000144831
-78.2	6.4869	0.000147126
-78	6.52629	0.000149723
-77.8	6.5657	0.000152261
-77.6	6.60508	0.000154857
-77.4	6.64445	0.000157364
-77.2	6.68379	0.000159758
-77	6.72316	0.000162434
-76.8	6.76253	0.000164857
-76.6	6.80191	0.000167427
-76.4	6.84129	0.000169824
-76.2	6.88067	0.00017241
-76	6.92003	0.000174927
-75.8	6.95937	0.000177502
-75.6	6.99869	0.000180021
-75.4	7.03804	0.000182587
-75.2	7.07742	0.00018512
-75	7.11683	0.000187655
-74.8	7.1562	0.000190108
-74.6	7.1956	0.000192592
-74.4	7.23497	0.00019512
-74.2	7.27438	0.000197708
-74	7.31377	0.000200189
-73.8	7.35321	0.000202673
-73.6	7.39265	0.000205205
-73.4	7.43207	0.000207639
-73.2	7.47149	0.000210213
-73	7.51092	0.000212517
-72.8	7.55036	0.000215221
-72.6	7.58977	0.000217563
-72.4	7.62919	0.00022017
-72.2	7.66859	0.000222592
-72	7.70801	0.000225078
-71.8	7.74742	0.000227475
-71.6	7.78683	0.000230066
-71.4	7.82627	0.000232353
-71.2	7.86565	0.000235046
-71	7.90504	0.000237482
-70.8	7.94443	0.000239965
-70.6	7.98381	0.000242449
-70.4	8.02318	0.000244891
-70.2	8.06262	0.000247488
-70	8.102	0.000249839
-69.8	8.14138	0.000252409
-69.6	8.18072	0.000254813
-69.4	8.22011	0.000257506
-69.2	8.25953	0.000259717
-69	8.29895	0.000262459
-68.8	8.33837	0.00026468
-68.6	8.37784	0.000267392
-68.4	8.41736	0.000269813
-68.2	8.45687	0.000272436
-68	8.49637	0.000274788
-67.8	8.53596	0.000277395
-67.6	8.57556	0.000279845
-67.4	8.61515	0.00028241
-67.2	8.65473	0.000284813
-67	8.69434	0.000287358
-66.8	8.73391	0.00028989
-66.6	8.77351	0.000292502
-66.4	8.81313	0.000294683
-66.2	8.85275	0.000297465
-66	8.89234	0.000299775
-65.8	8.93192	0.000302418
-65.6	8.97148	0.000304748
-65.4	9.01109	0.0003074
-65.2	9.05069	0.000309621
-65	9.09024	0.00031224
-64.8	9.12981	0.000314708
-64.6	9.16936	0.000317472
-64.4	9.20889	0.000319762
-64.2	9.24841	0.000322582
-64	9.28793	0.000325031
-63.8	9.32751	0.00032771
-63.6	9.36707	0.000330123
-63.4	9.40666	0.000332921
-63.2	9.44621	0.000335461
-63	9.48587	0.000338098
-62.8	9.52555	0.000340681
-62.6	9.5652	0.000343525
-62.4	9.60488	0.000345951
-62.2	9.64457	0.000348545
-62	9.68427	0.000351266
-61.8	9.72396	0.000354038
-61.6	9.76369	0.00035657
-61.4	9.80336	0.000359246
-61.2	9.8431	0.000361966
-61	9.8828	0.000364754
-60.8	9.92247	0.00036719
-60.6	9.96216	0.000369895
-60.4	10.00183	0.000372608
-60.2	10.04149	0.000375312
-60	10.08111	0.000377875
-59.8	10.1207	0.000380592
-59.6	10.16027	0.000383267
-59.4	10.19988	0.000385994
-59.2	10.23945	0.000388716
-59	10.27899	0.000391323
-58.8	10.31856	0.000393811
-58.6	10.35813	0.000396608
-58.4	10.39767	0.000399246
-58.2	10.43726	0.000401753
-58	10.47682	0.000404465
-57.8	10.5165	0.000407291
-57.6	10.55613	0.000410019
-57.4	10.59575	0.000412665
-57.2	10.6354	0.000415244
-57	10.67503	0.000417965
-56.8	10.71469	0.000420656
-56.6	10.7543	0.000423293
-56.4	10.79393	0.000425909
-56.2	10.83355	0.000428652
-56	10.87315	0.000431314
-55.8	10.91277	0.000434068
-55.6	10.95237	0.000436571
-55.4	10.99194	0.000439321
-55.2	11.03153	0.000442072
-55	11.07112	0.000444728
-54.8	11.1107	0.000447318
-54.6	11.15028	0.000449937
-54.4	11.18981	0.000452698
-54.2	11.22937	0.00045536
-54	11.26896	0.000458046
-53.8	11.30851	0.000460744
-53.6	11.34807	0.000463446
-53.4	11.38764	0.000466043
-53.2	11.42718	0.000468772
-53	11.46677	0.000471385
-52.8	11.50632	0.000474056
-52.6	11.54593	0.000476622
-52.4	11.58558	0.000479228
-52.2	11.62522	0.000481935
-52	11.66484	0.000484587
-51.8	11.70449	0.000487155
-51.6	11.74413	0.000489924
-51.4	11.78381	0.000492504
-51.2	11.82353	0.00049524
-51	11.86323	0.00049776
-50.8	11.90291	0.000500563
-50.6	11.94257	0.000502946
-50.4	11.98224	0.000505719
-50.2	12.02188	0.000508156
-50	12.0615	0.000511059
-49.8	12.10112	0.000513488
-49.6	12.1407	0.000516318
-49.4	12.18026	0.000518732
-49.2	12.2198	0.000521482
-49	12.2593	0.000524031
-48.8	12.29879	0.0005268
-48.6	12.33827	0.000529169
-48.4	12.37776	0.000531872
-48.2	12.41719	0.000534389
-48	12.45666	0.000537244
-47.8	12.49614	0.000539591
-47.6	12.53564	0.000542284
-47.4	12.57518	0.000544929
-47.2	12.61473	0.00054761
-47	12.65429	0.000550117
-46.8	12.69392	0.000552789
-46.6	12.7336	0.000555302
-46.4	12.77329	0.000557932
-46.2	12.81301	0.000560381
-46	12.85278	0.000562956
-45.8	12.89257	0.000565463
-45.6	12.93233	0.000568057
-45.4	12.97211	0.000570736
-45.2	13.0119	0.000573257
-45	13.0517	0.000575826
-44.8	13.09145	0.000578488
-44.6	13.13115	0.000581029
-44.4	13.17088	0.000583509
-44.2	13.21055	0.000586154
-44	13.25026	0.000588705
-43.8	13.28989	0.000591301
-43.6	13.32952	0.00059372
-43.4	13.36913	0.00059645
-43.2	13.40875	0.000599003
-43	13.44836	0.000601467
-42.8	13.48795	0.000603982
-42.6	13.52758	0.000606625
-42.4	13.56719	0.000609211
-42.2	13.60679	0.000611716
-42	13.64645	0.000614286
-41.8	13.68612	0.000616846
-41.6	13.72582	0.000619313
-41.4	13.76553	0.000622061
-41.2	13.80524	0.000624564
-41	13.84492	0.000627102
-40.8	13.88467	0.000629744
-40.6	13.92439	0.000632211
-40.4	13.96411	0.000634775
-40.2	14.00385	0.000637376
-40	14.04362	0.000639855
-39.8	14.08337	0.00064265
-39.6	14.12313	0.000645062
-39.4	14.1629	0.000647716
-39.2	14.20265	0.000650191
-39	14.24242	0.000652801
-38.8	14.28217	0.000655283
-38.6	14.32191	0.000657935
-38.4	14.36164	0.000660451
-38.2	14.4014	0.00066293
-38	14.44113	0.000665382
-37.8	14.48083	0.000668079
-37.6	14.52055	0.000670658
-37.4	14.56029	0.000673238
-37.2	14.60004	0.000675819
-37	14.63978	0.000678581
-36.8	14.67955	0.000681043
-36.6	14.71935	0.000683934
-36.4	14.75917	0.000686285
-36.2	14.79893	0.000689262
-36	14.83869	0.000691607
-35.8	14.87848	0.000694441
-35.6	14.91822	0.000697019
-35.4	14.95799	0.000699954
-35.2	14.99776	0.000702366
-35	15.03753	0.000705215
-34.8	15.07731	0.000707676
-34.6	15.11704	0.000710553
-34.4	15.15679	0.000713101
-34.2	15.19652	0.000715782
-34	15.23634	0.000718471
-33.8	15.27606	0.000721197
-33.6	15.31586	0.000723887
-33.4	15.35561	0.000726739
-33.2	15.39539	0.000729149
-33	15.43514	0.000731958
-32.8	15.47491	0.000734654
-32.6	15.51468	0.000737311
-32.4	15.55446	0.000740005
-32.2	15.5942	0.000742739
-32	15.63398	0.00074535
-31.8	15.6738	0.000748114
-31.6	15.71361	0.000750783
-31.4	15.75344	0.000753433
-31.2	15.79324	0.000756248
-31	15.83304	0.000758754
-30.8	15.8728	0.000761704
-30.6	15.9126	0.000764265
-30.4	15.95236	0.000766935
-30.2	15.99215	0.000769495
-30	16.03197	0.000772262
-29.8	16.07175	0.000774807
-29.6	16.11156	0.000777595
-29.4	16.15139	0.000780277
-29.2	16.1912	0.000783085
-29	16.23106	0.000785495
-28.8	16.27091	0.000788379
-28.6	16.31082	0.000791044
-28.4	16.35073	0.000793807
-28.2	16.39069	0.000796413
-28	16.43061	0.000799101
-27.8	16.47054	0.000801702
-27.6	16.51048	0.000804534
-27.4	16.55036	0.000807022
-27.2	16.59031	0.00080974
-27	16.63026	0.000812401
-26.8	16.67019	0.000815008
-26.6	16.71015	0.000817669
-26.4	16.75002	0.000820394
-26.2	16.78993	0.00082297
-26	16.82986	0.000825647
-25.8	16.86975	0.000828156
-25.6	16.90963	0.00083084
-25.4	16.94951	0.000833396
-25.2	16.98936	0.000836194
-25	17.02918	0.000838676
-24.8	17.06903	0.000841321
-24.6	17.10889	0.000843867
-24.4	17.14876	0.000846611
-24.2	17.18859	0.000849128
-24	17.2284	0.000851774
-23.8	17.26822	0.000854309
-23.6	17.30811	0.000857026
-23.4	17.34795	0.000859515
-23.2	17.38786	0.000862055
-23	17.42779	0.000864659
-22.8	17.46768	0.000867447
-22.6	17.50755	0.000869753
-22.4	17.54743	0.000872477
-22.2	17.58736	0.000875012
-22	17.62731	0.00087781
-21.8	17.66725	0.000880229
-21.6	17.70718	0.000882904
-21.4	17.74714	0.000885329
-21.2	17.78715	0.000888004
-21	17.82713	0.00089043
-20.8	17.86713	0.000893226
-20.6	17.90712	0.000895718
-20.4	17.94716	0.000898282
-20.2	17.98716	0.000900886
-20	18.02718	0.000903318
-19.8	18.06716	0.00090599
-19.6	18.10712	0.000908485
-19.4	18.14709	0.000911029
-19.2	18.18701	0.000913584
-19	18.22696	0.000916011
-18.8	18.26685	0.000918378
-18.6	18.30676	0.000921227
-18.4	18.34662	0.000923593
-18.2	18.38647	0.000926259
-18	18.42634	0.00092856
-17.8	18.46617	0.000931289
-17.6	18.50598	0.000933652
-17.4	18.54576	0.0009362
-17.2	18.58557	0.000938564
-17	18.62534	0.000941341
-16.8	18.66512	0.000943629
-16.6	18.70485	0.000946179
-16.4	18.74465	0.00094865
-16.2	18.78446	0.000951494
-16	18.82429	0.000953686
-15.8	18.86411	0.000956218
-15.6	18.90401	0.000958609
-15.4	18.94393	0.000961337
-15.2	18.98389	0.00096372
-15	19.02388	0.000966327
-14.8	19.0639	0.000968782
-14.6	19.10395	0.000971468
-14.4	19.14401	0.000973699
-14.2	19.18407	0.000976378
-14	19.22408	0.000978888
-13.8	19.26415	0.000981577
-13.6	19.30418	0.000983885
-13.4	19.34421	0.000986459
-13.2	19.38421	0.000989
-13	19.42417	0.000991538
-12.8	19.46412	0.000994079
-12.6	19.50406	0.000996519
-12.4	19.54398	0.000999094
-12.2	19.58391	0.001001485
-12	19.62384	0.001004073
-11.8	19.66378	0.001006585
-11.6	19.70365	0.001009085
-11.4	19.74352	0.001011388
-11.2	19.78337	0.001014042
-11	19.8232	0.001016307
-10.8	19.86305	0.001018878
-10.6	19.90291	0.001021254
-10.4	19.94277	0.001023903
-10.2	19.9826	0.001026191
-10	20.02245	0.001028732
-9.8	20.06226	0.001031239
-9.6	20.10212	0.001033865
-9.4	20.142	0.001036461
-9.2	20.18187	0.001038863
-9	20.22178	0.001041445
-8.8	20.26169	0.00104399
-8.6	20.30157	0.001046559
-8.4	20.34151	0.00104913
-8.2	20.38147	0.001051817
-8	20.42144	0.001054435
-7.8	20.4614	0.001057015
-7.6	20.50135	0.001059424
-7.4	20.54132	0.001062133
-7.2	20.5813	0.001064724
-7	20.62127	0.001067373
-6.8	20.66122	0.001069787
-6.6	20.7012	0.001072586
-6.4	20.74113	0.001075063
-6.2	20.78106	0.001077557
-6	20.82097	0.001080106
-5.8	20.8609	0.001082842
-5.6	20.90082	0.001085392
-5.4	20.94074	0.00108791
-5.2	20.98064	0.00109035
-5	21.02053	0.001093075
-4.8	21.06044	0.001095588
-4.6	21.10034	0.001098194
-4.4	21.14026	0.00110069
-4.2	21.18017	0.001103253
-4	21.22009	0.001105906
-3.8	21.26002	0.001108225
-3.6	21.29998	0.001110936
-3.4	21.33991	0.001113385
-3.2	21.37985	0.001116093
-3	21.41981	0.001118417
-2.8	21.45974	0.001121063
-2.6	21.4997	0.001123543
-2.4	21.53969	0.001126253
-2.2	21.57967	0.00112865
-2	21.61963	0.001131258
-1.8	21.65956	0.001133661
-1.6	21.69952	0.001136409
-1.4	21.73945	0.001138715
-1.2	21.7794	0.001141366
-1	21.81935	0.001143789
-0.8	21.85935	0.001146503
-0.6	21.89931	0.001148874
-0.4	21.93923	0.001151501
-0.2	21.97917	0.001153768
0	22.01907	0.001156535
0.2	22.05897	0.001158896
0.4	22.09887	0.001161476
0.6	22.13878	0.001163862
0.8	22.17872	0.001166371
1	22.21863	0.001168948
1.2	22.25849	0.00117147
1.4	22.29844	0.001173894
1.6	22.3384	0.001176412
1.8	22.37835	0.001178926
2	22.41833	0.001181357
2.2	22.45836	0.001183839
2.4	22.49838	0.001186323
2.6	22.53841	0.001188794
2.8	22.57845	0.00119126
3	22.61852	0.00119373
3.2	22.65864	0.001196279
3.4	22.6987	0.001198805
3.6	22.73875	0.00120113
3.8	22.77882	0.001203607
4	22.81887	0.001206008
4.2	22.85889	0.001208664
4.4	22.89887	0.001210905
4.6	22.93888	0.001213489
4.8	22.97881	0.001215924
5	23.01871	0.001218484
5.2	23.05858	0.001220631
5.4	23.09843	0.001223316
5.6	23.13826	0.001225728
5.8	23.17806	0.001228155
6	23.21789	0.001230359
6.2	23.25773	0.00123285
6.4	23.29757	0.001235312
6.6	23.33739	0.001237749
6.8	23.37723	0.001240017
7	23.41707	0.001242526
7.2	23.45691	0.001244991
7.4	23.49675	0.001247326
7.6	23.53662	0.001249794
7.8	23.5765	0.00125214
8	23.61637	0.001254603
8.2	23.65623	0.001256779
8.4	23.69608	0.001259356
8.6	23.73601	0.00126168
8.8	23.77594	0.001264246
9	23.8159	0.001266449
9.2	23.85588	0.00126895
9.4	23.89586	0.001271149
9.6	23.9358	0.001273692
9.8	23.9758	0.001275772
10	24.01578	0.001278236
10.2	24.05578	0.001280441
10.4	24.09576	0.001282907
10.6	24.13571	0.001285078
10.8	24.17565	0.001287539
11	24.21558	0.001289906
11.2	24.25549	0.001292086
11.4	24.29546	0.001294362
11.6	24.33542	0.001296837
11.8	24.37535	0.001299018
12	24.41529	0.001301354
12.2	24.45524	0.001303708
12.4	24.49519	0.001305765
12.6	24.53512	0.001308355
12.8	24.57504	0.00131051
13	24.61498	0.001312885
13.2	24.65491	0.001315099
13.4	24.69483	0.001317489
13.6	24.73476	0.001319694
13.8	24.77469	0.001321993
14	24.81458	0.001324211
14.2	24.85449	0.001326659
14.4	24.89438	0.001328785
14.6	24.93433	0.001331167
14.8	24.97425	0.001333253
15	25.01422	0.00133576
15.2	25.0542	0.001337785
15.4	25.09417	0.001340355
15.6	25.13415	0.001342318
15.8	25.17417	0.001344708
16	25.21419	0.001346903
16.2	25.25424	0.00134918
16.4	25.29431	0.001351329
16.6	25.33436	0.00135367
16.8	25.37443	0.001355816
17	25.41448	0.001358207
17.2	25.45449	0.001360281
17.4	25.49446	0.001362683
17.6	25.53442	0.001364763
17.8	25.57438	0.001367094
18	25.61431	0.001369168
18.2	25.65425	0.001371434
18.4	25.69419	0.001373753
18.6	25.73411	0.001375966
18.8	25.774	0.001377981
19	25.81392	0.001380125
19.2	25.85386	0.001382392
19.4	25.89382	0.001384541
19.6	25.93378	0.001386922
19.8	25.97375	0.001389073
20	26.01373	0.001391458
20.2	26.05374	0.00139361
20.4	26.09372	0.001395993
20.6	26.13374	0.001398084
20.8	26.17377	0.001400538
21	26.21374	0.001402623
21.2	26.25371	0.00140495
21.4	26.29371	0.001407098
21.6	26.33379	0.001409611
21.8	26.37382	0.001411699
22	26.41387	0.001413971
22.2	26.45389	0.001416243
22.4	26.4939	0.001418581
22.6	26.53391	0.001420781
22.8	26.5739	0.001423113
23	26.61393	0.001425381
23.2	26.65399	0.00142766
23.4	26.694	0.001429923
23.6	26.734	0.001432143
23.8	26.77402	0.001434532
24	26.81398	0.001436678
24.2	26.85394	0.001439
24.4	26.89391	0.001441035
24.6	26.93383	0.0014436
24.8	26.97375	0.001445502
25	27.01368	0.001447949
25.2	27.05362	0.001450034
25.4	27.09355	0.001452426
25.6	27.13342	0.001454508
25.8	27.17331	0.001456832
26	27.2132	0.001459038
26.2	27.25319	0.001461366
26.4	27.29317	0.001463394
26.6	27.33316	0.001465666
26.8	27.37317	0.001467755
27	27.4132	0.001470087
27.2	27.4532	0.001472178
27.4	27.49321	0.00147451
27.6	27.53326	0.001476785
27.8	27.57329	0.001478936
28	27.61329	0.001481088
28.2	27.65332	0.001483181
28.4	27.69333	0.001485332
28.6	27.73333	0.001487664
28.8	27.77335	0.001489815
29	27.81336	0.001491908
29.2	27.85335	0.001494178
29.4	27.89337	0.001496331
29.6	27.93338	0.001498422
29.8	27.9734	0.001500635
30	28.01341	0.001502726
30.2	28.05338	0.001504818
30.4	28.09333	0.001506965
30.6	28.13329	0.001508995
30.8	28.17326	0.001511448
31	28.21322	0.001513235
31.2	28.25318	0.001515747
31.4	28.29313	0.001517594
31.6	28.33309	0.001519806
31.8	28.37306	0.001521773
32	28.41299	0.001523982
32.2	28.45296	0.001526011
32.4	28.49294	0.001528285
32.6	28.53295	0.001530199
32.8	28.57293	0.00153241
33	28.61295	0.001534386
33.2	28.65293	0.001536532
33.4	28.69298	0.001538389
33.6	28.73296	0.00154066
33.8	28.77297	0.001542632
34	28.81295	0.001544724
34.2	28.85297	0.001546639
34.4	28.89296	0.00154879
34.6	28.93297	0.001550765
34.8	28.97302	0.001552859
35	29.01306	0.001554837
35.2	29.05313	0.001556871
35.4	29.09314	0.001558965
35.6	29.13315	0.001560874
35.8	29.1732	0.001563033
36	29.21328	0.001564888
36.2	29.25329	0.001567164
36.4	29.29333	0.001568959
36.6	29.33328	0.00157111
36.8	29.37319	0.001573139
37	29.41308	0.001575166
37.2	29.45297	0.001576954
37.4	29.49287	0.001579169
37.6	29.53277	0.001581014
37.8	29.57265	0.001583099
38	29.61257	0.001584953
38.2	29.6525	0.001587107
38.4	29.69244	0.001588959
38.6	29.73243	0.001591047
38.8	29.77241	0.001592896
39	29.8124	0.001595107
39.2	29.85241	0.001596851
39.4	29.89238	0.001598996
39.6	29.93235	0.00160086
39.8	29.97235	0.001602945
40	30.0123	0.001604752
40.2	30.05223	0.001606767
40.4	30.09215	0.001608753
40.6	30.13206	0.001610592
40.8	30.17199	0.001612819
41	30.21191	0.001614528
41.2	30.25183	0.001616517
41.4	30.29173	0.00161853
41.6	30.33168	0.00162039
41.8	30.37159	0.001622239
42	30.4115	0.001624276
42.2	30.45144	0.001626068
42.4	30.49138	0.001627977
42.6	30.5313	0.001629778
42.8	30.57124	0.001631817
43	30.61118	0.001633617
43.2	30.6511	0.001635613
43.4	30.69102	0.001637358
43.6	30.73095	0.001639255
43.8	30.77087	0.001641153
44	30.81082	0.00164301
44.2	30.85078	0.001644853
44.4	30.89071	0.001646676
44.6	30.93068	0.001648615
44.8	30.97065	0.001650308
45	31.01061	0.00165232
45.2	31.05056	0.001654025
45.4	31.09054	0.001655908
45.6	31.13056	0.001657716
45.8	31.17057	0.001659502
46	31.21062	0.00166123
46.2	31.25066	0.001663176
46.4	31.29076	0.001664887
46.6	31.33083	0.001666891
46.8	31.3709	0.001668491
47	31.411	0.001670422
47.2	31.45104	0.001671961
47.4	31.49115	0.001673952
47.6	31.53123	0.001675697
47.8	31.5713	0.001677602
48	31.61131	0.001679108
48.2	31.65129	0.001681034
48.4	31.69126	0.001682629
48.6	31.73118	0.001684491
48.8	31.7711	0.0016861
49	31.81098	0.001688201
49.2	31.8509	0.001689687
49.4	31.89077	0.001691465
49.6	31.93063	0.001693165
49.8	31.97051	0.001694948
50	32.01038	0.001696569
50.2	32.05027	0.001698439
50.4	32.09014	0.001700061
50.6	32.13003	0.001701813
50.8	32.16995	0.001703466
51	32.20985	0.0017052
51.2	32.24974	0.001706866
51.4	32.28962	0.001708571
51.6	32.32951	0.001710194
51.8	32.3694	0.001711848
52	32.40934	0.001713608
52.2	32.44927	0.001715202
52.4	32.48922	0.001716913
52.6	32.52915	0.001718472
52.8	32.56909	0.001720273
53	32.60905	0.001721857
53.2	32.64905	0.001723506
53.4	32.68905	0.001725045
53.6	32.72904	0.001726805
53.8	32.76901	0.001728325
54	32.80896	0.001730016
54.2	32.84892	0.001731603
54.4	32.88891	0.001733341
54.6	32.92892	0.001734705
54.8	32.96894	0.001736472
55	33.00894	0.001737932
55.2	33.04889	0.001739446
55.4	33.08888	0.001741032
55.6	33.12886	0.001742591
55.8	33.16888	0.001744113
56	33.20888	0.001745716
56.2	33.24885	0.00174726
56.4	33.28882	0.00174868
56.6	33.32875	0.00175051
56.8	33.3687	0.001751877
57	33.40865	0.001753565
57.2	33.44862	0.001754905
57.4	33.48861	0.001756588
57.6	33.52858	0.001758046
57.8	33.56857	0.001759647
58	33.60857	0.001761219
58.2	33.64856	0.001762934
58.4	33.68855	0.001764275
58.6	33.72855	0.001765703
58.8	33.76853	0.001767214
59	33.80851	0.001768799
59.2	33.84845	0.001770202
59.4	33.88842	0.001771751
59.6	33.9284	0.001773146
59.8	33.96835	0.001774839
60	34.0083	0.001776325
60.2	34.04828	0.001777667
60.4	34.08826	0.001779144
60.6	34.12829	0.001780688
60.8	34.1683	0.001782033
61	34.20831	0.00178354
61.2	34.24835	0.001785052
61.4	34.28839	0.001786537
61.6	34.3284	0.00178779
61.8	34.36847	0.001789339
62	34.4085	0.001790771
62.2	34.44856	0.001792213
62.4	34.48861	0.00179359
62.6	34.52863	0.001794988
62.8	34.56864	0.001796454
63	34.60864	0.001797748
63.2	34.64862	0.001799188
63.4	34.68859	0.001800444
63.6	34.72859	0.001801978
63.8	34.76855	0.001803291
64	34.80854	0.001804628
64.2	34.84848	0.001805896
64.4	34.88842	0.00180731
64.6	34.92838	0.001808557
64.8	34.96834	0.00181003
65	35.00828	0.00181112
65.2	35.04821	0.00181263
65.4	35.08814	0.00181369
65.6	35.12813	0.001815181
65.8	35.16814	0.0018164
66	35.2081	0.001817684
66.2	35.24814	0.001818771
66.4	35.28817	0.00182009
66.6	35.3282	0.001821334
66.8	35.36825	0.001822562
67	35.40827	0.001823616
67.2	35.44833	0.001824994
67.4	35.48843	0.001826117
67.6	35.52848	0.001827233
67.8	35.56852	0.001828352
68	35.60854	0.001829543
68.2	35.64852	0.001830854
68.4	35.68849	0.001831829
68.6	35.72845	0.001833109
68.8	35.76839	0.001834133
69	35.80833	0.001835351
69.2	35.84831	0.00183634
69.4	35.88818	0.001837544
69.6	35.92808	0.00183845
69.8	35.968	0.001839681
70	36.0079	0.001840506
70.2	36.04786	0.001841769
70.4	36.08776	0.00184263
70.6	36.12769	0.001843817
70.8	36.16767	0.001844688
71	36.20762	0.001845884
71.2	36.24758	0.001846724
71.4	36.28759	0.001847761
71.6	36.32763	0.001848693
71.8	36.36765	0.001849646
72	36.40771	0.001850681
72.2	36.44772	0.001851619
72.4	36.48775	0.001852542
72.6	36.5278	0.001853325
72.8	36.56781	0.001854352
73	36.60782	0.001855094
73.2	36.6478	0.001856065
73.4	36.68776	0.001856889
73.6	36.72774	0.001857801
73.8	36.76768	0.001858449
74	36.80766	0.001859406
74.2	36.84761	0.001860213
74.4	36.88757	0.001861116
74.6	36.92748	0.001861705
74.8	36.96743	0.00186272
75	37.00735	0.00186337
75.2	37.04732	0.00186412
75.4	37.08729	0.001864802
75.6	37.12726	0.001865579
75.8	37.16724	0.001866199
76	37.20714	0.001867
76.2	37.24707	0.001867669
76.4	37.28702	0.001868453
76.6	37.32697	0.00186904
76.8	37.36699	0.001869708
77	37.40704	0.001870334
77.2	37.44709	0.001870884
77.4	37.48716	0.001871486
77.6	37.5272	0.001872084
77.8	37.5672	0.001872631
78	37.60723	0.001873313
78.2	37.64731	0.00187395
78.4	37.68737	0.001874335
78.6	37.72746	0.001874939
78.8	37.7675	0.001875412
79	37.80751	0.001876059
79.2	37.84752	0.001876396
79.4	37.88754	0.001877042
79.6	37.92756	0.001877317
79.8	37.96764	0.001877855
80	38.00772	0.001878195
80.2	38.0477	0.001878703
80.4	38.08769	0.001879006
80.6	38.12767	0.001879591
80.8	38.16764	0.001879778
81	38.2076	0.001880268
81.2	38.24756	0.001880426
81.4	38.28747	0.001881014
81.6	38.32737	0.001881016
81.8	38.36725	0.001881496
82	38.40713	0.001881658
82.2	38.44703	0.001882058
82.4	38.48697	0.001882111
82.6	38.52687	0.001882471
82.8	38.56676	0.001882759
83	38.60669	0.001882856
83.2	38.64661	0.00188305
83.4	38.68655	0.001883225
83.6	38.72652	0.001883207
83.8	38.76652	0.001883445
84	38.80649	0.001883566			84	0.001883566
84.2	38.84646	0.001883636			56	-0.000555066	-9.91189E-06
84.4	38.88642	0.001883781
84.6	38.92642	0.001883554
84.8	38.96643	0.001883736
85	39.00644	0.001883599
85.2	39.04652	0.00188376
85.4	39.08664	0.001883582
85.6	39.12676	0.0018835
85.8	39.16685	0.001883441
86	39.20698	0.001883459
86.2	39.24711	0.001883047
86.4	39.28725	0.001883134
86.6	39.32735	0.001882801
86.8	39.36742	0.001882758
87	39.4075	0.001882497
87.2	39.44756	0.001882482
87.4	39.48755	0.001882256
87.6	39.52752	0.001881899
87.8	39.56751	0.001881636
88	39.60749	0.001881256
88.2	39.64744	0.00188102
88.4	39.68741	0.001880593
88.6	39.72737	0.001880375
88.8	39.76736	0.001879924
89	39.8073	0.001879622
89.2	39.84726	0.001879216
89.4	39.8872	0.001878852
89.6	39.92718	0.001878369
89.8	39.96716	0.001878045
90	40.00707	0.001877372
90.2	40.047	0.001877062
90.4	40.08693	0.001876416
90.6	40.12682	0.001875953
90.8	40.16666	0.001875211
91	40.20659	0.001874818
91.2	40.24647	0.001873991
91.4	40.28637	0.001873574
91.6	40.3263	0.001872822
91.8	40.36622	0.001872157
92	40.40617	0.001871262
92.2	40.44611	0.001870619
92.4	40.48607	0.001869865
92.6	40.52603	0.001869169
92.8	40.56605	0.001868331
93	40.60605	0.001867494
93.2	40.64604	0.001866606
93.4	40.68601	0.001865784
93.6	40.7259	0.001864842
93.8	40.76582	0.001863925
94	40.80573	0.001862991
94.2	40.8457	0.001862109
94.4	40.88569	0.001861061
94.6	40.92564	0.001860102
94.8	40.96561	0.001859072
95	41.00559	0.001857981
95.2	41.04558	0.001856915
95.4	41.08557	0.001855703
95.6	41.12562	0.001854743
95.8	41.16567	0.001853528
96	41.20568	0.001852319
96.2	41.24568	0.001851113
96.4	41.28566	0.001850035
96.6	41.32564	0.001848663
96.8	41.36566	0.001847449
97	41.40566	0.001845955
97.2	41.44571	0.001844796
97.4	41.48577	0.001843333
97.6	41.5258	0.001842053
97.8	41.56585	0.001840606
98	41.6059	0.001839315
98.2	41.64597	0.0018378
98.4	41.68606	0.001836321
98.6	41.72615	0.001834598
98.8	41.7662	0.001833323
99	41.80625	0.001831631
99.2	41.84628	0.001830013
99.4	41.88627	0.001828392
99.6	41.92628	0.001826891
99.8	41.96626	0.001825045
100	42.00622	0.001823532
100.2	42.04616	0.001821723
100.4	42.08609	0.001819981
100.6	42.12601	0.001818211
100.8	42.16594	0.001816468
101	42.20585	0.001814759
101.2	42.24578	0.001812875
101.4	42.28572	0.001811104
101.6	42.32563	0.001809115
101.8	42.3656	0.001807464
102	42.40559	0.001805373
102.2	42.44556	0.001803535
102.4	42.48554	0.001801501
102.6	42.52557	0.001799751
102.8	42.56559	0.001797646
103	42.60564	0.001795705
103.2	42.6457	0.001793644
103.4	42.68571	0.001791713
103.6	42.72572	0.001789654
103.8	42.76575	0.001787689
104	42.80575	0.001785562
104.2	42.84577	0.001783457
104.4	42.88575	0.001781391
104.6	42.9257	0.00177921
104.8	42.96563	0.001777212
105	43.00556	0.001774988
105.2	43.04548	0.001772833
105.4	43.08544	0.001770744
105.6	43.12542	0.001768465
105.8	43.16537	0.001766053
106	43.20526	0.00176401
106.2	43.24523	0.001761425
106.4	43.28516	0.001759223
106.6	43.32513	0.00175678
106.8	43.36509	0.001754609
107	43.405	0.001752024
107.2	43.44497	0.00174972
107.4	43.48492	0.001747257
107.6	43.5249	0.001744895
107.8	43.56486	0.001742313
108	43.60489	0.001739822
108.2	43.64494	0.001737165
108.4	43.685	0.001734686
108.6	43.72505	0.001732124
108.8	43.76511	0.00172951
109	43.80519	0.001726883
109.2	43.84525	0.001724234
109.4	43.88527	0.00172158
109.6	43.92529	0.001718955
109.8	43.96531	0.001716284
110	44.00533	0.00171349
110.2	44.04526	0.001710738
110.4	44.08519	0.001707943
110.6	44.12512	0.001705295
110.8	44.16501	0.001702517
111	44.20495	0.001699301
111.2	44.24489	0.001695795
111.4	44.28482	0.001693228
111.6	44.32473	0.001690261
111.8	44.36462	0.00168743
112	44.40449	0.001684337
112.2	44.44442	0.001681619
112.4	44.48437	0.001678636
112.6	44.52435	0.001675792
112.8	44.56433	0.001672562
113	44.60432	0.001669714
113.2	44.64433	0.001666591
113.4	44.68435	0.00166371
113.6	44.72441	0.001660415
113.8	44.76449	0.001657517
114	44.80458	0.001654323
114.2	44.84468	0.001651196
114.4	44.88472	0.001648061
114.6	44.92484	0.00164505
114.8	44.96493	0.001641943
115	45.00504	0.001638763
115.2	45.04516	0.001635539
115.4	45.08526	0.00163238
115.6	45.12538	0.001629217
115.8	45.16552	0.001625966
116	45.20561	0.001622717
116.2	45.24571	0.0016195
116.4	45.28582	0.001616438
116.6	45.32589	0.001613132
116.8	45.36593	0.00160997
117	45.40593	0.001606637
117.2	45.44588	0.001603553
117.4	45.48581	0.00160015
117.6	45.52572	0.001597006
117.8	45.5656	0.001593645
118	45.60548	0.001590539
118.2	45.64533	0.001587107
118.4	45.68518	0.001583839
118.6	45.72507	0.001580497
118.8	45.76495	0.001577312
119	45.80484	0.001573869
119.2	45.84476	0.001570617
119.4	45.8847	0.001567166
119.6	45.92463	0.001563889
119.8	45.96457	0.001560587
120	46.00451	0.001557169
120.2	46.04448	0.00155386
120.4	46.08447	0.001550438
120.6	46.1244	0.001547162
120.8	46.16436	0.001543697
121	46.20431	0.001540546
121.2	46.24427	0.001537155
121.4	46.2842	0.001533817
121.6	46.32417	0.001530406
121.8	46.36415	0.0015272
122	46.40416	0.001523833
122.2	46.44414	0.001520526
122.4	46.48411	0.001517027
122.6	46.52412	0.001513923
122.8	46.56413	0.001510468
123	46.60413	0.001507144
123.2	46.64414	0.001503672
123.4	46.68416	0.001500406
123.6	46.72419	0.001497041
123.8	46.76422	0.001493742
124	46.8042	0.001490514
124.2	46.84422	0.00148754
124.4	46.88422	0.001484211
124.6	46.92426	0.001481045
124.8	46.96429	0.001477975
125	47.0043	0.001474875
125.2	47.04431	0.001471807
125.4	47.08433	0.001468779
125.6	47.12432	0.001465739
125.8	47.16433	0.001462849
126	47.20434	0.001459949
126.2	47.24433	0.001456872
126.4	47.28434	0.001453986
126.6	47.3243	0.001451152
126.8	47.36429	0.001448426
127	47.40424	0.001445284
127.2	47.44422	0.00144264
127.4	47.48418	0.001439711
127.6	47.52415	0.001436886
127.8	47.56407	0.001434029
128	47.60403	0.001431364
128.2	47.64399	0.001428511
128.4	47.68391	0.001425815
128.6	47.72382	0.001422992
128.8	47.76374	0.001420469
129	47.80367	0.001417765
129.2	47.84364	0.001415276
129.4	47.88358	0.001412558
129.6	47.92356	0.001410129
129.8	47.96354	0.001407613
130	48.00351	0.001404994
130.2	48.0435	0.001402467
130.4	48.08349	0.001400004
130.6	48.12353	0.001397527
130.8	48.16355	0.001395365
131	48.20357	0.001392814
131.2	48.24357	0.001390453
131.4	48.28357	0.00138821
131.6	48.32355	0.001385814
131.8	48.36355	0.001383568
132	48.4035	0.001381314
132.2	48.44348	0.001379294
132.4	48.48343	0.00137707
132.6	48.52339	0.001375049
132.8	48.56331	0.001372929
133	48.60325	0.001370967
133.2	48.64318	0.001368772
133.4	48.68311	0.001367003
133.6	48.72306	0.001365062
133.8	48.76304	0.001363332
134	48.80303	0.001361299
134.2	48.84298	0.001359539
134.4	48.88296	0.001357811
134.6	48.92296	0.001356206
134.8	48.96296	0.001354408
135	49.00296	0.001352872
135.2	49.04298	0.001351295
135.4	49.083	0.001349763
135.6	49.12305	0.001348209
135.8	49.16306	0.001346839
136	49.20308	0.001345511
136.2	49.24314	0.001343896
136.4	49.28318	0.00134273
136.6	49.32326	0.001341344
136.8	49.36331	0.001340451
137	49.40338	0.001339157
137.2	49.44344	0.001338064
137.4	49.48349	0.00133697
137.6	49.52352	0.001336156
137.8	49.56358	0.001335018
138	49.60361	0.001334254
138.2	49.64363	0.001333426
138.4	49.68364	0.001332742
138.6	49.72362	0.001331844
138.8	49.76363	0.001331207
139	49.80362	0.001330578
139.2	49.84362	0.001330208
139.4	49.88364	0.00132966
139.6	49.92366	0.001329182
139.8	49.96367	0.001328752
140	50.00369	0.0013285
140.2	50.04372	0.001328235
140.4	50.08374	0.001328044
140.6	50.12377	0.001327981
140.8	50.16375	0.001327844
141	50.20371	0.001327732
141.2	50.24367	0.001327892
141.4	50.28363	0.00132798
141.6	50.32358	0.00132817
141.8	50.3635	0.001328467
142	50.40344	0.001328628
142.2	50.44331	0.001329057
142.4	50.48326	0.001329492
142.6	50.52319	0.001330055
142.8	50.56309	0.001330533
143	50.60307	0.001331293
143.2	50.64304	0.00133181
143.4	50.68301	0.001332672
143.6	50.72301	0.001333338
143.8	50.76305	0.001334317
144	50.80308	0.001335054
144.2	50.84317	0.001336122
144.4	50.88325	0.001337024
144.6	50.92332	0.001338273
144.8	50.96345	0.001339383
145	51.00361	0.001340726
145.2	51.04372	0.001341824
145.4	51.08385	0.001343285
145.6	51.12396	0.001344603
145.8	51.16404	0.001346263
146	51.20411	0.001347589
146.2	51.24418	0.00134931
146.4	51.28427	0.001350827
146.6	51.32431	0.001352571
146.8	51.36435	0.001354271
147	51.40437	0.00135608
147.2	51.44437	0.001357975
147.4	51.48438	0.001359913
147.6	51.52439	0.001361723
147.8	51.56438	0.001363567
148	51.60438	0.001365727
148.2	51.64434	0.001367692
148.4	51.68421	0.001369892
148.6	51.72414	0.001371976
148.8	51.76406	0.00137415
149	51.80395	0.00137632
149.2	51.84384	0.001378712
149.4	51.88374	0.001380919
149.6	51.92362	0.001383419
149.8	51.96351	0.001385673
150	52.00338	0.001388143
150.2	52.04326	0.001390462
150.4	52.08318	0.001393261
150.6	52.12313	0.001395577
150.8	52.16303	0.001398266
151	52.203	0.001400943
151.2	52.24294	0.001403717
151.4	52.28293	0.001406463
151.6	52.32296	0.001409077
151.8	52.36304	0.001412027
152	52.40317	0.001414827
152.2	52.44332	0.001417722
152.4	52.48344	0.001420457
152.6	52.52356	0.001423505
152.8	52.56371	0.001426568
153	52.60387	0.001429565
153.2	52.64406	0.001432413
153.4	52.68422	0.001435623
153.6	52.72436	0.001438599
153.8	52.76448	0.001441762
154	52.80454	0.001444782
154.2	52.8446	0.00144806
154.4	52.88468	0.001451181
154.6	52.92474	0.001454576
154.8	52.96477	0.00145762
155	53.00476	0.001461127
155.2	53.04472	0.001464301
155.4	53.0847	0.001467706
155.6	53.12467	0.00147077
155.8	53.16458	0.00147432
156	53.20448	0.001477589
156.2	53.24437	0.001481162
156.4	53.28427	0.001484596
156.6	53.32417	0.001488258
156.8	53.36409	0.00149162
157	53.40402	0.001495327
157.2	53.44393	0.001498785
157.4	53.4838	0.001502654
157.6	53.52371	0.001506305
157.8	53.56358	0.001510086
158	53.6035	0.001513873
158.2	53.64345	0.001517674
158.4	53.68335	0.001521667
158.6	53.72325	0.001525303
158.8	53.7631	0.001529166
159	53.803	0.001533132
159.2	53.84293	0.001537141
159.4	53.88286	0.00154086
159.6	53.92282	0.001544903
159.8	53.96279	0.001548841
160	54.00274	0.001552939
160.2	54.04268	0.001556725
160.4	54.08268	0.001560966
160.6	54.12267	0.001564743
160.8	54.16272	0.001569047
161	54.20275	0.001572785
161.2	54.24277	0.001577022
161.4	54.2828	0.001581141
161.6	54.32284	0.001585303
161.8	54.36286	0.001589378
162	54.4029	0.001593627
162.2	54.44293	0.001597646
162.4	54.48297	0.001601958
162.6	54.52298	0.001605999
162.8	54.56301	0.001610259
163	54.60303	0.001614405
163.2	54.64308	0.001618669
163.4	54.6831	0.001622726
163.6	54.72316	0.001627078
163.8	54.76316	0.001631296
164	54.8032	0.001635396
164.2	54.84325	0.001639705
164.4	54.88326	0.001643846
164.6	54.92326	0.001648185
164.8	54.96325	0.001652374
165	55.00323	0.001656653
165.2	55.0432	0.001660854
165.4	55.08316	0.001665238
165.6	55.1231	0.001669484
165.8	55.16305	0.001673828
166	55.203	0.001678027
166.2	55.24292	0.001682608
166.4	55.28289	0.001686801
166.6	55.32287	0.001691122
166.8	55.36284	0.001695291
167	55.40283	0.001699904
167.2	55.44279	0.00170415
167.4	55.48279	0.001708587
167.6	55.52279	0.001712892
167.8	55.56276	0.001717451
168	55.60284	0.001721792
168.2	55.64289	0.001726193
168.4	55.68299	0.00173069
168.6	55.72302	0.001735017
168.8	55.76311	0.001739489
169	55.80317	0.001743756
169.2	55.84325	0.001748154
169.4	55.88332	0.00175256
169.6	55.92336	0.001757175
169.8	55.96343	0.001761497
170	56.00347	0.001766051
170.2	56.04349	0.001770426
170.4	56.08344	0.001774981
170.6	56.12343	0.00177925
170.8	56.16339	0.001783906
171	56.20338	0.001788248
171.2	56.24334	0.001792923
171.4	56.28327	0.001797168
171.6	56.32321	0.00180185
171.8	56.36318	0.001806329
172	56.40315	0.001810957
172.2	56.44311	0.00181532
172.4	56.4831	0.00182
172.6	56.52308	0.001824358
172.8	56.56309	0.001828995
173	56.60311	0.001833374
173.2	56.64313	0.001838065
173.4	56.68317	0.001842635
173.6	56.72321	0.001847467
173.8	56.76321	0.001852033
174	56.80321	0.001856831
174.2	56.84324	0.001861675
174.4	56.88323	0.001866462
174.6	56.92319	0.001871386
174.8	56.96316	0.001876145
175	57.00315	0.001881128
175.2	57.04314	0.00188584
175.4	57.08315	0.00189092
175.6	57.12317	0.001895638
175.8	57.16322	0.001900675
176	57.20326	0.001905559
176.2	57.24329	0.001910487
176.4	57.28332	0.001915228
176.6	57.32339	0.001920332
176.8	57.36347	0.001925121
177	57.4035	0.001930153
177.2	57.44354	0.001934902
177.4	57.48358	0.001940037
177.6	57.52362	0.00194488
177.8	57.56363	0.001949917
178	57.60366	0.001954676
178.2	57.64371	0.001959752
178.4	57.68377	0.001964712
178.6	57.72385	0.001969675
178.8	57.76391	0.001974461
179	57.80398	0.001979555
179.2	57.84404	0.001984335
179.4	57.8841	0.001989192
179.6	57.92411	0.001993988
179.8	57.96413	0.001999065
180	58.00415	0.002003825
180.2	58.04417	0.002008787
180.4	58.08411	0.002013531
180.6	58.12404	0.002018585
180.8	58.16395	0.002023342
181	58.20385	0.002028248
181.2	58.24376	0.002033099
181.4	58.28368	0.002038
181.6	58.32358	0.002043032
181.8	58.36352	0.002047693
182	58.40343	0.00205262
182.2	58.44333	0.002057421
182.4	58.48325	0.002062414
182.6	58.52316	0.002067193
182.8	58.5631	0.002072156
183	58.60304	0.002077065
183.2	58.64297	0.002081945
183.4	58.68289	0.00208665
183.6	58.72286	0.002091479
183.8	58.76284	0.002096318
184	58.80285	0.002101166
184.2	58.84288	0.002105904
184.4	58.88291	0.002110878
184.6	58.92296	0.002115677
184.8	58.96301	0.002120598
185	59.00305	0.00212539
185.2	59.04311	0.002130297
185.4	59.08317	0.002135081
185.6	59.1232	0.002140074
185.8	59.16324	0.002144805
186	59.20325	0.002149708
186.2	59.24325	0.002154598
186.4	59.28325	0.002159465
186.6	59.32328	0.002164205
186.8	59.36326	0.002169033
187	59.40328	0.002174097
187.2	59.44329	0.002178714
187.4	59.4833	0.002183507
187.6	59.5233	0.002188257
187.8	59.56333	0.002193415
188	59.60337	0.00219822
188.2	59.64337	0.002203297
188.4	59.68336	0.002208289
188.6	59.72334	0.002213511
188.8	59.76338	0.002218377
189	59.80339	0.002223452
189.2	59.84343	0.00222862
189.4	59.88349	0.002233879
189.6	59.92354	0.002238858
189.8	59.96355	0.002244077
190	60.00356	0.002249141
190.2	60.04356	0.002254531
190.4	60.08358	0.002259487
190.6	60.12358	0.002264761
190.8	60.16358	0.002269706
191	60.20358	0.002275209
191.2	60.24356	0.002279997
191.4	60.28352	0.002285207
191.6	60.32349	0.002290196
191.8	60.36346	0.002295638
192	60.40343	0.002300619
192.2	60.44341	0.002305861
192.4	60.48342	0.002310793
192.6	60.52343	0.002316164
192.8	60.56344	0.00232121
193	60.60341	0.002326418
193.2	60.64342	0.002331523
193.4	60.68343	0.002336662
193.6	60.72346	0.002341732
193.8	60.76349	0.002346874
194	60.80352	0.002351905
194.2	60.84357	0.002356674
194.4	60.88357	0.002361921
194.6	60.9236	0.002366836
194.8	60.96362	0.002371982
195	61.00369	0.002377035
195.2	61.04377	0.002382104
195.4	61.08385	0.002387112
195.6	61.12391	0.002392333
195.8	61.16397	0.002397298
196	61.20406	0.00240258
196.2	61.24416	0.002407401
196.4	61.28429	0.002412659
196.6	61.32443	0.002417706
196.8	61.36458	0.002422942
197	61.40472	0.002427796
197.2	61.44485	0.00243284
197.4	61.48498	0.00243778
197.6	61.52511	0.002442824
197.8	61.56524	0.002447835
198	61.60535	0.002452925
198.2	61.64539	0.002457788
198.4	61.68541	0.002462823
198.6	61.72541	0.002467791
198.8	61.76543	0.002472805
199	61.80539	0.002477816
199.2	61.84532	0.002482791
199.4	61.88521	0.002487795
199.6	61.92516	0.002492774
199.8	61.96533	0.002497814
199.9	61.98511	0.002500202