File: inner experiment data/Mn3.2/2-6-2.txt
#EXPORTTYPE:DATA SINGLE
#FILE:A+.ngb-sla
#FORMAT:NETZSCH5
#FTYPE:ANSI
#IDENTITY:A-2+
#DECIMAL:POINT
#SEPARATOR:SEMICOLON
#MTYPE:DIL
#INSTRUMENT:NETZSCH DIL 402SE
#PROJECT:1
#DATE/TIME:10.12.2019 13:35
#CORR. FILE:
#TEMPCAL:TCALZERO.TMX
#LABORATORY:1
#OPERATOR:1
#REMARK:
#SAMPLE:A-2+
#SAMPLE LENGTH /mm:23.75
#MATERIAL:
#MEASMODE:Standard Expansion
#M.RANGE /¶Ãm:20000
#CORR. CODE:010
#RANGE:-110°„C/5.0(K/min)/200°„C
#SEGMENT:S1/1
#SEG. 1:-110°„C/5.0(K/min)/200°„C

##Temp./°„C	Time/min	dL/Lo
-100	2.17211	-3.91048E-05
-99.8	2.20965	-3.90271E-05
-99.6	2.247	-3.9013E-05
-99.4	2.28419	-3.89664E-05
-99.2	2.3213	-3.88969E-05
-99	2.35845	-3.86954E-05
-98.8	2.39565	-3.8739E-05
-98.6	2.43296	-3.85323E-05
-98.4	2.47043	-3.84767E-05
-98.2	2.50804	-3.831E-05
-98	2.54588	-3.82301E-05
-97.8	2.58396	-3.80156E-05
-97.6	2.62232	-3.79124E-05
-97.4	2.66095	-3.77549E-05
-97.2	2.69986	-3.75184E-05
-97	2.73908	-3.73173E-05
-96.8	2.77855	-3.71613E-05
-96.6	2.81822	-3.67913E-05
-96.4	2.85808	-3.66211E-05
-96.2	2.89815	-3.62696E-05
-96	2.93843	-3.59246E-05
-95.8	2.97887	-3.56857E-05
-95.6	3.01939	-3.53331E-05
-95.4	3.06002	-3.5083E-05
-95.2	3.10075	-3.46231E-05
-95	3.14142	-3.43684E-05
-94.8	3.18211	-3.39872E-05
-94.6	3.22286	-3.36967E-05
-94.4	3.2636	-3.33224E-05
-94.2	3.30434	-3.30639E-05
-94	3.345	-3.27608E-05
-93.8	3.3856	-3.25187E-05
-93.6	3.4262	-3.22514E-05
-93.4	3.46667	-3.19043E-05
-93.2	3.50703	-3.17706E-05
-93	3.54738	-3.15956E-05
-92.8	3.58769	-3.14286E-05
-92.6	3.62786	-3.11677E-05
-92.4	3.66793	-3.10655E-05
-92.2	3.70791	-3.08556E-05
-92	3.7479	-3.06751E-05
-91.8	3.78782	-3.05056E-05
-91.6	3.82765	-3.03709E-05
-91.4	3.86749	-3.02375E-05
-91.2	3.90733	-3.0107E-05
-91	3.94707	-2.99336E-05
-90.8	3.98678	-2.97546E-05
-90.6	4.02654	-2.96215E-05
-90.4	4.06634	-2.9362E-05
-90.2	4.10616	-2.93104E-05
-90	4.14592	-2.91281E-05
-89.8	4.18572	-2.90412E-05
-89.6	4.22558	-2.88579E-05
-89.4	4.26545	-2.87755E-05
-89.2	4.30532	-2.86772E-05
-89	4.34523	-2.84589E-05
-88.8	4.38519	-2.83243E-05
-88.6	4.42515	-2.81878E-05
-88.4	4.4651	-2.80875E-05
-88.2	4.50504	-2.79548E-05
-88	4.54502	-2.79347E-05
-87.8	4.58502	-2.77173E-05
-87.6	4.62496	-2.77161E-05
-87.4	4.6649	-2.74936E-05
-87.2	4.70487	-2.73897E-05
-87	4.74478	-2.72001E-05
-86.8	4.7847	-2.71508E-05
-86.6	4.82463	-2.70057E-05
-86.4	4.86451	-2.69573E-05
-86.2	4.90438	-2.69173E-05
-86	4.94418	-2.68142E-05
-85.8	4.984	-2.67093E-05
-85.6	5.02374	-2.65962E-05
-85.4	5.06351	-2.64593E-05
-85.2	5.10321	-2.63116E-05
-85	5.1429	-2.62479E-05
-84.8	5.18252	-2.61777E-05
-84.6	5.22216	-2.60976E-05
-84.4	5.26182	-2.60137E-05
-84.2	5.30146	-2.59818E-05
-84	5.34111	-2.5825E-05
-83.8	5.38073	-2.57443E-05
-83.6	5.42041	-2.56124E-05
-83.4	5.46008	-2.55819E-05
-83.2	5.49973	-2.55155E-05
-83	5.53939	-2.54927E-05
-82.8	5.57911	-2.53347E-05
-82.6	5.61878	-2.53144E-05
-82.4	5.65846	-2.51315E-05
-82.2	5.69809	-2.50601E-05
-82	5.73773	-2.48716E-05
-81.8	5.77741	-2.48381E-05
-81.6	5.81701	-2.46767E-05
-81.4	5.85661	-2.46332E-05
-81.2	5.89621	-2.45847E-05
-81	5.93581	-2.44711E-05
-80.8	5.97541	-2.44061E-05
-80.6	6.015	-2.4252E-05
-80.4	6.05454	-2.41204E-05
-80.2	6.09407	-2.39749E-05
-80	6.13354	-2.38766E-05
-79.8	6.173	-2.36899E-05
-79.6	6.21245	-2.36715E-05
-79.4	6.25191	-2.35681E-05
-79.2	6.29133	-2.35128E-05
-79	6.33078	-2.32393E-05
-78.8	6.37022	-2.31664E-05
-78.6	6.40958	-2.30288E-05
-78.4	6.44903	-2.28101E-05
-78.2	6.48843	-2.26952E-05
-78	6.5278	-2.25501E-05
-77.8	6.56717	-2.24168E-05
-77.6	6.60656	-2.2325E-05
-77.4	6.64598	-2.21601E-05
-77.2	6.68542	-2.1955E-05
-77	6.72487	-2.17667E-05
-76.8	6.76428	-2.15354E-05
-76.6	6.80365	-2.14368E-05
-76.4	6.84305	-2.11369E-05
-76.2	6.88244	-2.09983E-05
-76	6.92194	-2.07157E-05
-75.8	6.9614	-2.06082E-05
-75.6	7.00089	-2.03367E-05
-75.4	7.04034	-2.01866E-05
-75.2	7.07978	-1.99137E-05
-75	7.11921	-1.96842E-05
-74.8	7.15869	-1.94202E-05
-74.6	7.19821	-1.92644E-05
-74.4	7.23778	-1.898E-05
-74.2	7.2773	-1.88082E-05
-74	7.31689	-1.85846E-05
-73.8	7.35645	-1.82148E-05
-73.6	7.39604	-1.80553E-05
-73.4	7.4356	-1.77168E-05
-73.2	7.47519	-1.73531E-05
-73	7.51473	-1.70008E-05
-72.8	7.55427	-1.68102E-05
-72.6	7.59384	-1.6449E-05
-72.4	7.63333	-1.62287E-05
-72.2	7.67279	-1.58646E-05
-72	7.71221	-1.55352E-05
-71.8	7.75158	-1.51354E-05
-71.6	7.79096	-1.48988E-05
-71.4	7.83033	-1.45245E-05
-71.2	7.8697	-1.40983E-05
-71	7.90908	-1.37498E-05
-70.8	7.94844	-1.34079E-05
-70.6	7.98781	-1.3054E-05
-70.4	8.02714	-1.2604E-05
-70.2	8.06654	-1.22854E-05
-70	8.10594	-1.18443E-05
-69.8	8.14539	-1.14041E-05
-69.6	8.18488	-1.10147E-05
-69.4	8.2244	-1.05949E-05
-69.2	8.26395	-1.00157E-05
-69	8.30349	-9.61279E-06
-68.8	8.34305	-9.16783E-06
-68.6	8.38264	-8.78956E-06
-68.4	8.4223	-8.26833E-06
-68.2	8.46196	-7.80402E-06
-68	8.50164	-7.24162E-06
-67.8	8.54134	-6.82646E-06
-67.6	8.58108	-6.21093E-06
-67.4	8.62083	-5.71728E-06
-67.2	8.66053	-5.17395E-06
-67	8.70027	-4.63999E-06
-66.8	8.74004	-3.98972E-06
-66.6	8.77977	-3.50859E-06
-66.4	8.81947	-2.8853E-06
-66.2	8.85918	-2.34413E-06
-66	8.89887	-1.72135E-06
-65.8	8.93856	-1.09748E-06
-65.6	8.9782	-5.29226E-07
-65.4	9.01779	9.69794E-08
-65.2	9.05741	7.5982E-07
-65	9.09702	1.44448E-06
-64.8	9.13667	2.02101E-06
-64.6	9.17631	2.72513E-06
-64.4	9.21597	3.35273E-06
-64.2	9.2556	4.08348E-06
-64	9.29523	4.77932E-06
-63.8	9.33486	5.56096E-06
-63.6	9.37448	6.17566E-06
-63.4	9.41416	6.96291E-06
-63.2	9.45381	7.66871E-06
-63	9.49346	8.41374E-06
-62.8	9.53307	9.07145E-06
-62.6	9.57271	9.90054E-06
-62.4	9.61237	1.06338E-05
-62.2	9.65201	1.13866E-05
-62	9.69169	1.23096E-05
-61.8	9.73138	1.29735E-05
-61.6	9.77107	1.37601E-05
-61.4	9.81078	1.45482E-05
-61.2	9.85049	1.54023E-05
-61	9.89019	1.61369E-05
-60.8	9.92992	1.70558E-05
-60.6	9.96962	1.78056E-05
-60.4	10.0093	1.86628E-05
-60.2	10.04902	1.94836E-05
-60	10.08871	2.03266E-05
-59.8	10.12839	2.11239E-05
-59.6	10.1681	2.19756E-05
-59.4	10.20778	2.28169E-05
-59.2	10.24744	2.36361E-05
-59	10.28708	2.4458E-05
-58.8	10.32673	2.52906E-05
-58.6	10.36631	2.61415E-05
-58.4	10.40594	2.6992E-05
-58.2	10.44552	2.78735E-05
-58	10.48509	2.85916E-05
-57.8	10.52466	2.95351E-05
-57.6	10.56422	3.02722E-05
-57.4	10.60379	3.11945E-05
-57.2	10.64335	3.20171E-05
-57	10.68292	3.29145E-05
-56.8	10.72249	3.36964E-05
-56.6	10.76206	3.45659E-05
-56.4	10.80167	3.53407E-05
-56.2	10.84126	3.60782E-05
-56	10.88083	3.69589E-05
-55.8	10.9204	3.77076E-05
-55.6	10.95998	3.86221E-05
-55.4	10.99955	3.94159E-05
-55.2	11.03917	4.01646E-05
-55	11.07877	4.09627E-05
-54.8	11.11836	4.18017E-05
-54.6	11.15799	4.25415E-05
-54.4	11.19761	4.32541E-05
-54.2	11.23725	4.39525E-05
-54	11.27689	4.47992E-05
-53.8	11.31653	4.54898E-05
-53.6	11.35617	4.62761E-05
-53.4	11.39583	4.69522E-05
-53.2	11.43542	4.76864E-05
-53	11.475	4.84102E-05
-52.8	11.51459	4.91402E-05
-52.6	11.55413	4.98161E-05
-52.4	11.59368	5.05535E-05
-52.2	11.63321	5.1256E-05
-52	11.67271	5.18756E-05
-51.8	11.71224	5.26373E-05
-51.6	11.75176	5.33095E-05
-51.4	11.79125	5.3988E-05
-51.2	11.83079	5.45504E-05
-51	11.87032	5.52709E-05
-50.8	11.90981	5.58774E-05
-50.6	11.94928	5.6611E-05
-50.4	11.9888	5.72105E-05
-50.2	12.02836	5.7876E-05
-50	12.06789	5.85048E-05
-49.8	12.10744	5.90914E-05
-49.6	12.14691	5.96407E-05
-49.4	12.1864	6.02736E-05
-49.2	12.2259	6.08136E-05
-49	12.26537	6.14499E-05
-48.8	12.30488	6.20263E-05
-48.6	12.34441	6.25739E-05
-48.4	12.38394	6.29432E-05
-48.2	12.42344	6.34227E-05
-48	12.46298	6.4016E-05
-47.8	12.50251	6.4474E-05
-47.6	12.54204	6.50935E-05
-47.4	12.5816	6.55352E-05
-47.2	12.62117	6.60968E-05
-47	12.66077	6.66193E-05
-46.8	12.70034	6.71866E-05
-46.6	12.73993	6.77163E-05
-46.4	12.77949	6.82631E-05
-46.2	12.8191	6.8659E-05
-46	12.8587	6.9065E-05
-45.8	12.89832	6.95294E-05
-45.6	12.93793	6.99209E-05
-45.4	12.97753	7.03565E-05
-45.2	13.01716	7.07902E-05
-45	13.05679	7.12882E-05
-44.8	13.09644	7.17096E-05
-44.6	13.13612	7.21666E-05
-44.4	13.17577	7.25131E-05
-44.2	13.21534	7.29589E-05
-44	13.25497	7.32603E-05
-43.8	13.29454	7.365E-05
-43.6	13.33412	7.39959E-05
-43.4	13.37367	7.44231E-05
-43.2	13.41323	7.47689E-05
-43	13.45278	7.52026E-05
-42.8	13.49236	7.55049E-05
-42.6	13.53191	7.58157E-05
-42.4	13.57148	7.60837E-05
-42.2	13.61108	7.63529E-05
-42	13.6507	7.67167E-05
-41.8	13.69036	7.69348E-05
-41.6	13.73001	7.73057E-05
-41.4	13.7697	7.7601E-05
-41.2	13.80941	7.78493E-05
-41	13.84914	7.80663E-05
-40.8	13.8888	0.000078448
-40.6	13.92852	7.84799E-05
-40.4	13.96823	7.87798E-05
-40.2	14.00796	7.89333E-05
-40	14.0477	7.92959E-05
-39.8	14.08746	7.94061E-05
-39.6	14.12716	7.96714E-05
-39.4	14.16685	7.98562E-05
-39.2	14.20656	7.99858E-05
-39	14.24625	8.02442E-05
-38.8	14.28596	8.03493E-05
-38.6	14.32565	8.04568E-05
-38.4	14.36534	8.06236E-05
-38.2	14.40502	8.07672E-05
-38	14.44464	8.08832E-05
-37.8	14.48425	8.11201E-05
-37.6	14.52394	8.11212E-05
-37.4	14.56363	8.11889E-05
-37.2	14.60331	8.12139E-05
-37	14.64299	8.13838E-05
-36.8	14.68268	8.13769E-05
-36.6	14.72239	8.14738E-05
-36.4	14.76212	8.15186E-05
-36.2	14.80183	8.16158E-05
-36	14.8416	8.16452E-05
-35.8	14.88142	8.16201E-05
-35.6	14.9212	8.1555E-05
-35.4	14.96094	8.16191E-05
-35.2	15.00073	8.15205E-05
-35	15.04052	8.14984E-05			-35	8.14984E-05
-34.8	15.08034	8.15204E-05			71	-0.001393342	-1.96245E-05
-34.6	15.12014	8.15409E-05
-34.4	15.15994	8.14378E-05
-34.2	15.19977	8.13782E-05
-34	15.23957	8.12741E-05
-33.8	15.27935	8.10446E-05
-33.6	15.3191	8.09806E-05
-33.4	15.35888	8.07906E-05
-33.2	15.39867	8.07276E-05
-33	15.43848	8.05941E-05
-32.8	15.47827	8.05327E-05
-32.6	15.51805	8.03092E-05
-32.4	15.55787	8.02236E-05
-32.2	15.59767	7.99378E-05
-32	15.63747	7.98025E-05
-31.8	15.67729	7.95662E-05
-31.6	15.71715	7.92963E-05
-31.4	15.75702	7.90885E-05
-31.2	15.79691	7.87717E-05
-31	15.8368	7.85837E-05
-30.8	15.87666	7.821E-05
-30.6	15.91654	7.79698E-05
-30.4	15.95639	7.75529E-05
-30.2	15.99625	7.73407E-05
-30	16.0361	7.69786E-05
-29.8	16.07594	7.67007E-05
-29.6	16.11576	7.62356E-05
-29.4	16.15562	7.59428E-05
-29.2	16.19541	7.54824E-05
-29	16.23519	7.49953E-05
-28.8	16.27494	7.46216E-05
-28.6	16.31473	7.41498E-05
-28.4	16.35452	7.36858E-05
-28.2	16.3943	7.31687E-05
-28	16.43411	7.27273E-05
-27.8	16.47393	7.21494E-05
-27.6	16.51378	7.16278E-05
-27.4	16.55357	7.11071E-05
-27.2	16.59342	7.04739E-05
-27	16.63327	6.99796E-05
-26.8	16.67317	6.94197E-05
-26.6	16.71307	6.87765E-05
-26.4	16.75295	6.80576E-05
-26.2	16.79284	6.74729E-05
-26	16.8327	6.67031E-05
-25.8	16.8726	6.60595E-05
-25.6	16.91247	6.5312E-05
-25.4	16.95234	6.46248E-05
-25.2	16.99221	6.39161E-05
-25	17.03206	6.31045E-05
-24.8	17.07189	6.23461E-05
-24.6	17.1117	6.15054E-05
-24.4	17.15154	6.07351E-05
-24.2	17.19139	5.9857E-05
-24	17.23124	5.90804E-05
-23.8	17.27111	5.83113E-05
-23.6	17.31097	5.72787E-05
-23.4	17.35082	5.64723E-05
-23.2	17.39068	5.55259E-05
-23	17.43053	5.45741E-05
-22.8	17.4704	0.000053633
-22.6	17.51029	5.26917E-05
-22.4	17.55016	5.16993E-05
-22.2	17.58997	5.06685E-05
-22	17.62981	4.96682E-05
-21.8	17.66961	4.85517E-05
-21.6	17.70934	4.74994E-05
-21.4	17.7491	4.6411E-05
-21.2	17.78889	4.5343E-05
-21	17.82866	4.42291E-05
-20.8	17.86847	4.31251E-05
-20.6	17.90822	4.1837E-05
-20.4	17.94798	4.06993E-05
-20.2	17.98785	3.96053E-05
-20	18.02769	3.83364E-05
-19.8	18.06752	3.71948E-05
-19.6	18.10744	3.59267E-05
-19.4	18.14736	3.46949E-05
-19.2	18.18725	3.3386E-05
-19	18.22712	3.20827E-05
-18.8	18.26697	3.07778E-05
-18.6	18.30689	2.94267E-05
-18.4	18.3468	2.81179E-05
-18.2	18.38667	2.66855E-05
-18	18.42654	2.5253E-05
-17.8	18.46647	2.38193E-05
-17.6	18.50635	2.22597E-05
-17.4	18.54623	2.08282E-05
-17.2	18.58614	1.93107E-05
-17	18.62609	1.78381E-05
-16.8	18.66602	1.61925E-05
-16.6	18.70598	1.45928E-05
-16.4	18.74594	1.29443E-05
-16.2	18.78591	1.12528E-05
-16	18.82586	9.65133E-06
-15.8	18.86584	7.9275E-06
-15.6	18.90578	6.24378E-06
-15.4	18.94576	4.39015E-06
-15.2	18.98575	2.53869E-06
-15	19.02573	7.58133E-07
-14.8	19.06569	-1.09299E-06
-14.6	19.1056	-2.86513E-06
-14.4	19.14553	-4.92045E-06
-14.2	19.18544	-6.84873E-06
-14	19.22533	-8.8388E-06
-13.8	19.26524	-1.09313E-05
-13.6	19.30512	-1.29981E-05
-13.4	19.345	-1.509E-05
-13.2	19.3849	-1.70201E-05
-13	19.42479	-1.93317E-05
-12.8	19.46466	-2.15E-05
-12.6	19.5046	-2.38401E-05
-12.4	19.5445	-2.6147E-05
-12.2	19.58445	-2.84691E-05
-12	19.6244	-3.08484E-05
-11.8	19.66432	-3.30934E-05
-11.6	19.70429	-3.56353E-05
-11.4	19.74427	-3.81133E-05
-11.2	19.78427	-4.06395E-05
-11	19.82423	-4.32237E-05
-10.8	19.86422	-4.57588E-05
-10.6	19.90421	-4.84743E-05
-10.4	19.94421	-5.10322E-05
-10.2	19.98413	-5.3852E-05
-10	20.02408	-5.66E-05
-9.8	20.06405	-5.93779E-05
-9.6	20.10399	-6.22212E-05
-9.4	20.14392	-6.50576E-05
-9.2	20.18383	-6.80371E-05
-9	20.22376	-7.10274E-05
-8.8	20.26366	-7.41518E-05
-8.6	20.30355	-7.71816E-05
-8.4	20.34349	-8.03898E-05
-8.2	20.38343	-8.34947E-05
-8	20.42336	-8.68551E-05
-7.8	20.46333	-8.99866E-05
-7.6	20.50331	-9.33574E-05
-7.4	20.54329	-9.67569E-05
-7.2	20.58327	-0.000100197
-7	20.62325	-0.000103716
-6.8	20.66322	-0.000107237
-6.6	20.70319	-0.0001108
-6.4	20.74313	-0.000114375
-6.2	20.78305	-0.00011803
-6	20.823	-0.000121757
-5.8	20.86292	-0.00012555
-5.6	20.9028	-0.000129315
-5.4	20.94267	-0.000133197
-5.2	20.98254	-0.00013698
-5	21.02244	-0.000140893
-4.8	21.06236	-0.000144651
-4.6	21.10231	-0.000148637
-4.4	21.1422	-0.000152675
-4.2	21.18215	-0.000156898
-4	21.22204	-0.000161175
-3.8	21.26196	-0.00016555
-3.6	21.30193	-0.000169906
-3.4	21.34188	-0.000174435
-3.2	21.38184	-0.000178987
-3	21.42178	-0.000183535
-2.8	21.46168	-0.000188189
-2.6	21.50156	-0.000192809
-2.4	21.5415	-0.000197525
-2.2	21.58143	-0.000202302
-2	21.62135	-0.000207209
-1.8	21.66128	-0.000212014
-1.6	21.70118	-0.00021705
-1.4	21.74108	-0.000222062
-1.2	21.78098	-0.00022725
-1	21.82086	-0.000232373
-0.8	21.86076	-0.000237756
-0.6	21.90067	-0.000243098
-0.4	21.94057	-0.000248571
-0.2	21.98044	-0.000254277
0	22.02032	-0.000259986
0.2	22.06026	-0.000265704
0.4	22.10015	-0.000271642
0.6	22.14003	-0.000277598
0.8	22.17993	-0.000283565
1	22.21984	-0.000289729
1.2	22.25976	-0.000295896
1.4	22.29969	-0.00030231
1.6	22.33961	-0.000308689
1.8	22.37958	-0.000315305
2	22.41956	-0.000321872
2.2	22.45952	-0.000328572
2.4	22.49954	-0.000335263
2.6	22.53957	-0.000342156
2.8	22.57963	-0.000349197
3	22.6197	-0.000356232
3.2	22.65976	-0.000363366
3.4	22.69984	-0.000370314
3.6	22.73991	-0.000377362
3.8	22.77996	-0.000384677
4	22.82002	-0.000392157
4.2	22.86005	-0.000399797
4.4	22.90005	-0.000407577
4.6	22.94	-0.000415314
4.8	22.9799	-0.000423146
5	23.01983	-0.000430938
5.2	23.05976	-0.00043883
5.4	23.09971	-0.000446847
5.6	23.13963	-0.000454967
5.8	23.17954	-0.000463349
6	23.21946	-0.000471576
6.2	23.25937	-0.000480013
6.4	23.29928	-0.000488611
6.6	23.33921	-0.000497333
6.8	23.37916	-0.000506131
7	23.4191	-0.000515035
7.2	23.45898	-0.000523953
7.4	23.49884	-0.000533072
7.6	23.5387	-0.000542242
7.8	23.57856	-0.000551579
8	23.61845	-0.000560829
8.2	23.65835	-0.000570223
8.4	23.69829	-0.000579601
8.6	23.73817	-0.000588993
8.8	23.77807	-0.000598464
9	23.81799	-0.00060773
9.2	23.85797	-0.000617076
9.4	23.89796	-0.000626597
9.6	23.93799	-0.000636394
9.8	23.97804	-0.000646091
10	24.01808	-0.000655796
10.2	24.05808	-0.000665262
10.4	24.09804	-0.000674901
10.6	24.13807	-0.000684438
10.8	24.17807	-0.000694207
11	24.21809	-0.000703835
11.2	24.25808	-0.000713598
11.4	24.29803	-0.000723338
11.6	24.33794	-0.000733092
11.8	24.37786	-0.000742871
12	24.41772	-0.000752667
12.2	24.45764	-0.000762394
12.4	24.49758	-0.000772244
12.6	24.53749	-0.000782188
12.8	24.57738	-0.000792037
13	24.61727	-0.000801864
13.2	24.65717	-0.000811549
13.4	24.69703	-0.000821354
13.6	24.73692	-0.000830932
13.8	24.7768	-0.000840339
14	24.81669	-0.000849541
14.2	24.85664	-0.000858986
14.4	24.89658	-0.000868346
14.6	24.93654	-0.000877715
14.8	24.97653	-0.000886938
15	25.01652	-0.000895958
15.2	25.05654	-0.000904727
15.4	25.09658	-0.000913576
15.6	25.13662	-0.000922204
15.8	25.17671	-0.0009308
16	25.21677	-0.000939299
16.2	25.25676	-0.000947549
16.4	25.29675	-0.000955991
16.6	25.33673	-0.000964219
16.8	25.3767	-0.000972427
17	25.41667	-0.00098049
17.2	25.45662	-0.000988519
17.4	25.49656	-0.000996389
17.6	25.53649	-0.001004305
17.8	25.57639	-0.001012111
18	25.61633	-0.001019849
18.2	25.65626	-0.00102745
18.4	25.69618	-0.001034882
18.6	25.73613	-0.001042411
18.8	25.77603	-0.001049652
19	25.81597	-0.001056915
19.2	25.85596	-0.001063897
19.4	25.8959	-0.0010708
19.6	25.93586	-0.001077153
19.8	25.97587	-0.001084026
20	26.01589	-0.001090631
20.2	26.05588	-0.001097203
20.4	26.09588	-0.001103644
20.6	26.13585	-0.001109867
20.8	26.17582	-0.001116116
21	26.2158	-0.00112207
21.2	26.25571	-0.001127865
21.4	26.29565	-0.001133486
21.6	26.33557	-0.001139121
21.8	26.37545	-0.001144432
22	26.41535	-0.001149888
22.2	26.45522	-0.00115499
22.4	26.49512	-0.001160214
22.6	26.53504	-0.001165079
22.8	26.57504	-0.001169981
23	26.61501	-0.001174759
23.2	26.65498	-0.001179509
23.4	26.69494	-0.001184131
23.6	26.73489	-0.001188681
23.8	26.77492	-0.001193226
24	26.8149	-0.001197671
24.2	26.85488	-0.001201816
24.4	26.89485	-0.00120596
24.6	26.93483	-0.001209995
24.8	26.97476	-0.001213927
25	27.01469	-0.001217814
25.2	27.0546	-0.001221589
25.4	27.09455	-0.001225311
25.6	27.1345	-0.001228947
25.8	27.17445	-0.00123251
26	27.2144	-0.001235906
26.2	27.25439	-0.001239295
26.4	27.29436	-0.001242614
26.6	27.33437	-0.001245797
26.8	27.37441	-0.0012489
27	27.41445	-0.001252038
27.2	27.45444	-0.001254939
27.4	27.49443	-0.001257812
27.6	27.53443	-0.001260663
27.8	27.57444	-0.001263351
28	27.61449	-0.001265911
28.2	27.65451	-0.001268493
28.4	27.6945	-0.001270974
28.6	27.73447	-0.001273313
28.8	27.77443	-0.001275645
29	27.81438	-0.001277854
29.2	27.85436	-0.001280072
29.4	27.89432	-0.001282036
29.6	27.93427	-0.001284165
29.8	27.97418	-0.001286008
30	28.01408	-0.001287963
30.2	28.05392	-0.001289749
30.4	28.09378	-0.001291491
30.6	28.13362	-0.001292985
30.8	28.17347	-0.001294479
31	28.2134	-0.001295851
31.2	28.2533	-0.001297264
31.4	28.2932	-0.001298593
31.6	28.33313	-0.001299797
31.8	28.37306	-0.001301001
32	28.41299	-0.001302082
32.2	28.45298	-0.001303163
32.4	28.49304	-0.001304034
32.6	28.53308	-0.001305031
32.8	28.57309	-0.001305729
33	28.61309	-0.001306598
33.2	28.65311	-0.001307341
33.4	28.69311	-0.001308083
33.6	28.73311	-0.001308701
33.8	28.77313	-0.001309192
34	28.81312	-0.001309724
34.2	28.85306	-0.001310169
34.4	28.89299	-0.001310573
34.6	28.93288	-0.001310934
34.8	28.97279	-0.001311339
35	29.01272	-0.001311487
35.2	29.05261	-0.001311693
35.4	29.0925	-0.001311761
35.6	29.1324	-0.001311781
35.8	29.17232	-0.001311809
36	29.21224	-0.001311844
36.2	29.25218	-0.001311777
36.4	29.2921	-0.001311593
36.6	29.33201	-0.001311499
36.8	29.37192	-0.001311184
37	29.41183	-0.001310831
37.2	29.45173	-0.001310455
37.4	29.49165	-0.001310003
37.6	29.53157	-0.001309406
37.8	29.57148	-0.001308935
38	29.6114	-0.001308349
38.2	29.65133	-0.001307761
38.4	29.69125	-0.001307072
38.6	29.73126	-0.001306386
38.8	29.77127	-0.001305626
39	29.81131	-0.001304913
39.2	29.85136	-0.001304178
39.4	29.89137	-0.001303312
39.6	29.9314	-0.001302508
39.8	29.97143	-0.001301609
40	30.01146	-0.001300675
40.2	30.05148	-0.001299641
40.4	30.09148	-0.001298616
40.6	30.13145	-0.001297436
40.8	30.17137	-0.001296252
41	30.21125	-0.00129519
41.2	30.25114	-0.001293966
41.4	30.29103	-0.001292753
41.6	30.33084	-0.001291517
41.8	30.37074	-0.001290186
42	30.41059	-0.001288826
42.2	30.45043	-0.0012875
42.4	30.49029	-0.00128611
42.6	30.53013	-0.001284605
42.8	30.57002	-0.001283143
43	30.60993	-0.001281519
43.2	30.64982	-0.001279902
43.4	30.68976	-0.001278294
43.6	30.72972	-0.001276714
43.8	30.76967	-0.001274959
44	30.80962	-0.001273297
44.2	30.84961	-0.001271538
44.4	30.88961	-0.001269696
44.6	30.92959	-0.001267861
44.8	30.9696	-0.001266011
45	31.00956	-0.001264222
45.2	31.04955	-0.001262305
45.4	31.08947	-0.00126041
45.6	31.12941	-0.001258432
45.8	31.16936	-0.001256496
46	31.20927	-0.001254366
46.2	31.24923	-0.001252302
46.4	31.28916	-0.001250305
46.6	31.32915	-0.001248141
46.8	31.36912	-0.001246009
47	31.40911	-0.00124387
47.2	31.44911	-0.0012417
47.4	31.48914	-0.001239497
47.6	31.5292	-0.001237232
47.8	31.56923	-0.001235079
48	31.60927	-0.001232675
48.2	31.64929	-0.00123043
48.4	31.68933	-0.001227967
48.6	31.72937	-0.001225769
48.8	31.76941	-0.001223354
49	31.80944	-0.001220851
49.2	31.84945	-0.001218512
49.4	31.88946	-0.001216119
49.6	31.92949	-0.001213601
49.8	31.96953	-0.001211111
50	32.00952	-0.001208685
50.2	32.04951	-0.001206037
50.4	32.08954	-0.001203569
50.6	32.12962	-0.001201089
50.8	32.16964	-0.001198512
51	32.2097	-0.001195885
51.2	32.24976	-0.001193186
51.4	32.28982	-0.001190797
51.6	32.32987	-0.001188075
51.8	32.3699	-0.00118541
52	32.40996	-0.001182796
52.2	32.45002	-0.00118001
52.4	32.49006	-0.001177264
52.6	32.53007	-0.001174449
52.8	32.57001	-0.00117176
53	32.60995	-0.001168936
53.2	32.64987	-0.00116622
53.4	32.6898	-0.001163362
53.6	32.72974	-0.001160483
53.8	32.76963	-0.001157676
54	32.80953	-0.001154789
54.2	32.8494	-0.001151884
54.4	32.88927	-0.001149063
54.6	32.92917	-0.001146237
54.8	32.96907	-0.001143287
55	33.00896	-0.001140365
55.2	33.04887	-0.001137403
55.4	33.08876	-0.001134346
55.6	33.12869	-0.001131398
55.8	33.16862	-0.001128311
56	33.20859	-0.001125425
56.2	33.24858	-0.001122267
56.4	33.28856	-0.001119269
56.6	33.32852	-0.0011161
56.8	33.36847	-0.001113057
57	33.40847	-0.001109951
57.2	33.44843	-0.001106729
57.4	33.48843	-0.00110358
57.6	33.52836	-0.001100402
57.8	33.56831	-0.001097189
58	33.60825	-0.001093934
58.2	33.64814	-0.001090695
58.4	33.68807	-0.001087307
58.6	33.72797	-0.001084001
58.8	33.76785	-0.001082053
59	33.80773	-0.001078409
59.2	33.84765	-0.001074885
59.4	33.88751	-0.001071409
59.6	33.92741	-0.001067927
59.8	33.96731	-0.001064491
60	34.00719	-0.001061051
60.2	34.04708	-0.001057605
60.4	34.08698	-0.001054118
60.6	34.12691	-0.001050717
60.8	34.16684	-0.001047143
61	34.20674	-0.001043737
61.2	34.24668	-0.001040225
61.4	34.28665	-0.00103678
61.6	34.32663	-0.001033326
61.8	34.3666	-0.001029789
62	34.40651	-0.001026182
62.2	34.44646	-0.001022484
62.4	34.48643	-0.001018895
62.6	34.52644	-0.001015223
62.8	34.56646	-0.001011536
63	34.60649	-0.001007815
63.2	34.64653	-0.001004161
63.4	34.6865	-0.001000393
63.6	34.72644	-0.000996646
63.8	34.76641	-0.000992996
64	34.80645	-0.000989215
64.2	34.84651	-0.000985543
64.4	34.88656	-0.000981764
64.6	34.92656	-0.000978005
64.8	34.96657	-0.000974116
65	35.00657	-0.000970366
65.2	35.04663	-0.00096657
65.4	35.08669	-0.000962719
65.6	35.12681	-0.000958944
65.8	35.16692	-0.000955069
66	35.207	-0.00095139
66.2	35.24709	-0.000947501
66.4	35.28719	-0.000943708
66.6	35.32727	-0.000939812
66.8	35.36738	-0.000936016
67	35.40743	-0.000932183
67.2	35.44746	-0.000928366
67.4	35.48749	-0.000924514
67.6	35.52746	-0.000920595
67.8	35.56744	-0.000916733
68	35.60747	-0.000912753
68.2	35.64744	-0.000909009
68.4	35.68738	-0.000904989
68.6	35.72732	-0.000901139
68.8	35.76724	-0.000897245
69	35.80716	-0.000893377
69.2	35.84712	-0.000889472
69.4	35.88701	-0.000885449
69.6	35.927	-0.000881652
69.8	35.96695	-0.000877644
70	36.00694	-0.000873708
70.2	36.04689	-0.000869729
70.4	36.08688	-0.000865797
70.6	36.12687	-0.000861718
70.8	36.16684	-0.000857731
71	36.20684	-0.00085369
71.2	36.24682	-0.000849752
71.4	36.28694	-0.000845669
71.6	36.327	-0.000841505
71.8	36.36704	-0.000837408
72	36.40708	-0.000833235
72.2	36.44712	-0.000829044
72.4	36.48719	-0.000824798
72.6	36.5272	-0.000820552
72.8	36.56722	-0.000816347
73	36.60728	-0.000812121
73.2	36.64727	-0.000807975
73.4	36.68723	-0.000803862
73.6	36.72718	-0.000799674
73.8	36.76712	-0.000795565
74	36.80705	-0.000791304
74.2	36.84694	-0.000787191
74.4	36.88682	-0.000783003
74.6	36.92673	-0.000778891
74.8	36.96662	-0.000774606
75	37.00646	-0.000770338
75.2	37.04634	-0.000766104
75.4	37.08622	-0.000761818
75.6	37.12607	-0.000757468
75.8	37.16592	-0.000753075
76	37.20585	-0.000748715
76.2	37.24576	-0.000744288
76.4	37.28567	-0.000740022
76.6	37.32561	-0.000735618
76.8	37.36555	-0.00073132
77	37.40555	-0.000726914
77.2	37.4456	-0.000722491
77.4	37.48563	-0.000717996
77.6	37.5257	-0.000713677
77.8	37.56578	-0.000709268
78	37.60584	-0.000704913
78.2	37.64591	-0.000700505
78.4	37.68597	-0.000696121
78.6	37.72599	-0.000691749
78.8	37.76604	-0.000687316
79	37.80603	-0.000682877
79.2	37.84607	-0.000678456
79.4	37.8861	-0.000674084
79.6	37.9261	-0.000669534
79.8	37.96605	-0.000665189
80	38.00602	-0.000660664
80.2	38.04597	-0.000656324
80.4	38.08591	-0.000651808
80.6	38.12586	-0.000647472
80.8	38.16583	-0.000643015
81	38.20584	-0.000638683
81.2	38.24578	-0.000634299
81.4	38.2857	-0.000629806
81.6	38.32562	-0.000625432
81.8	38.36557	-0.00062097
82	38.40553	-0.000616529
82.2	38.44555	-0.000612047
82.4	38.48558	-0.000607758
82.6	38.52556	-0.000603216
82.8	38.56556	-0.000598844
83	38.60552	-0.000594382
83.2	38.64549	-0.000589872
83.4	38.68546	-0.000585286
83.6	38.72543	-0.000580653
83.8	38.76545	-0.000576072
84	38.80541	-0.000571472
84.2	38.84536	-0.000566973
84.4	38.88527	-0.000562387
84.6	38.92522	-0.000557842
84.8	38.96514	-0.00055328
85	39.00508	-0.000548772
85.2	39.04502	-0.000544278
85.4	39.08492	-0.000539822
85.6	39.12486	-0.00053534
85.8	39.16476	-0.000530883
86	39.20463	-0.000526252
86.2	39.2445	-0.000521582
86.4	39.2844	-0.000517046
86.6	39.32435	-0.000512304
86.8	39.36432	-0.00050759
87	39.40433	-0.000502846
87.2	39.44432	-0.000498257
87.4	39.48436	-0.000493462
87.6	39.52438	-0.00048889
87.8	39.56443	-0.000484067
88	39.60455	-0.000479397
88.2	39.64465	-0.000474601
88.4	39.68474	-0.000469931
88.6	39.72482	-0.000465124
88.8	39.76484	-0.000460357
89	39.80483	-0.000455685
89.2	39.84486	-0.000451007
89.4	39.88492	-0.000446337
89.6	39.92494	-0.000441577
89.8	39.96497	-0.000436858
90	40.00496	-0.000432132
90.2	40.04495	-0.000427471
90.4	40.08494	-0.000422722
90.6	40.1249	-0.000418072
90.8	40.16488	-0.000413342
91	40.20486	-0.000408603
91.2	40.24484	-0.000403832
91.4	40.28476	-0.000399269
91.6	40.3247	-0.000394512
91.8	40.36464	-0.000389969
92	40.40461	-0.000385333
92.2	40.44459	-0.000380752
92.4	40.48458	-0.000376059
92.6	40.52459	-0.000371464
92.8	40.56461	-0.000366863
93	40.60465	-0.000362163
93.2	40.6447	-0.000357584
93.4	40.68472	-0.000352908
93.6	40.72471	-0.000348362
93.8	40.76471	-0.00034363
94	40.80464	-0.00033901
94.2	40.84459	-0.000334185
94.4	40.88457	-0.000329453
94.6	40.92449	-0.000324727
94.8	40.96439	-0.000319923
95	41.00431	-0.000315205
95.2	41.04419	-0.000310476
95.4	41.0841	-0.00030581
95.6	41.12402	-0.000301082
95.8	41.16393	-0.000296531
96	41.20382	-0.000291787
96.2	41.24374	-0.000287227
96.4	41.2837	-0.000282566
96.6	41.32367	-0.000277862
96.8	41.36369	-0.000273075
97	41.40371	-0.000268328
97.2	41.44372	-0.000263494
97.4	41.48377	-0.000258705
97.6	41.52382	-0.000253871
97.8	41.5639	-0.000248904
98	41.60398	-0.000244136
98.2	41.64407	-0.000239272
98.4	41.6841	-0.000234457
98.6	41.72417	-0.000229582
98.8	41.7642	-0.000224715
99	41.80421	-0.000219788
99.2	41.84424	-0.000214988
99.4	41.88424	-0.000210014
99.6	41.92429	-0.000205293
99.8	41.9643	-0.000200391
100	42.00433	-0.000195572
100.2	42.04439	-0.000190768
100.4	42.08441	-0.00018588
100.6	42.12441	-0.000181115
100.8	42.1644	-0.000176166
101	42.20442	-0.000171364
101.2	42.24444	-0.000166498
101.4	42.28446	-0.000161738
101.6	42.32444	-0.000156841
101.8	42.36442	-0.000152135
102	42.40441	-0.000147339
102.2	42.44441	-0.000142649
102.4	42.48438	-0.00013784
102.6	42.52438	-0.000133154
102.8	42.56438	-0.000128371
103	42.60433	-0.000123607
103.2	42.64426	-0.000118889
103.4	42.6842	-0.000114165
103.6	42.72416	-0.000109421
103.8	42.76408	-0.000104756
104	42.80397	-9.99607E-05
104.2	42.84387	-9.51484E-05
104.4	42.88379	-9.0312E-05
104.6	42.92371	-8.54615E-05
104.8	42.96361	-8.05352E-05
105	43.00354	-7.56067E-05
105.2	43.0435	-7.07325E-05
105.4	43.08346	-6.59055E-05
105.6	43.12341	-6.09308E-05
105.8	43.16336	-5.61738E-05
106	43.20331	-5.13077E-05
106.2	43.2433	-4.65464E-05
106.4	43.28324	-4.1644E-05
106.6	43.32325	-3.68832E-05
106.8	43.36325	-3.20099E-05
107	43.40329	-2.70156E-05
107.2	43.44338	-2.19586E-05
107.4	43.4834	-1.69651E-05
107.6	43.52343	-1.19324E-05
107.8	43.56349	-6.97371E-06
108	43.60356	-1.86541E-06
108.2	43.64364	3.11636E-06
108.4	43.68373	8.19048E-06
108.6	43.7238	1.31655E-05
108.8	43.76384	1.83066E-05
109	43.80387	2.33384E-05
109.2	43.84388	2.84787E-05
109.4	43.8839	3.34458E-05
109.6	43.92396	3.85045E-05
109.8	43.964	4.35243E-05
110	44.00406	4.85465E-05
110.2	44.0441	5.35277E-05
110.4	44.08419	5.85714E-05
110.6	44.12427	6.35452E-05
110.8	44.16434	6.85655E-05
111	44.20441	7.35792E-05
111.2	44.24447	7.85742E-05
111.4	44.28454	8.34488E-05
111.6	44.32461	8.85268E-05
111.8	44.36467	9.34117E-05
112	44.40468	9.83419E-05
112.2	44.44469	0.000103174
112.4	44.48464	0.000108209
112.6	44.52451	0.000113023
112.8	44.56436	0.000118008
113	44.60428	0.00012292
113.2	44.64417	0.000127803
113.4	44.68404	0.000132636
113.6	44.72389	0.000137556
113.8	44.76373	0.000142371
114	44.80359	0.00014729
114.2	44.84347	0.00015221
114.4	44.88336	0.000157204
114.6	44.92327	0.000162282
114.8	44.96321	0.000167398
115	45.0031	0.000172474
115.2	45.04301	0.000177561
115.4	45.08296	0.000182519
115.6	45.12289	0.000187545
115.8	45.16282	0.000192574
116	45.20278	0.000197552
116.2	45.24275	0.000202486
116.4	45.28276	0.000207489
116.6	45.32281	0.000212502
116.8	45.36289	0.000217418
117	45.40297	0.000222475
117.2	45.44302	0.000227535
117.4	45.48311	0.000232691
117.6	45.52318	0.000237784
117.8	45.56322	0.000242865
118	45.60326	0.000247993
118.2	45.64335	0.000253106
118.4	45.68342	0.000258165
118.6	45.72346	0.000263296
118.8	45.76348	0.00026851
119	45.80346	0.000273487
119.2	45.84344	0.000278611
119.4	45.88341	0.00028368
119.6	45.92335	0.000288675
119.8	45.96332	0.000293706
120	46.00327	0.000298785
120.2	46.04318	0.000303758
120.4	46.08303	0.000308886
120.6	46.12287	0.000313878
120.8	46.16272	0.000318919
121	46.2026	0.000323891
121.2	46.2425	0.000328934
121.4	46.28241	0.000333945
121.6	46.32234	0.00033906
121.8	46.36229	0.000344078
122	46.40225	0.000349034
122.2	46.44225	0.000354036
122.4	46.48222	0.000359097
122.6	46.5222	0.000364059
122.8	46.56223	0.000369065
123	46.60226	0.000374106
123.2	46.64225	0.000379118
123.4	46.6822	0.000384055
123.6	46.7222	0.000389238
123.8	46.76219	0.000394201
124	46.80219	0.000399271
124.2	46.84219	0.000404358
124.4	46.8822	0.00040956
124.6	46.92223	0.000414712
124.8	46.96223	0.000419948
125	47.00224	0.000425203
125.2	47.04226	0.000430374
125.4	47.08228	0.000435538
125.6	47.12231	0.000440721
125.8	47.16232	0.000445764
126	47.20231	0.000450856
126.2	47.24224	0.000455881
126.4	47.28218	0.000460973
126.6	47.3221	0.000465982
126.8	47.36205	0.000471295
127	47.40203	0.000476469
127.2	47.44201	0.000481719
127.4	47.48199	0.000486757
127.6	47.52199	0.000492099
127.8	47.56196	0.000497243
128	47.60194	0.000502417
128.2	47.642	0.000507599
128.4	47.68209	0.000512881
128.6	47.7222	0.000517985
128.8	47.76221	0.000523191
129	47.80222	0.000528329
129.2	47.84225	0.000533493
129.4	47.88234	0.000538558
129.6	47.92242	0.000543732
129.8	47.96247	0.000548779
130	48.00255	0.000553926
130.2	48.04261	0.000558996
130.4	48.08264	0.000564129
130.6	48.12263	0.000569134
130.8	48.16265	0.000574244
131	48.20272	0.000579346
131.2	48.24272	0.000584444
131.4	48.28272	0.000589488
131.6	48.3227	0.000594541
131.8	48.36272	0.000599648
132	48.40272	0.00060464
132.2	48.44267	0.00060959
132.4	48.48263	0.000614741
132.6	48.52265	0.000619726
132.8	48.56267	0.000624854
133	48.60267	0.000629854
133.2	48.64268	0.000634958
133.4	48.68271	0.000639929
133.6	48.72274	0.000644978
133.8	48.76272	0.000650115
134	48.80265	0.00065526
134.2	48.84265	0.000660369
134.4	48.88269	0.000665648
134.6	48.92267	0.000670951
134.8	48.96266	0.000676212
135	49.00266	0.000681352
135.2	49.04266	0.000686616
135.4	49.08264	0.000691705
135.6	49.12262	0.000696869
135.8	49.16262	0.000701882
136	49.2027	0.000707012
136.2	49.24278	0.000712022
136.4	49.2829	0.000717229
136.6	49.32297	0.000722454
136.8	49.36306	0.00072767
137	49.40312	0.00073289
137.2	49.44318	0.000738099
137.4	49.48328	0.000743238
137.6	49.52335	0.000748519
137.8	49.56344	0.000753643
138	49.60345	0.000758915
138.2	49.64344	0.000764044
138.4	49.68342	0.000769368
138.6	49.72345	0.000774551
138.8	49.76348	0.000779747
139	49.80353	0.000784923
139.2	49.84356	0.000790142
139.4	49.88361	0.000795234
139.6	49.9236	0.000800448
139.8	49.96359	0.00080563
140	50.00361	0.000810779
140.2	50.04363	0.000816005
140.4	50.08365	0.000821257
140.6	50.1236	0.000826361
140.8	50.16357	0.000831618
141	50.20351	0.000836776
141.2	50.24347	0.000841963
141.4	50.28341	0.000847011
141.6	50.32338	0.000852216
141.8	50.36337	0.000857367
142	50.40332	0.00086258
142.2	50.44331	0.000867848
142.4	50.48326	0.000873031
142.6	50.52325	0.000878175
142.8	50.56324	0.000883342
143	50.60327	0.000888579
143.2	50.64328	0.000893774
143.4	50.6833	0.000898966
143.6	50.7233	0.0009043
143.8	50.76329	0.000909673
144	50.80333	0.000915064
144.2	50.84337	0.00092046
144.4	50.88341	0.00092587
144.6	50.92347	0.000931189
144.8	50.96347	0.000936571
145	51.0035	0.000941783
145.2	51.04352	0.00094697
145.4	51.08355	0.000952214
145.6	51.12358	0.000957421
145.8	51.16363	0.000962571
146	51.20364	0.000967988
146.2	51.24366	0.000973476
146.4	51.2837	0.000978837
146.6	51.32376	0.000984237
146.8	51.36381	0.000989681
147	51.40385	0.000994978
147.2	51.4439	0.001000426
147.4	51.48393	0.001005808
147.6	51.52398	0.001011246
147.8	51.56397	0.001016726
148	51.604	0.001022159
148.2	51.64402	0.001027603
148.4	51.68404	0.001033009
148.6	51.72408	0.001038353
148.8	51.76415	0.001043694
149	51.80423	0.001049074
149.2	51.84428	0.001054432
149.4	51.88432	0.001059818
149.6	51.92431	0.001065166
149.8	51.96435	0.001070582
150	52.00434	0.001076011
150.2	52.0443	0.0010813
150.4	52.08426	0.001086759
150.6	52.12421	0.001091989
150.8	52.16411	0.001097293
151	52.20401	0.001102481
151.2	52.24392	0.001107804
151.4	52.28385	0.001113036
151.6	52.32375	0.001118273
151.8	52.36362	0.001123625
152	52.40354	0.001128986
152.2	52.44352	0.001134232
152.4	52.48349	0.001139528
152.6	52.52345	0.001144797
152.8	52.56344	0.001150139
153	52.60341	0.001155471
153.2	52.64344	0.001160935
153.4	52.68346	0.001166398
153.6	52.72353	0.0011719
153.8	52.76363	0.00117736
154	52.80375	0.001182756
154.2	52.84389	0.001188212
154.4	52.88402	0.001193542
154.6	52.92419	0.001198852
154.8	52.96429	0.001204179
155	53.00443	0.001209499
155.2	53.04453	0.001214938
155.4	53.08459	0.001220493
155.6	53.12468	0.001226072
155.8	53.16473	0.00123161
156	53.20476	0.001237202
156.2	53.24478	0.001242712
156.4	53.28476	0.001248277
156.6	53.3247	0.001253846
156.8	53.36471	0.001259345
157	53.40466	0.001264957
157.2	53.44457	0.001270472
157.4	53.48451	0.001276132
157.6	53.5244	0.001281678
157.8	53.56438	0.001287225
158	53.60432	0.001292792
158.2	53.64427	0.001298336
158.4	53.68422	0.001303746
158.6	53.72417	0.001309276
158.8	53.76407	0.001314714
159	53.80401	0.00132017
159.2	53.84396	0.001325647
159.4	53.88394	0.001331244
159.6	53.92395	0.001336664
159.8	53.96388	0.001342148
160	54.00385	0.0013475
160.2	54.04383	0.001352842
160.4	54.08379	0.001358169
160.6	54.12382	0.001363578
160.8	54.16384	0.001368774
161	54.20387	0.001374143
161.2	54.24391	0.001379454
161.4	54.28395	0.001384763
161.6	54.32398	0.001390126
161.8	54.364	0.001395482
162	54.40407	0.001400773
162.2	54.44409	0.001406155
162.4	54.48414	0.001411614
162.6	54.52416	0.001417139
162.8	54.56418	0.001422548
163	54.60415	0.001427985
163.2	54.64413	0.00143344
163.4	54.6841	0.001438854
163.6	54.72411	0.001444055
163.8	54.76412	0.001449459
164	54.80411	0.001454711
164.2	54.84407	0.001460071
164.4	54.88406	0.001465417
164.6	54.92404	0.001471053
164.8	54.964	0.001476559
165	55.00397	0.001482143
165.2	55.04395	0.001487747
165.4	55.0839	0.001493344
165.6	55.12385	0.001498847
165.8	55.16382	0.001504417
166	55.20378	0.001509924
166.2	55.24375	0.001515507
166.4	55.28373	0.00152094
166.6	55.3237	0.001526605
166.8	55.3637	0.001532063
167	55.40368	0.001537631
167.2	55.44371	0.0015431
167.4	55.48368	0.001548643
167.6	55.52371	0.001554045
167.8	55.56373	0.001559556
168	55.60373	0.001565026
168.2	55.64373	0.001570511
168.4	55.68371	0.001575878
168.6	55.7237	0.001581404
168.8	55.7637	0.00158671
169	55.80366	0.001592078
169.2	55.84364	0.00159745
169.4	55.88364	0.001602874
169.6	55.92361	0.001608124
169.8	55.96357	0.001613504
170	56.00352	0.001618852
170.2	56.04348	0.001624195
170.4	56.08345	0.001629513
170.6	56.12345	0.001634874
170.8	56.16344	0.001640211
171	56.20341	0.001645609
171.2	56.24342	0.001651119
171.4	56.28342	0.001656599
171.6	56.32342	0.001662063
171.8	56.36343	0.001667679
172	56.4035	0.001673084
172.2	56.44354	0.001678599
172.4	56.48365	0.001683995
172.6	56.52373	0.001689529
172.8	56.56377	0.001695005
173	56.60388	0.001700444
173.2	56.644	0.001705865
173.4	56.68412	0.001711527
173.6	56.72424	0.001717129
173.8	56.76436	0.001722751
174	56.80446	0.001728409
174.2	56.84455	0.00173403
174.4	56.88459	0.001739561
174.6	56.92461	0.001745283
174.8	56.96464	0.001750936
175	57.00467	0.001756592
175.2	57.04469	0.001762193
175.4	57.08466	0.00176792
175.6	57.12459	0.001773491
175.8	57.16453	0.001779107
176	57.20447	0.001784578
176.2	57.24441	0.001790223
176.4	57.2844	0.001795749
176.6	57.32437	0.001801272
176.8	57.36433	0.001806873
177	57.40432	0.001812443
177.2	57.4443	0.001817976
177.4	57.48425	0.001823502
177.6	57.52424	0.001829014
177.8	57.56425	0.001834581
178	57.60424	0.001839938
178.2	57.64421	0.001845464
178.4	57.68414	0.001850855
178.6	57.7241	0.001856404
178.8	57.76407	0.001861855
179	57.804	0.00186734
179.2	57.84389	0.001872769
179.4	57.88382	0.001878209
179.6	57.92377	0.001883638
179.8	57.96369	0.00188906
180	58.00364	0.001894566
180.2	58.04363	0.001900161
180.4	58.08363	0.001905752
180.6	58.12362	0.001911469
180.8	58.16361	0.001917103
181	58.20362	0.001922737
181.2	58.24366	0.001928294
181.4	58.28365	0.00193379
181.6	58.32365	0.001939321
181.8	58.36359	0.001944815
182	58.40354	0.001950334
182.2	58.44352	0.001955823
182.4	58.48346	0.001961599
182.6	58.52342	0.001967199
182.8	58.56337	0.001972917
183	58.60332	0.00197855
183.2	58.64328	0.001984283
183.4	58.68328	0.001989853
183.6	58.72327	0.001995508
183.8	58.76328	0.002001233
184	58.80326	0.002006865
184.2	58.84324	0.002012417
184.4	58.88322	0.002018165
184.6	58.92317	0.002023755
184.8	58.96313	0.002029343
185	59.00313	0.002034923
185.2	59.04316	0.002040458
185.4	59.08313	0.002046036
185.6	59.12311	0.002051554
185.8	59.1631	0.002057179
186	59.20311	0.002062833
186.2	59.24309	0.002068381
186.4	59.2831	0.002073916
186.6	59.32311	0.002079488
186.8	59.36313	0.002084956
187	59.40309	0.002090393
187.2	59.44306	0.002095815
187.4	59.48302	0.002101363
187.6	59.523	0.002106777
187.8	59.563	0.002112328
188	59.60304	0.00211785
188.2	59.64305	0.00212338
188.4	59.68309	0.002128868
188.6	59.72314	0.002134362
188.8	59.76314	0.002139899
189	59.80317	0.002145526
189.2	59.84322	0.002151127
189.4	59.88327	0.002156881
189.6	59.9233	0.002162559
189.8	59.96335	0.002168222
190	60.00343	0.002173819
190.2	60.04347	0.00217942
190.4	60.08352	0.002184952
190.6	60.12356	0.002190407
190.8	60.16361	0.002195832
191	60.20367	0.002201426
191.2	60.24371	0.002206947
191.4	60.28378	0.002212621
191.6	60.32386	0.002218302
191.8	60.36392	0.002223982
192	60.40394	0.002229535
192.2	60.44396	0.002235201
192.4	60.48402	0.002240748
192.6	60.52407	0.002246278
192.8	60.56414	0.002251738
193	60.60417	0.002257435
193.2	60.6442	0.002262961
193.4	60.68424	0.002268528
193.6	60.72424	0.002274129
193.8	60.76425	0.00227964
194	60.80419	0.002285053
194.2	60.84418	0.002290557
194.4	60.88415	0.00229592
194.6	60.92407	0.002301407
194.8	60.96398	0.002306888
195	61.00386	0.00231235
195.2	61.04379	0.00231784
195.4	61.08372	0.002323408
195.6	61.12365	0.002328739
195.8	61.16363	0.00233411
196	61.20357	0.002339592
196.2	61.24358	0.002344949
196.4	61.28357	0.00235039
196.6	61.32356	0.002355842
196.8	61.36362	0.002361386
197	61.40368	0.002366767
197.2	61.44375	0.002372243
197.4	61.4838	0.002377714
197.6	61.52383	0.002383147
197.8	61.56383	0.00238856
198	61.60384	0.0023942
198.2	61.64384	0.002399789
198.4	61.68386	0.002405503
198.6	61.72388	0.002411092
198.8	61.76386	0.002416615
199	61.80381	0.002422127
199.2	61.84376	0.002427592
199.4	61.88376	0.002432945
199.6	61.92378	0.00243837
199.8	61.9636	0.002443791
199.9	61.98337	0.002446522