File: inner experiment data/Mn3.1/1-4-5.txt
#EXPORTTYPE:DATA SINGLE
#FILE:B&D.ngb-sla
#FORMAT:NETZSCH5
#FTYPE:ANSI
#IDENTITY:D
#DECIMAL:POINT
#SEPARATOR:SEMICOLON
#MTYPE:DIL
#INSTRUMENT:NETZSCH DIL 402SE
#PROJECT:1
#DATE/TIME:10.12.2019 16:07
#CORR. FILE:
#TEMPCAL:TCALZERO.TMX
#LABORATORY:1
#OPERATOR:1
#REMARK:
#SAMPLE:D
#SAMPLE LENGTH /mm:9.91
#MATERIAL:Ã’¥…
#MEASMODE:Standard Expansion
#M.RANGE /¶Ãm:20000
#CORR. CODE:010
#RANGE:-110°„C/5.0(K/min)/200°„C
#SEGMENT:S1/1
#SEG. 1:-110°„C/5.0(K/min)/200°„C

##Temp./°„C	Time/min	dL/Lo
-100	2.14097	-6.33785E-05
-99.8	2.17909	-6.19173E-05
-99.6	2.21719	-6.03112E-05
-99.4	2.25541	-5.87594E-05
-99.2	2.29369	-5.7019E-05
-99	2.33216	-5.5359E-05
-98.8	2.37079	-5.37729E-05
-98.6	2.40959	-5.1889E-05
-98.4	2.44866	-5.0142E-05
-98.2	2.48796	-4.84277E-05
-98	2.52744	-4.63267E-05
-97.8	2.56718	-4.45812E-05
-97.6	2.60723	-4.24188E-05
-97.4	2.64741	-4.04318E-05
-97.2	2.68779	-3.8406E-05
-97	2.72824	-3.63358E-05
-96.8	2.76886	-3.42179E-05
-96.6	2.80961	-3.21594E-05
-96.4	2.85043	-2.99395E-05
-96.2	2.89132	-2.79747E-05
-96	2.93228	-2.5808E-05
-95.8	2.97321	-2.37313E-05
-95.6	3.01404	-2.11839E-05
-95.4	3.05489	-1.88836E-05
-95.2	3.09571	-1.66185E-05
-95	3.13653	-1.41729E-05
-94.8	3.1772	-1.21039E-05
-94.6	3.21786	-1.00919E-05
-94.4	3.25839	-7.58094E-06
-94.2	3.29885	-5.12674E-06
-94	3.33923	-2.71026E-06
-93.8	3.37957	-3.15019E-07
-93.6	3.4199	2.09216E-06
-93.4	3.46019	4.54119E-06
-93.2	3.50044	7.18115E-06
-93	3.54069	9.66507E-06
-92.8	3.58095	1.19144E-05
-92.6	3.62119	1.44085E-05
-92.4	3.6615	1.69509E-05
-92.2	3.70183	1.93812E-05
-92	3.74213	2.1943E-05
-91.8	3.78247	2.45895E-05
-91.6	3.82285	2.71181E-05
-91.4	3.86317	2.96389E-05
-91.2	3.90354	3.22132E-05
-91	3.94385	3.4844E-05
-90.8	3.98419	3.73277E-05
-90.6	4.02452	3.98775E-05
-90.4	4.06483	4.23322E-05
-90.2	4.1051	4.50495E-05
-90	4.14535	4.75964E-05
-89.8	4.18556	5.03064E-05
-89.6	4.22575	5.29684E-05
-89.4	4.26593	5.56378E-05
-89.2	4.30607	5.82613E-05
-89	4.34619	6.06173E-05
-88.8	4.38629	6.31574E-05
-88.6	4.42637	6.59936E-05
-88.4	4.46638	6.82257E-05
-88.2	4.50639	7.09615E-05
-88	4.54638	7.37947E-05
-87.8	4.58636	7.62226E-05
-87.6	4.62631	7.87531E-05
-87.4	4.66621	8.1285E-05
-87.2	4.70611	8.39072E-05
-87	4.74598	8.66375E-05
-86.8	4.78584	8.91766E-05
-86.6	4.82571	9.17239E-05
-86.4	4.86555	9.41546E-05
-86.2	4.90535	9.66554E-05
-86	4.94517	9.9185E-05
-85.8	4.98495	0.000101592
-85.6	5.02468	0.00010418
-85.4	5.06445	0.000106791
-85.2	5.10417	0.000109236
-85	5.14387	0.000111867
-84.8	5.18355	0.000114414
-84.6	5.22322	0.000117018
-84.4	5.26281	0.000119644
-84.2	5.30241	0.000122182
-84	5.34196	0.000124594
-83.8	5.3815	0.000127066
-83.6	5.42102	0.000129686
-83.4	5.46055	0.000132174
-83.2	5.50005	0.000134847
-83	5.53954	0.000137412
-82.8	5.57904	0.000139929
-82.6	5.61852	0.000142649
-82.4	5.65801	0.000145412
-82.2	5.69748	0.000147994
-82	5.73697	0.000150783
-81.8	5.77645	0.000153506
-81.6	5.81587	0.000155977
-81.4	5.85537	0.000158726
-81.2	5.89486	0.000161571
-81	5.93437	0.000164094
-80.8	5.97388	0.000167013
-80.6	6.01337	0.000169625
-80.4	6.05286	0.000172432
-80.2	6.09237	0.000175129
-80	6.13185	0.000177825
-79.8	6.17138	0.000180553
-79.6	6.2109	0.000183446
-79.4	6.25042	0.000186224
-79.2	6.28989	0.000188735
-79	6.32929	0.00019146
-78.8	6.3687	0.000194228
-78.6	6.40809	0.00019692
-78.4	6.44749	0.000199496
-78.2	6.4869	0.000202195
-78	6.52629	0.000204888
-77.8	6.5657	0.000207511
-77.6	6.60508	0.000210147
-77.4	6.64445	0.000213124
-77.2	6.68379	0.000215769
-77	6.72316	0.000218561
-76.8	6.76253	0.00022116
-76.6	6.80191	0.000224051
-76.4	6.84129	0.000226646
-76.2	6.88067	0.000229452
-76	6.92003	0.000231956
-75.8	6.95937	0.000234375
-75.6	6.99869	0.000237159
-75.4	7.03804	0.000239866
-75.2	7.07742	0.000242671
-75	7.11683	0.000245362
-74.8	7.1562	0.000248292
-74.6	7.1956	0.000250785
-74.4	7.23497	0.000253528
-74.2	7.27438	0.000256338
-74	7.31377	0.000259109
-73.8	7.35321	0.000261816
-73.6	7.39265	0.000264522
-73.4	7.43207	0.000267362
-73.2	7.47149	0.000269911
-73	7.51092	0.000272607
-72.8	7.55036	0.000275168
-72.6	7.58977	0.000277965
-72.4	7.62919	0.000280511
-72.2	7.66859	0.000283317
-72	7.70801	0.000285921
-71.8	7.74742	0.000288729
-71.6	7.78683	0.000291338
-71.4	7.82627	0.000294247
-71.2	7.86565	0.00029696
-71	7.90504	0.000299574
-70.8	7.94443	0.000302307
-70.6	7.98381	0.000304815
-70.4	8.02318	0.000307454
-70.2	8.06262	0.000310088
-70	8.102	0.000312739
-69.8	8.14138	0.00031542
-69.6	8.18072	0.000318082
-69.4	8.22011	0.000320927
-69.2	8.25953	0.000323282
-69	8.29895	0.000326066
-68.8	8.33837	0.000328774
-68.6	8.37784	0.000331342
-68.4	8.41736	0.000334087
-68.2	8.45687	0.000336705
-68	8.49637	0.000339528
-67.8	8.53596	0.000341976
-67.6	8.57556	0.000344492
-67.4	8.61515	0.000347232
-67.2	8.65473	0.000349867
-67	8.69434	0.000352389
-66.8	8.73391	0.000355115
-66.6	8.77351	0.000357952
-66.4	8.81313	0.000360679
-66.2	8.85275	0.000363211
-66	8.89234	0.000365943
-65.8	8.93192	0.00036857
-65.6	8.97148	0.000371104
-65.4	9.01109	0.000373737
-65.2	9.05069	0.000376253
-65	9.09024	0.000378982
-64.8	9.12981	0.000381682
-64.6	9.16936	0.000384422
-64.4	9.20889	0.000386952
-64.2	9.24841	0.00038971
-64	9.28793	0.000392389
-63.8	9.32751	0.000394976
-63.6	9.36707	0.00039745
-63.4	9.40666	0.000400122
-63.2	9.44621	0.000402602
-63	9.48587	0.000405228
-62.8	9.52555	0.000407987
-62.6	9.5652	0.000410656
-62.4	9.60488	0.000413304
-62.2	9.64457	0.00041592
-62	9.68427	0.000418568
-61.8	9.72396	0.000421371
-61.6	9.76369	0.000423764
-61.4	9.80336	0.000426291
-61.2	9.8431	0.000428841
-61	9.8828	0.000431527
-60.8	9.92247	0.000433986
-60.6	9.96216	0.0004367
-60.4	10.00183	0.000439362
-60.2	10.04149	0.000441782
-60	10.08111	0.000444408
-59.8	10.1207	0.000447038
-59.6	10.16027	0.00044957
-59.4	10.19988	0.000452009
-59.2	10.23945	0.000454442
-59	10.27899	0.00045697
-58.8	10.31856	0.00045969
-58.6	10.35813	0.000462233
-58.4	10.39767	0.000464739
-58.2	10.43726	0.000467274
-58	10.47682	0.000469821
-57.8	10.5165	0.000472336
-57.6	10.55613	0.000474869
-57.4	10.59575	0.000477407
-57.2	10.6354	0.000479796
-57	10.67503	0.000482502
-56.8	10.71469	0.000485094
-56.6	10.7543	0.000487698
-56.4	10.79393	0.000490397
-56.2	10.83355	0.000492969
-56	10.87315	0.000495482
-55.8	10.91277	0.000497861
-55.6	10.95237	0.000500485
-55.4	10.99194	0.000502891
-55.2	11.03153	0.000505436
-55	11.07112	0.000508025
-54.8	11.1107	0.000510507
-54.6	11.15028	0.000513175
-54.4	11.18981	0.00051589
-54.2	11.22937	0.000518433
-54	11.26896	0.000520865
-53.8	11.30851	0.000523489
-53.6	11.34807	0.000525926
-53.4	11.38764	0.000528379
-53.2	11.42718	0.000531015
-53	11.46677	0.000533662
-52.8	11.50632	0.000536097
-52.6	11.54593	0.000538939
-52.4	11.58558	0.000541386
-52.2	11.62522	0.000544045
-52	11.66484	0.000546569
-51.8	11.70449	0.000549061
-51.6	11.74413	0.000551508
-51.4	11.78381	0.000554259
-51.2	11.82353	0.000556686
-51	11.86323	0.000559302
-50.8	11.90291	0.000561938
-50.6	11.94257	0.000564503
-50.4	11.98224	0.000566921
-50.2	12.02188	0.000569519
-50	12.0615	0.000572227
-49.8	12.10112	0.000574672
-49.6	12.1407	0.000577248
-49.4	12.18026	0.000579849
-49.2	12.2198	0.000582484
-49	12.2593	0.000585081
-48.8	12.29879	0.000587927
-48.6	12.33827	0.000590434
-48.4	12.37776	0.000593071
-48.2	12.41719	0.000595845
-48	12.45666	0.00059841
-47.8	12.49614	0.00060106
-47.6	12.53564	0.000603681
-47.4	12.57518	0.000606305
-47.2	12.61473	0.000608889
-47	12.65429	0.000611547
-46.8	12.69392	0.000614099
-46.6	12.7336	0.000616752
-46.4	12.77329	0.000619605
-46.2	12.81301	0.00062236
-46	12.85278	0.000625023
-45.8	12.89257	0.000627384
-45.6	12.93233	0.000629976
-45.4	12.97211	0.000632735
-45.2	13.0119	0.000635258
-45	13.0517	0.00063802
-44.8	13.09145	0.000640679
-44.6	13.13115	0.000643216
-44.4	13.17088	0.000645881
-44.2	13.21055	0.000648503
-44	13.25026	0.000651242
-43.8	13.28989	0.000653605
-43.6	13.32952	0.000656282
-43.4	13.36913	0.000658918
-43.2	13.40875	0.000661531
-43	13.44836	0.000664018
-42.8	13.48795	0.000666736
-42.6	13.52758	0.000669402
-42.4	13.56719	0.000671938
-42.2	13.60679	0.00067445
-42	13.64645	0.000676985
-41.8	13.68612	0.000679534
-41.6	13.72582	0.000681979
-41.4	13.76553	0.000684565
-41.2	13.80524	0.000686977
-41	13.84492	0.000689545
-40.8	13.88467	0.000692062
-40.6	13.92439	0.000694593
-40.4	13.96411	0.00069734
-40.2	14.00385	0.000699895
-40	14.04362	0.000702473
-39.8	14.08337	0.000704945
-39.6	14.12313	0.000707424
-39.4	14.1629	0.000709925
-39.2	14.20265	0.000712531
-39	14.24242	0.000715241
-38.8	14.28217	0.000717763
-38.6	14.32191	0.000720188
-38.4	14.36164	0.000722838
-38.2	14.4014	0.00072552
-38	14.44113	0.00072818
-37.8	14.48083	0.000730851
-37.6	14.52055	0.000733526
-37.4	14.56029	0.000735999
-37.2	14.60004	0.000738663
-37	14.63978	0.000741528
-36.8	14.67955	0.000744099
-36.6	14.71935	0.000746775
-36.4	14.75917	0.000749355
-36.2	14.79893	0.000752126
-36	14.83869	0.000754715
-35.8	14.87848	0.000757372
-35.6	14.91822	0.000760048
-35.4	14.95799	0.000762696
-35.2	14.99776	0.000765337
-35	15.03753	0.000768198
-34.8	15.07731	0.000770981
-34.6	15.11704	0.000773577
-34.4	15.15679	0.00077621
-34.2	15.19652	0.000778879
-34	15.23634	0.000781371
-33.8	15.27606	0.00078421
-33.6	15.31586	0.000786619
-33.4	15.35561	0.000789485
-33.2	15.39539	0.000792112
-33	15.43514	0.000794857
-32.8	15.47491	0.000797539
-32.6	15.51468	0.00080013
-32.4	15.55446	0.000802711
-32.2	15.5942	0.000805435
-32	15.63398	0.000808121
-31.8	15.6738	0.000810737
-31.6	15.71361	0.000813521
-31.4	15.75344	0.000816205
-31.2	15.79324	0.000818898
-31	15.83304	0.000821362
-30.8	15.8728	0.000824207
-30.6	15.9126	0.000826872
-30.4	15.95236	0.000829631
-30.2	15.99215	0.00083224
-30	16.03197	0.000834849
-29.8	16.07175	0.000837524
-29.6	16.11156	0.000840058
-29.4	16.15139	0.000842739
-29.2	16.1912	0.000845607
-29	16.23106	0.000848194
-28.8	16.27091	0.000851034
-28.6	16.31082	0.000853605
-28.4	16.35073	0.000856353
-28.2	16.39069	0.000858864
-28	16.43061	0.000861506
-27.8	16.47054	0.000864369
-27.6	16.51048	0.000867025
-27.4	16.55036	0.00086962
-27.2	16.59031	0.000872483
-27	16.63026	0.000874931
-26.8	16.67019	0.000877656
-26.6	16.71015	0.000880369
-26.4	16.75002	0.000882992
-26.2	16.78993	0.00088546
-26	16.82986	0.000888307
-25.8	16.86975	0.000890932
-25.6	16.90963	0.000893664
-25.4	16.94951	0.000896318
-25.2	16.98936	0.000898898
-25	17.02918	0.000901535
-24.8	17.06903	0.000904115
-24.6	17.10889	0.000906687
-24.4	17.14876	0.000909273
-24.2	17.18859	0.000911885
-24	17.2284	0.000914606
-23.8	17.26822	0.000917084
-23.6	17.30811	0.000919875
-23.4	17.34795	0.000922461
-23.2	17.38786	0.000925061
-23	17.42779	0.000927623
-22.8	17.46768	0.000930312
-22.6	17.50755	0.000932901
-22.4	17.54743	0.000935382
-22.2	17.58736	0.000938076
-22	17.62731	0.000940681
-21.8	17.66725	0.000943078
-21.6	17.70718	0.000945676
-21.4	17.74714	0.00094847
-21.2	17.78715	0.000950877
-21	17.82713	0.000953466
-20.8	17.86713	0.000956163
-20.6	17.90712	0.000958658
-20.4	17.94716	0.000961258
-20.2	17.98716	0.000963547
-20	18.02718	0.000966252
-19.8	18.06716	0.000968967
-19.6	18.10712	0.000971363
-19.4	18.14709	0.000973955
-19.2	18.18701	0.000976551
-19	18.22696	0.000979146
-18.8	18.26685	0.000981541
-18.6	18.30676	0.000984336
-18.4	18.34662	0.000987029
-18.2	18.38647	0.000989622
-18	18.42634	0.000992016
-17.8	18.46617	0.000994605
-17.6	18.50598	0.000997088
-17.4	18.54576	0.000999767
-17.2	18.58557	0.001002062
-17	18.62534	0.001004943
-16.8	18.66512	0.001007535
-16.6	18.70485	0.001010014
-16.4	18.74465	0.001012821
-16.2	18.78446	0.001015495
-16	18.82429	0.001017942
-15.8	18.86411	0.001020397
-15.6	18.90401	0.001022905
-15.4	18.94393	0.001025381
-15.2	18.98389	0.001027911
-15	19.02388	0.001030364
-14.8	19.0639	0.00103289
-14.6	19.10395	0.001035582
-14.4	19.14401	0.00103818
-14.2	19.18407	0.001040726
-14	19.22408	0.001043334
-13.8	19.26415	0.001045899
-13.6	19.30418	0.00104846
-13.4	19.34421	0.001050976
-13.2	19.38421	0.001053475
-13	19.42417	0.00105586
-12.8	19.46412	0.001058565
-12.6	19.50406	0.001060948
-12.4	19.54398	0.001063663
-12.2	19.58391	0.001066121
-12	19.62384	0.001068803
-11.8	19.66378	0.001071115
-11.6	19.70365	0.001073936
-11.4	19.74352	0.001076252
-11.2	19.78337	0.001078879
-11	19.8232	0.001081258
-10.8	19.86305	0.001083723
-10.6	19.90291	0.001086227
-10.4	19.94277	0.001088842
-10.2	19.9826	0.001091497
-10	20.02245	0.001093874
-9.8	20.06226	0.001096423
-9.6	20.10212	0.001099038
-9.4	20.142	0.001101579
-9.2	20.18187	0.001103802
-9	20.22178	0.001106513
-8.8	20.26169	0.00110899
-8.6	20.30157	0.001111496
-8.4	20.34151	0.001113852
-8.2	20.38147	0.001116615
-8	20.42144	0.001118931
-7.8	20.4614	0.001121671
-7.6	20.50135	0.00112411
-7.4	20.54132	0.001126621
-7.2	20.5813	0.001129212
-7	20.62127	0.001131742
-6.8	20.66122	0.001134222
-6.6	20.7012	0.001136723
-6.4	20.74113	0.001139297
-6.2	20.78106	0.0011416
-6	20.82097	0.001144202
-5.8	20.8609	0.001146581
-5.6	20.90082	0.001149131
-5.4	20.94074	0.001151667
-5.2	20.98064	0.001154217
-5	21.02053	0.001156697
-4.8	21.06044	0.00115927
-4.6	21.10034	0.001161584
-4.4	21.14026	0.001164183
-4.2	21.18017	0.001166764
-4	21.22009	0.001169222
-3.8	21.26002	0.001171679
-3.6	21.29998	0.001174286
-3.4	21.33991	0.00117679
-3.2	21.37985	0.001179494
-3	21.41981	0.001182085
-2.8	21.45974	0.001184751
-2.6	21.4997	0.001187386
-2.4	21.53969	0.001190066
-2.2	21.57967	0.001192565
-2	21.61963	0.001195322
-1.8	21.65956	0.001197688
-1.6	21.69952	0.00120031
-1.4	21.73945	0.001202833
-1.2	21.7794	0.001205516
-1	21.81935	0.001208081
-0.8	21.85935	0.00121079
-0.6	21.89931	0.001213441
-0.4	21.93923	0.001215916
-0.2	21.97917	0.001218542
0	22.01907	0.001221344
0.2	22.05897	0.001223749
0.4	22.09887	0.001226327
0.6	22.13878	0.001228868
0.8	22.17872	0.001231443
1	22.21863	0.001234088
1.2	22.25849	0.001236784
1.4	22.29844	0.001239468
1.6	22.3384	0.001241772
1.8	22.37835	0.001244643
2	22.41833	0.001247267
2.2	22.45836	0.001249955
2.4	22.49838	0.001252391
2.6	22.53841	0.001254989
2.8	22.57845	0.001257556
3	22.61852	0.001259989
3.2	22.65864	0.001262612
3.4	22.6987	0.001265314
3.6	22.73875	0.001267863
3.8	22.77882	0.001270345
4	22.81887	0.001272949
4.2	22.85889	0.001275476
4.4	22.89887	0.001277865
4.6	22.93888	0.001280338
4.8	22.97881	0.001282796
5	23.01871	0.001285268
5.2	23.05858	0.001287616
5.4	23.09843	0.001290131
5.6	23.13826	0.001292637
5.8	23.17806	0.00129494
6	23.21789	0.001297465
6.2	23.25773	0.001300022
6.4	23.29757	0.001302559
6.6	23.33739	0.00130493
6.8	23.37723	0.001307536
7	23.41707	0.001309838
7.2	23.45691	0.00131277
7.4	23.49675	0.001315013
7.6	23.53662	0.001317409
7.8	23.5765	0.001319783
8	23.61637	0.001322104
8.2	23.65623	0.00132452
8.4	23.69608	0.001327272
8.6	23.73601	0.001329766
8.8	23.77594	0.001332562
9	23.8159	0.001334928
9.2	23.85588	0.001337624
9.4	23.89586	0.001340156
9.6	23.9358	0.001342567
9.8	23.9758	0.001345126
10	24.01578	0.001347793
10.2	24.05578	0.001350098
10.4	24.09576	0.001352583
10.6	24.13571	0.001355075
10.8	24.17565	0.001357647
11	24.21558	0.001360437
11.2	24.25549	0.001362758
11.4	24.29546	0.001365473
11.6	24.33542	0.001367801
11.8	24.37535	0.001370379
12	24.41529	0.001372688
12.2	24.45524	0.001375393
12.4	24.49519	0.001377916
12.6	24.53512	0.001380382
12.8	24.57504	0.001382836
13	24.61498	0.001385359
13.2	24.65491	0.001387946
13.4	24.69483	0.001390584
13.6	24.73476	0.001392987
13.8	24.77469	0.001395576
14	24.81458	0.001398078
14.2	24.85449	0.001400385
14.4	24.89438	0.001402788
14.6	24.93433	0.001405308
14.8	24.97425	0.001407835
15	25.01422	0.001410437
15.2	25.0542	0.001412645
15.4	25.09417	0.001415389
15.6	25.13415	0.00141779
15.8	25.17417	0.001420514
16	25.21419	0.001422908
16.2	25.25424	0.001425527
16.4	25.29431	0.001427924
16.6	25.33436	0.001430247
16.8	25.37443	0.001432773
17	25.41448	0.001435488
17.2	25.45449	0.001438014
17.4	25.49446	0.001440541
17.6	25.53442	0.001443064
17.8	25.57438	0.001445575
18	25.61431	0.001448286
18.2	25.65425	0.001450581
18.4	25.69419	0.001453196
18.6	25.73411	0.001455511
18.8	25.774	0.001458413
19	25.81392	0.001460413
19.2	25.85386	0.001463023
19.4	25.89382	0.001465549
19.6	25.93378	0.00146817
19.8	25.97375	0.001470485
20	26.01373	0.001473
20.2	26.05374	0.001475521
20.4	26.09372	0.001478231
20.6	26.13374	0.001480542
20.8	26.17377	0.001483063
21	26.21374	0.001485368
21.2	26.25371	0.001487981
21.4	26.29371	0.001490501
21.6	26.33379	0.001492722
21.8	26.37382	0.001495146
22	26.41387	0.001497572
22.2	26.45389	0.001500186
22.4	26.4939	0.001502705
22.6	26.53391	0.001505216
22.8	26.5739	0.001507531
23	26.61393	0.001509936
23.2	26.65399	0.001512357
23.4	26.694	0.001514879
23.6	26.734	0.001517103
23.8	26.77402	0.001519728
24	26.81398	0.00152214
24.2	26.85394	0.00152446
24.4	26.89391	0.001526888
24.6	26.93383	0.001529687
24.8	26.97375	0.00153179
25	27.01368	0.001534511
25.2	27.05362	0.001536917
25.4	27.09355	0.001539231
25.6	27.13342	0.001541746
25.8	27.17331	0.001544158
26	27.2132	0.001546267
26.2	27.25319	0.001548983
26.4	27.29317	0.001551097
26.6	27.33316	0.001553819
26.8	27.37317	0.001556238
27	27.4132	0.001558859
27.2	27.4532	0.001560974
27.4	27.49321	0.001563393
27.6	27.53326	0.00156612
27.8	27.57329	0.001568438
28	27.61329	0.001570756
28.2	27.65332	0.001572874
28.4	27.69333	0.001575495
28.6	27.73333	0.001577914
28.8	27.77335	0.001580433
29	27.81336	0.001582854
29.2	27.85335	0.001585473
29.4	27.89337	0.001587591
29.6	27.93338	0.001590313
29.8	27.9734	0.001592633
30	28.01341	0.001595152
30.2	28.05338	0.00159727
30.4	28.09333	0.001599483
30.6	28.13329	0.001601901
30.8	28.17326	0.00160442
31	28.21322	0.001606836
31.2	28.25318	0.001609453
31.4	28.29313	0.001611773
31.6	28.33309	0.001614391
31.8	28.37306	0.001616607
32	28.41299	0.001619022
32.2	28.45296	0.00162114
32.4	28.49294	0.001623562
32.6	28.53295	0.001625884
32.8	28.57293	0.001628302
33	28.61295	0.001630429
33.2	28.65293	0.001632734
33.4	28.69298	0.001635157
33.6	28.73296	0.001637667
33.8	28.77297	0.001640098
34	28.81295	0.001642414
34.2	28.85297	0.001644847
34.4	28.89296	0.001646961
34.6	28.93297	0.001649391
34.8	28.97302	0.001651508
35	29.01306	0.001654032
35.2	29.05313	0.001656153
35.4	29.09314	0.001658677
35.6	29.13315	0.001661196
35.8	29.1732	0.001663516
36	29.21328	0.001665843
36.2	29.25329	0.001668368
36.4	29.29333	0.001670592
36.6	29.33328	0.001672911
36.8	29.37319	0.001675126
37	29.41308	0.001677443
37.2	29.45297	0.00167976
37.4	29.49287	0.001682077
37.6	29.53277	0.001684585
37.8	29.57265	0.001686988
38	29.61257	0.00168921
38.2	29.6525	0.001691722
38.4	29.69244	0.001693956
38.6	29.73243	0.001696385
38.8	29.77241	0.001698708
39	29.8124	0.001701142
39.2	29.85241	0.00170327
39.4	29.89238	0.001705576
39.6	29.93235	0.001707994
39.8	29.97235	0.001710189
40	30.0123	0.001712705
40.2	30.05223	0.00171502
40.4	30.09215	0.001717349
40.6	30.13206	0.00171969
40.8	30.17199	0.001722079
41	30.21191	0.001724617
41.2	30.25183	0.00172686
41.4	30.29173	0.001728985
41.6	30.33168	0.001731488
41.8	30.37159	0.001733709
42	30.4115	0.00173591
42.2	30.45144	0.001738223
42.4	30.49138	0.001740529
42.6	30.5313	0.001743065
42.8	30.57124	0.001745263
43	30.61118	0.001747626
43.2	30.6511	0.001750121
43.4	30.69102	0.001752495
43.6	30.73095	0.001754689
43.8	30.77087	0.001756839
44	30.81082	0.001759034
44.2	30.85078	0.001761448
44.4	30.89071	0.001763468
44.6	30.93068	0.001765963
44.8	30.97065	0.001768152
45	31.01061	0.00177058
45.2	31.05056	0.001773028
45.4	31.09054	0.001775285
45.6	31.13056	0.001777534
45.8	31.17057	0.001780069
46	31.21062	0.001782086
46.2	31.25066	0.001784536
46.4	31.29076	0.001786833
46.6	31.33083	0.001789239
46.8	31.3709	0.001791586
47	31.411	0.001793899
47.2	31.45104	0.001796296
47.4	31.49115	0.001798738
47.6	31.53123	0.001801089
47.8	31.5713	0.001803514
48	31.61131	0.001805942
48.2	31.65129	0.001808216
48.4	31.69126	0.001810421
48.6	31.73118	0.001812735
48.8	31.7711	0.001815059
49	31.81098	0.001817655
49.2	31.8509	0.001819766
49.4	31.89077	0.00182226
49.6	31.93063	0.001824556
49.8	31.97051	0.001827098
50	32.01038	0.001829389
50.2	32.05027	0.001831575
50.4	32.09014	0.001833984
50.6	32.13003	0.001836276
50.8	32.16995	0.001838625
51	32.20985	0.001840885
51.2	32.24974	0.001843306
51.4	32.28962	0.001845764
51.6	32.32951	0.001847822
51.8	32.3694	0.001850206
52	32.40934	0.001852645
52.2	32.44927	0.001854774
52.4	32.48922	0.001856978
52.6	32.52915	0.001859168
52.8	32.56909	0.001861574
53	32.60905	0.001863791
53.2	32.64905	0.001866087
53.4	32.68905	0.001868295
53.6	32.72904	0.001870492
53.8	32.76901	0.001872723
54	32.80896	0.00187508
54.2	32.84892	0.00187733
54.4	32.88891	0.001879827
54.6	32.92892	0.001881824
54.8	32.96894	0.001884116
55	33.00894	0.001886293
55.2	33.04889	0.001888297
55.4	33.08888	0.001890586
55.6	33.12886	0.001892616
55.8	33.16888	0.001894805
56	33.20888	0.001896961
56.2	33.24885	0.001899219
56.4	33.28882	0.001901253
56.6	33.32875	0.001903595
56.8	33.3687	0.001905765
57	33.40865	0.001907966
57.2	33.44862	0.001909977
57.4	33.48861	0.001912212
57.6	33.52858	0.001914248
57.8	33.56857	0.001916433
58	33.60857	0.00191856
58.2	33.64856	0.001920678
58.4	33.68855	0.001922964
58.6	33.72855	0.001924952
58.8	33.76853	0.001927157
59	33.80851	0.001929435
59.2	33.84845	0.001931519
59.4	33.88842	0.001933774
59.6	33.9284	0.001935786
59.8	33.96835	0.001937924
60	34.0083	0.001940139
60.2	34.04828	0.001942208
60.4	34.08826	0.001944473
60.6	34.12829	0.001946707
60.8	34.1683	0.001948912
61	34.20831	0.001951265
61.2	34.24835	0.001953356
61.4	34.28839	0.001955654
61.6	34.3284	0.001957907
61.8	34.36847	0.00195994
62	34.4085	0.001962144
62.2	34.44856	0.001964193
62.4	34.48861	0.001966486
62.6	34.52863	0.001968554
62.8	34.56864	0.00197089
63	34.60864	0.001973047
63.2	34.64862	0.001975438
63.4	34.68859	0.001977564
63.6	34.72859	0.001979589
63.8	34.76855	0.001981632
64	34.80854	0.001983989
64.2	34.84848	0.001986116
64.4	34.88842	0.001988188
64.6	34.92838	0.001990305
64.8	34.96834	0.001992373
65	35.00828	0.001994567
65.2	35.04821	0.001996889
65.4	35.08814	0.001998987
65.6	35.12813	0.0020011
65.8	35.16814	0.002003336
66	35.2081	0.002005515
66.2	35.24814	0.002007723
66.4	35.28817	0.002009732
66.6	35.3282	0.0020117
66.8	35.36825	0.002013839
67	35.40827	0.002015856
67.2	35.44833	0.002018008
67.4	35.48843	0.002020198
67.6	35.52848	0.002022289
67.8	35.56852	0.002024498
68	35.60854	0.002026545
68.2	35.64852	0.002028803
68.4	35.68849	0.002030673
68.6	35.72845	0.002032851
68.8	35.76839	0.002034699
69	35.80833	0.002036904
69.2	35.84831	0.002038964
69.4	35.88818	0.002041001
69.6	35.92808	0.002042947
69.8	35.968	0.002045064
70	36.0079	0.002047093
70.2	36.04786	0.002049262
70.4	36.08776	0.002051434
70.6	36.12769	0.00205356
70.8	36.16767	0.002055429
71	36.20762	0.002057602
71.2	36.24758	0.002059599
71.4	36.28759	0.002061628
71.6	36.32763	0.002063597
71.8	36.36765	0.002065605
72	36.40771	0.002067704
72.2	36.44772	0.002069731
72.4	36.48775	0.002071673
72.6	36.5278	0.002073832
72.8	36.56781	0.002075757
73	36.60782	0.002077729
73.2	36.6478	0.002079775
73.4	36.68776	0.002081809
73.6	36.72774	0.002083742
73.8	36.76768	0.002085599
74	36.80766	0.002087697
74.2	36.84761	0.002089654
74.4	36.88757	0.002091565
74.6	36.92748	0.002093351
74.8	36.96743	0.002095538
75	37.00735	0.002097462
75.2	37.04732	0.002099478
75.4	37.08729	0.002101326
75.6	37.12726	0.002103235
75.8	37.16724	0.002105202
76	37.20714	0.002106998
76.2	37.24707	0.002108971
76.4	37.28702	0.002110846
76.6	37.32697	0.0021128
76.8	37.36699	0.002114794
77	37.40704	0.00211669
77.2	37.44709	0.002118607
77.4	37.48716	0.002120479
77.6	37.5272	0.002122422
77.8	37.5672	0.002124338
78	37.60723	0.002126152
78.2	37.64731	0.002128086
78.4	37.68737	0.00212981
78.6	37.72746	0.002131731
78.8	37.7675	0.002133652
79	37.80751	0.002135547
79.2	37.84752	0.002137375
79.4	37.88754	0.002139302
79.6	37.92756	0.002141079
79.8	37.96764	0.002143024
80	38.00772	0.002144839
80.2	38.0477	0.002146703
80.4	38.08769	0.002148476
80.6	38.12767	0.002150289
80.8	38.16764	0.002151962
81	38.2076	0.00215384
81.2	38.24756	0.002155764
81.4	38.28747	0.002157544
81.6	38.32737	0.002159423
81.8	38.36725	0.002161265
82	38.40713	0.002163043
82.2	38.44703	0.002164829
82.4	38.48697	0.002166492
82.6	38.52687	0.002168229
82.8	38.56676	0.002169938
83	38.60669	0.002171655
83.2	38.64661	0.002173544
83.4	38.68655	0.002175293
83.6	38.72652	0.002177258
83.8	38.76652	0.002178731
84	38.80649	0.002180674
84.2	38.84646	0.002182501
84.4	38.88642	0.002184209
84.6	38.92642	0.002185744
84.8	38.96643	0.002187479
85	39.00644	0.002189098
85.2	39.04652	0.002190757
85.4	39.08664	0.002192367
85.6	39.12676	0.002194241
85.8	39.16685	0.002195917
86	39.20698	0.002197634
86.2	39.24711	0.002199303
86.4	39.28725	0.002201026
86.6	39.32735	0.002202688
86.8	39.36742	0.002204428
87	39.4075	0.002205994
87.2	39.44756	0.00220751
87.4	39.48755	0.002209193
87.6	39.52752	0.00221078
87.8	39.56751	0.002212424
88	39.60749	0.002214218
88.2	39.64744	0.002215919
88.4	39.68741	0.002217339
88.6	39.72737	0.002219141
88.8	39.76736	0.002220718
89	39.8073	0.002222199
89.2	39.84726	0.00222383
89.4	39.8872	0.002225504
89.6	39.92718	0.002226899
89.8	39.96716	0.002228642
90	40.00707	0.002230165
90.2	40.047	0.002231823
90.4	40.08693	0.002233416
90.6	40.12682	0.002234994
90.8	40.16666	0.002236471
91	40.20659	0.002238111
91.2	40.24647	0.002239441
91.4	40.28637	0.002240965
91.6	40.3263	0.002242506
91.8	40.36622	0.002243956
92	40.40617	0.002245363
92.2	40.44611	0.002246776
92.4	40.48607	0.002248425
92.6	40.52603	0.002249721
92.8	40.56605	0.002251279
93	40.60605	0.002252664
93.2	40.64604	0.002254345
93.4	40.68601	0.002255671
93.6	40.7259	0.002257221
93.8	40.76582	0.002258578
94	40.80573	0.002259917
94.2	40.8457	0.002261102
94.4	40.88569	0.002262637
94.6	40.92564	0.00226394
94.8	40.96561	0.002265406
95	41.00559	0.002266755
95.2	41.04558	0.002268205
95.4	41.08557	0.002269562
95.6	41.12562	0.002271154
95.8	41.16567	0.002272345
96	41.20568	0.002273602
96.2	41.24568	0.002274945
96.4	41.28566	0.002276382
96.6	41.32564	0.002277475
96.8	41.36566	0.00227885
97	41.40566	0.002280136
97.2	41.44571	0.002281485
97.4	41.48577	0.0022828
97.6	41.5258	0.002284131
97.8	41.56585	0.002285384
98	41.6059	0.002286725
98.2	41.64597	0.00228802
98.4	41.68606	0.002288958
98.6	41.72615	0.0022901
98.8	41.7662	0.002291367
99	41.80625	0.002292596
99.2	41.84628	0.002293622
99.4	41.88627	0.002295008
99.6	41.92628	0.002296148
99.8	41.96626	0.002297335
100	42.00622	0.002298622
100.2	42.04616	0.002299821
100.4	42.08609	0.002300874
100.6	42.12601	0.002301913
100.8	42.16594	0.002303017
101	42.20585	0.002304131
101.2	42.24578	0.002305117
101.4	42.28572	0.002306192
101.6	42.32563	0.002307232
101.8	42.3656	0.002308439
102	42.40559	0.002309448
102.2	42.44556	0.00231058
102.4	42.48554	0.002311714
102.6	42.52557	0.002312648
102.8	42.56559	0.002313699
103	42.60564	0.002314485
103.2	42.6457	0.002315497
103.4	42.68571	0.002316495
103.6	42.72572	0.002317504
103.8	42.76575	0.002318361
104	42.80575	0.00231939
104.2	42.84577	0.002320415
104.4	42.88575	0.002321432
104.6	42.9257	0.002322261
104.8	42.96563	0.00232325
105	43.00556	0.002324185
105.2	43.04548	0.002325131
105.4	43.08544	0.002325801
105.6	43.12542	0.002326721
105.8	43.16537	0.00232765
106	43.20526	0.002328542
106.2	43.24523	0.002329233
106.4	43.28516	0.002330149
106.6	43.32513	0.002331001
106.8	43.36509	0.002331831
107	43.405	0.002332595
107.2	43.44497	0.002333446
107.4	43.48492	0.002334366
107.6	43.5249	0.002335118
107.8	43.56486	0.002335711
108	43.60489	0.002336287
108.2	43.64494	0.002337163
108.4	43.685	0.0023378
108.6	43.72505	0.002338589
108.8	43.76511	0.002339296
109	43.80519	0.002340157
109.2	43.84525	0.002340661
109.4	43.88527	0.002341449
109.6	43.92529	0.002341987
109.8	43.96531	0.002342726
110	44.00533	0.002343227
110.2	44.04526	0.00234378
110.4	44.08519	0.002344307
110.6	44.12512	0.002344989
110.8	44.16501	0.002345421
111	44.20495	0.002346111
111.2	44.24489	0.002346479
111.4	44.28482	0.002346972
111.6	44.32473	0.002347597
111.8	44.36462	0.002348074
112	44.40449	0.002348446
112.2	44.44442	0.002348985
112.4	44.48437	0.002349275
112.6	44.52435	0.002349676
112.8	44.56433	0.002349967
113	44.60432	0.002350492
113.2	44.64433	0.002350904
113.4	44.68435	0.002351286
113.6	44.72441	0.002351702
113.8	44.76449	0.00235219
114	44.80458	0.002352501
114.2	44.84468	0.002352541
114.4	44.88472	0.002352909
114.6	44.92484	0.002353013
114.8	44.96493	0.002353148
115	45.00504	0.002353321
115.2	45.04516	0.002353674
115.4	45.08526	0.0023539
115.6	45.12538	0.002354153
115.8	45.16552	0.002354355
116	45.20561	0.002354687
116.2	45.24571	0.002354689
116.4	45.28582	0.002354947
116.6	45.32589	0.00235491
116.8	45.36593	0.002355029
117	45.40593	0.002355099
117.2	45.44588	0.002355106
117.4	45.48581	0.002354974
117.6	45.52572	0.002355131
117.8	45.5656	0.002355135
118	45.60548	0.002355276		118	0.002355276
118.2	45.64533	0.002355132		48	-0.000380613	-7.92944E-06
118.4	45.68518	0.002355231
118.6	45.72507	0.002355059
118.8	45.76495	0.002355002
119	45.80484	0.002354927
119.2	45.84476	0.00235473
119.4	45.8847	0.00235465
119.6	45.92463	0.002354556
119.8	45.96457	0.002354406
120	46.00451	0.002354278
120.2	46.04448	0.002354112
120.4	46.08447	0.002353901
120.6	46.1244	0.002353735
120.8	46.16436	0.002353336
121	46.20431	0.002353206
121.2	46.24427	0.00235287
121.4	46.2842	0.002352519
121.6	46.32417	0.0023521
121.8	46.36415	0.002351817
122	46.40416	0.002351301
122.2	46.44414	0.002350938
122.4	46.48411	0.002350534
122.6	46.52412	0.002350093
122.8	46.56413	0.002349631
123	46.60413	0.002349266
123.2	46.64414	0.002348651
123.4	46.68416	0.002348203
123.6	46.72419	0.002347806
123.8	46.76422	0.002346959
124	46.8042	0.002346448
124.2	46.84422	0.002345704
124.4	46.88422	0.002345026
124.6	46.92426	0.002344443
124.8	46.96429	0.002343821
125	47.0043	0.002343093
125.2	47.04431	0.002342522
125.4	47.08433	0.002341803
125.6	47.12432	0.002341139
125.8	47.16433	0.002340388
126	47.20434	0.002339639
126.2	47.24433	0.002338567
126.4	47.28434	0.002337707
126.6	47.3243	0.002336774
126.8	47.36429	0.002335845
127	47.40424	0.002335026
127.2	47.44422	0.002334263
127.4	47.48418	0.002333341
127.6	47.52415	0.002332449
127.8	47.56407	0.002331429
128	47.60403	0.002330437
128.2	47.64399	0.002329246
128.4	47.68391	0.00232806
128.6	47.72382	0.002327063
128.8	47.76374	0.002325901
129	47.80367	0.002324717
129.2	47.84364	0.002323571
129.4	47.88358	0.002322361
129.6	47.92356	0.002321353
129.8	47.96354	0.002320218
130	48.00351	0.002319037
130.2	48.0435	0.002317701
130.4	48.08349	0.002316272
130.6	48.12353	0.002314858
130.8	48.16355	0.002313571
131	48.20357	0.002312286
131.2	48.24357	0.002310706
131.4	48.28357	0.00230934
131.6	48.32355	0.002307907
131.8	48.36355	0.002306706
132	48.4035	0.002305148
132.2	48.44348	0.002303856
132.4	48.48343	0.002302187
132.6	48.52339	0.002300776
132.8	48.56331	0.002299049
133	48.60325	0.002297572
133.2	48.64318	0.002295869
133.4	48.68311	0.002294325
133.6	48.72306	0.002292756
133.8	48.76304	0.002291116
134	48.80303	0.002289326
134.2	48.84298	0.002287853
134.4	48.88296	0.002286232
134.6	48.92296	0.002284417
134.8	48.96296	0.002282775
135	49.00296	0.002280767
135.2	49.04298	0.002279062
135.4	49.083	0.002277205
135.6	49.12305	0.002275313
135.8	49.16306	0.002273356
136	49.20308	0.002271585
136.2	49.24314	0.002269482
136.4	49.28318	0.002267621
136.6	49.32326	0.002265658
136.8	49.36331	0.002263743
137	49.40338	0.002261606
137.2	49.44344	0.002259616
137.4	49.48349	0.002257502
137.6	49.52352	0.002255515
137.8	49.56358	0.002253337
138	49.60361	0.002251248
138.2	49.64363	0.002248991
138.4	49.68364	0.002246962
138.6	49.72362	0.002244816
138.8	49.76363	0.002242801
139	49.80362	0.002240483
139.2	49.84362	0.002238267
139.4	49.88364	0.002236246
139.6	49.92366	0.002233837
139.8	49.96367	0.002231552
140	50.00369	0.002229087
140.2	50.04372	0.002226904
140.4	50.08374	0.002224471
140.6	50.12377	0.002222214
140.8	50.16375	0.00222001
141	50.20371	0.002217731
141.2	50.24367	0.002215437
141.4	50.28363	0.002213194
141.6	50.32358	0.002210649
141.8	50.3635	0.002208323
142	50.40344	0.002205666
142.2	50.44331	0.002203209
142.4	50.48326	0.002200681
142.6	50.52319	0.002198195
142.8	50.56309	0.00219576
143	50.60307	0.002193467
143.2	50.64304	0.002190899
143.4	50.68301	0.00218856
143.6	50.72301	0.002185938
143.8	50.76305	0.002183496
144	50.80308	0.002180951
144.2	50.84317	0.002178366
144.4	50.88325	0.002175529
144.6	50.92332	0.002173157
144.8	50.96345	0.002170413
145	51.00361	0.002167874
145.2	51.04372	0.002165503
145.4	51.08385	0.002162702
145.6	51.12396	0.002160237
145.8	51.16404	0.00215763
146	51.20411	0.002155038
146.2	51.24418	0.002152342
146.4	51.28427	0.002149831
146.6	51.32431	0.002146866
146.8	51.36435	0.00214421
147	51.40437	0.002141473
147.2	51.44437	0.002139054
147.4	51.48438	0.002136384
147.6	51.52439	0.002133622
147.8	51.56438	0.002131097
148	51.60438	0.002128486
148.2	51.64434	0.002125846
148.4	51.68421	0.002122985
148.6	51.72414	0.002120279
148.8	51.76406	0.002117711
149	51.80395	0.002114955
149.2	51.84384	0.002112319
149.4	51.88374	0.002109566
149.6	51.92362	0.002106862
149.8	51.96351	0.002104261
150	52.00338	0.002101602
150.2	52.04326	0.002098872
150.4	52.08318	0.002096388
150.6	52.12313	0.002093824
150.8	52.16303	0.002091095
151	52.203	0.002088608
151.2	52.24294	0.002086045
151.4	52.28293	0.002083381
151.6	52.32296	0.002080588
151.8	52.36304	0.002078267
152	52.40317	0.002075515
152.2	52.44332	0.002073212
152.4	52.48344	0.002070577
152.6	52.52356	0.00206818
152.8	52.56371	0.00206578
153	52.60387	0.00206334
153.2	52.64406	0.002060727
153.4	52.68422	0.002058368
153.6	52.72436	0.002055842
153.8	52.76448	0.002053473
154	52.80454	0.002050896
154.2	52.8446	0.002048684
154.4	52.88468	0.002046299
154.6	52.92474	0.002043917
154.8	52.96477	0.002041816
155	53.00476	0.00203972
155.2	53.04472	0.002037493
155.4	53.0847	0.002035222
155.6	53.12467	0.00203287
155.8	53.16458	0.002030686
156	53.20448	0.002028595
156.2	53.24437	0.002026427
156.4	53.28427	0.002024433
156.6	53.32417	0.002022459
156.8	53.36409	0.002020485
157	53.40402	0.002018763
157.2	53.44393	0.00201692
157.4	53.4838	0.002015266
157.6	53.52371	0.002013412
157.8	53.56358	0.002011601
158	53.6035	0.002009949
158.2	53.64345	0.002008179
158.4	53.68335	0.002006707
158.6	53.72325	0.002004946
158.8	53.7631	0.002003489
159	53.803	0.002002033
159.2	53.84293	0.002000508
159.4	53.88286	0.001999257
159.6	53.92282	0.001997792
159.8	53.96279	0.001996461
160	54.00274	0.001995076
160.2	54.04268	0.001993854
160.4	54.08268	0.001992579
160.6	54.12267	0.001991285
160.8	54.16272	0.001990203
161	54.20275	0.001988942
161.2	54.24277	0.001988344
161.4	54.2828	0.001987346
161.6	54.32284	0.001986366
161.8	54.36286	0.001985251
162	54.4029	0.001984446
162.2	54.44293	0.001983434
162.4	54.48297	0.001982567
162.6	54.52298	0.001981661
162.8	54.56301	0.001980746
163	54.60303	0.001980219
163.2	54.64308	0.00197957
163.4	54.6831	0.001978915
163.6	54.72316	0.001978385
163.8	54.76316	0.001977816
164	54.8032	0.001977335
164.2	54.84325	0.001976984
164.4	54.88326	0.001976501
164.6	54.92326	0.00197602
164.8	54.96325	0.001975775
165	55.00323	0.001975453
165.2	55.0432	0.001975213
165.4	55.08316	0.001975165
165.6	55.1231	0.001974778
165.8	55.16305	0.001974678
166	55.203	0.001974663
166.2	55.24292	0.001974927
166.4	55.28289	0.001974817
166.6	55.32287	0.001974991
166.8	55.36284	0.001974976
167	55.40283	0.001975231
167.2	55.44279	0.001975347
167.4	55.48279	0.001975505
167.6	55.52279	0.001975881
167.8	55.56276	0.00197614
168	55.60284	0.001976572
168.2	55.64289	0.001977028
168.4	55.68299	0.001977649
168.6	55.72302	0.001978237
168.8	55.76311	0.00197896
169	55.80317	0.00197947
169.2	55.84325	0.001980116
169.4	55.88332	0.001980882
169.6	55.92336	0.001981581
169.8	55.96343	0.001982268
170	56.00347	0.001983177
170.2	56.04349	0.001984068
170.4	56.08344	0.001985018
170.6	56.12343	0.001985963
170.8	56.16339	0.001987085
171	56.20338	0.001988048
171.2	56.24334	0.001989083
171.4	56.28327	0.001990174
171.6	56.32321	0.00199123
171.8	56.36318	0.00199237
172	56.40315	0.001993551
172.2	56.44311	0.001994697
172.4	56.4831	0.001996127
172.6	56.52308	0.001997535
172.8	56.56309	0.001998915
173	56.60311	0.002000494
173.2	56.64313	0.002002026
173.4	56.68317	0.002003619
173.6	56.72321	0.002005093
173.8	56.76321	0.002006722
174	56.80321	0.002008148
174.2	56.84324	0.002010104
174.4	56.88323	0.002011843
174.6	56.92319	0.002013709
174.8	56.96316	0.002015381
175	57.00315	0.00201752
175.2	57.04314	0.002019384
175.4	57.08315	0.002021504
175.6	57.12317	0.00202346
175.8	57.16322	0.002025494
176	57.20326	0.002027527
176.2	57.24329	0.002029597
176.4	57.28332	0.002031752
176.6	57.32339	0.002034037
176.8	57.36347	0.002036224
177	57.4035	0.002038712
177.2	57.44354	0.002041168
177.4	57.48358	0.002043819
177.6	57.52362	0.002046225
177.8	57.56363	0.002048959
178	57.60366	0.002051352
178.2	57.64371	0.002054059
178.4	57.68377	0.002056765
178.6	57.72385	0.002059375
178.8	57.76391	0.002062114
179	57.80398	0.002065076
179.2	57.84404	0.002067972
179.4	57.8841	0.002070837
179.6	57.92411	0.002073833
179.8	57.96413	0.0020768
180	58.00415	0.002079687
180.2	58.04417	0.002082699
180.4	58.08411	0.002085598
180.6	58.12404	0.002088868
180.8	58.16395	0.002091861
181	58.20385	0.002094944
181.2	58.24376	0.002098256
181.4	58.28368	0.002101529
181.6	58.32358	0.002104901
181.8	58.36352	0.002108176
182	58.40343	0.002111444
182.2	58.44333	0.002114781
182.4	58.48325	0.00211817
182.6	58.52316	0.00212159
182.8	58.5631	0.002124858
183	58.60304	0.002128393
183.2	58.64297	0.002131982
183.4	58.68289	0.002135514
183.6	58.72286	0.002139124
183.8	58.76284	0.002142556
184	58.80285	0.002146323
184.2	58.84288	0.002149808
184.4	58.88291	0.002153788
184.6	58.92296	0.002157393
184.8	58.96301	0.002161174
185	59.00305	0.00216481
185.2	59.04311	0.002168562
185.4	59.08317	0.002172368
185.6	59.1232	0.002176098
185.8	59.16324	0.002179935
186	59.20325	0.002183919
186.2	59.24325	0.002187776
186.4	59.28325	0.002191608
186.6	59.32328	0.002195736
186.8	59.36326	0.002199541
187	59.40328	0.002203656
187.2	59.44329	0.002207515
187.4	59.4833	0.002211461
187.6	59.5233	0.002215381
187.8	59.56333	0.002219452
188	59.60337	0.002223236
188.2	59.64337	0.002227397
188.4	59.68336	0.002231482
188.6	59.72334	0.002235598
188.8	59.76338	0.002239856
189	59.80339	0.002243919
189.2	59.84343	0.002247932
189.4	59.88349	0.002252124
189.6	59.92354	0.00225617
189.8	59.96355	0.002260242
190	60.00356	0.002264235
190.2	60.04356	0.002268624
190.4	60.08358	0.002272812
190.6	60.12358	0.002277059
190.8	60.16358	0.002281407
191	60.20358	0.00228562
191.2	60.24356	0.002289944
191.4	60.28352	0.002294241
191.6	60.32349	0.002298469
191.8	60.36346	0.002302826
192	60.40343	0.002306917
192.2	60.44341	0.002311236
192.4	60.48342	0.002315649
192.6	60.52343	0.002319946
192.8	60.56344	0.002324391
193	60.60341	0.002328741
193.2	60.64342	0.002333193
193.4	60.68343	0.002337597
193.6	60.72346	0.002341951
193.8	60.76349	0.002346319
194	60.80352	0.002350488
194.2	60.84357	0.002355069
194.4	60.88357	0.002359406
194.6	60.9236	0.002363572
194.8	60.96362	0.002368177
195	61.00369	0.002372436
195.2	61.04377	0.002376961
195.4	61.08385	0.002381347
195.6	61.12391	0.002385697
195.8	61.16397	0.002390083
196	61.20406	0.00239467
196.2	61.24416	0.002398873
196.4	61.28429	0.00240342
196.6	61.32443	0.002407864
196.8	61.36458	0.002412384
197	61.40472	0.002416806
197.2	61.44485	0.002421358
197.4	61.48498	0.002425917
197.6	61.52511	0.002430391
197.8	61.56524	0.002434966
198	61.60535	0.002439404
198.2	61.64539	0.002443869
198.4	61.68541	0.002448441
198.6	61.72541	0.002453041
198.8	61.76543	0.002457419
199	61.80539	0.002461967
199.2	61.84532	0.002466487
199.4	61.88521	0.002471056
199.6	61.92516	0.002475651
199.8	61.96533	0.002480327
199.9	61.98511	0.002482403