File: inner experiment data/Mn3.1/1-6-3.txt
#EXPORTTYPE:DATA SINGLE
#FILE:C.ngb-sla
#FORMAT:NETZSCH5
#FTYPE:ANSI
#IDENTITY:C-2
#DECIMAL:POINT
#SEPARATOR:SEMICOLON
#MTYPE:DIL
#INSTRUMENT:NETZSCH DIL 402SE
#PROJECT:1
#DATE/TIME:10.12.2019 18:53
#CORR. FILE:
#TEMPCAL:TCALZERO.TMX
#LABORATORY:1
#OPERATOR:1
#REMARK:
#SAMPLE:C-2
#SAMPLE LENGTH /mm:23.86
#MATERIAL:Ã’¥…
#MEASMODE:Standard Expansion
#M.RANGE /¶Ãm:20000
#CORR. CODE:010
#RANGE:-110°„C/5.0(K/min)/200°„C
#SEGMENT:S1/1
#SEG. 1:-110°„C/5.0(K/min)/200°„C

##Temp./°„C	Time/min	dL/Lo
-100	2.20313	-0.00012885
-99.8	2.242	-0.000128963
-99.6	2.28049	-0.000128973
-99.4	2.3187	-0.000128983
-99.2	2.35662	-0.000128987
-99	2.39434	-0.000128937
-98.8	2.432	-0.00012874
-98.6	2.46949	-0.000128674
-98.4	2.50699	-0.000128397
-98.2	2.54447	-0.000128247
-98	2.58193	-0.000128022
-97.8	2.61947	-0.00012769
-97.6	2.65714	-0.000127337
-97.4	2.69491	-0.000126958
-97.2	2.73291	-0.000126559
-97	2.77108	-0.00012612
-96.8	2.80942	-0.000125724
-96.6	2.84792	-0.000125182
-96.4	2.88668	-0.000124648
-96.2	2.9256	-0.000123982
-96	2.96468	-0.000123441
-95.8	3.00398	-0.000122729
-95.6	3.04341	-0.000122114
-95.4	3.08304	-0.000121353
-95.2	3.12276	-0.000120612
-95	3.16259	-0.00011974
-94.8	3.20253	-0.000118983
-94.6	3.24258	-0.000118132
-94.4	3.28266	-0.000117172
-94.2	3.32282	-0.000116307
-94	3.36301	-0.000115394
-93.8	3.40322	-0.000114436
-93.6	3.44341	-0.000113399
-93.4	3.48356	-0.000112405
-93.2	3.52366	-0.000111382
-93	3.56375	-0.000110359
-92.8	3.60385	-0.000109121
-92.6	3.64388	-0.000108013
-92.4	3.68389	-0.000106875
-92.2	3.72379	-0.0001064
-92	3.76367	-0.000105405
-91.8	3.80349	-0.000104343
-91.6	3.84329	-0.000103129
-91.4	3.88303	-0.000101972
-91.2	3.9228	-0.000100709
-91	3.96261	-9.94766E-05
-90.8	4.00238	-9.81741E-05
-90.6	4.04207	-9.68333E-05
-90.4	4.08179	-9.55278E-05
-90.2	4.1215	-9.41839E-05
-90	4.16126	-9.28522E-05
-89.8	4.20103	-9.15962E-05
-89.6	4.24088	-9.01658E-05
-89.4	4.2807	-8.87785E-05
-89.2	4.32055	-8.73512E-05
-89	4.36033	-8.59208E-05
-88.8	4.40012	-8.4492E-05
-88.6	4.43998	-8.30202E-05
-88.4	4.47984	-8.15486E-05
-88.2	4.51969	-8.00759E-05
-88	4.55952	-7.85217E-05
-87.8	4.59942	-7.70462E-05
-87.6	4.63925	-7.54899E-05
-87.4	4.6791	-7.38139E-05
-87.2	4.71891	-7.24156E-05
-87	4.75873	-7.07774E-05
-86.8	4.79851	-6.93567E-05
-86.6	4.83829	-6.76796E-05
-86.4	4.87807	-6.60862E-05
-86.2	4.9178	-6.44933E-05
-86	4.95752	-6.28167E-05
-85.8	4.9972	-6.11848E-05
-85.6	5.03684	-5.95054E-05
-85.4	5.07644	-5.77814E-05
-85.2	5.11606	-5.61961E-05
-85	5.15565	-5.44819E-05
-84.8	5.19525	-5.28097E-05
-84.6	5.2348	-5.11435E-05
-84.4	5.27433	-4.94184E-05
-84.2	5.31386	-4.77555E-05
-84	5.35337	-4.60604E-05
-83.8	5.3929	-4.43387E-05
-83.6	5.43242	-4.25857E-05
-83.4	5.47192	-4.09068E-05
-83.2	5.51144	-3.91917E-05
-83	5.55098	-3.74982E-05
-82.8	5.59053	-3.57559E-05
-82.6	5.63009	-3.39294E-05
-82.4	5.66967	-3.21434E-05
-82.2	5.70919	-3.04971E-05
-82	5.74873	-2.86545E-05
-81.8	5.78828	-2.69052E-05
-81.6	5.82779	-2.51488E-05
-81.4	5.86732	-2.35133E-05
-81.2	5.90686	-2.17124E-05
-81	5.94635	-2.00789E-05
-80.8	5.98581	-1.82023E-05
-80.6	6.02528	-1.65214E-05
-80.4	6.06471	-1.4659E-05
-80.2	6.10414	-1.29902E-05
-80	6.14362	-1.11185E-05
-79.8	6.18306	-9.36765E-06
-79.6	6.22248	-7.56733E-06
-79.4	6.26193	-5.82799E-06
-79.2	6.30135	-4.01181E-06
-79	6.34076	-2.07979E-06
-78.8	6.38014	-2.46388E-07
-78.6	6.41952	1.57583E-06
-78.4	6.45889	3.4622E-06
-78.2	6.49824	5.33076E-06
-78	6.53759	7.17592E-06
-77.8	6.57687	9.02796E-06
-77.6	6.61621	1.09985E-05
-77.4	6.65552	1.29204E-05
-77.2	6.6948	1.48398E-05
-77	6.73408	1.67933E-05
-76.8	6.77338	1.86649E-05
-76.6	6.81272	2.0663E-05
-76.4	6.85206	2.24601E-05
-76.2	6.89144	2.45131E-05
-76	6.93082	2.63572E-05
-75.8	6.97021	2.84067E-05
-75.6	7.00965	3.02368E-05
-75.4	7.04906	3.21715E-05
-75.2	7.08848	3.41384E-05
-75	7.12793	3.60072E-05
-74.8	7.16735	3.80067E-05
-74.6	7.20679	3.99308E-05
-74.4	7.24625	4.19083E-05
-74.2	7.28571	4.38354E-05
-74	7.32516	4.58306E-05
-73.8	7.36464	4.77265E-05
-73.6	7.40409	4.96765E-05
-73.4	7.44357	5.16616E-05
-73.2	7.48306	5.36778E-05
-73	7.5226	5.56024E-05
-72.8	7.56214	5.75227E-05
-72.6	7.60162	5.95169E-05
-72.4	7.64108	6.15274E-05
-72.2	7.68055	6.35415E-05
-72	7.72002	6.55111E-05
-71.8	7.7595	6.74787E-05
-71.6	7.79899	6.94472E-05
-71.4	7.83845	7.14616E-05
-71.2	7.87791	7.34888E-05
-71	7.91737	7.5493E-05
-70.8	7.95681	7.75187E-05
-70.6	7.99626	7.95333E-05
-70.4	8.03575	8.15619E-05
-70.2	8.07524	8.35573E-05
-70	8.11469	8.54006E-05
-69.8	8.15418	8.74923E-05
-69.6	8.19366	8.95011E-05
-69.4	8.2331	9.15453E-05
-69.2	8.27256	9.35599E-05
-69	8.31203	9.55582E-05
-68.8	8.35147	9.76122E-05
-68.6	8.39092	9.96195E-05
-68.4	8.43034	0.000101613
-68.2	8.46981	0.000103777
-68	8.50927	0.000105801
-67.8	8.54875	0.000107818
-67.6	8.58826	0.000109869
-67.4	8.62779	0.000111937
-67.2	8.66732	0.000113956
-67	8.70686	0.000115936
-66.8	8.74649	0.00011796
-66.6	8.78611	0.000119939
-66.4	8.82573	0.000122005
-66.2	8.8654	0.000123986
-66	8.90504	0.000126057
-65.8	8.94467	0.000128067
-65.6	8.98432	0.000130111
-65.4	9.02394	0.000132136
-65.2	9.06356	0.000134153
-65	9.10317	0.000136174
-64.8	9.14273	0.000138273
-64.6	9.18228	0.000140306
-64.4	9.22186	0.000142312
-64.2	9.26141	0.00014433
-64	9.30097	0.000146366
-63.8	9.34055	0.000148394
-63.6	9.38012	0.00015044
-63.4	9.41968	0.000152456
-63.2	9.45926	0.000154486
-63	9.49883	0.000156553
-62.8	9.53841	0.000158597
-62.6	9.57794	0.000160677
-62.4	9.61745	0.000162794
-62.2	9.65698	0.000164758
-62	9.69653	0.00016679
-61.8	9.73608	0.000168817
-61.6	9.77558	0.000170908
-61.4	9.81512	0.000172896
-61.2	9.85467	0.00017497
-61	9.89423	0.000177119
-60.8	9.93381	0.000179152
-60.6	9.97349	0.000181221
-60.4	10.01317	0.000183295
-60.2	10.05283	0.000185451
-60	10.09248	0.000187444
-59.8	10.13219	0.000189612
-59.6	10.17186	0.00019172
-59.4	10.21151	0.000193876
-59.2	10.25122	0.000195912
-59	10.2909	0.000198054
-58.8	10.33055	0.000200172
-58.6	10.37017	0.000202288
-58.4	10.40977	0.000204319
-58.2	10.4494	0.000206475
-58	10.48906	0.000208567
-57.8	10.52863	0.000210705
-57.6	10.56823	0.000212825
-57.4	10.60786	0.000214915
-57.2	10.64746	0.000216984
-57	10.68703	0.000219068
-56.8	10.72662	0.000221016
-56.6	10.76618	0.000223106
-56.4	10.80574	0.00022519
-56.2	10.84531	0.000227252
-56	10.88485	0.000229385
-55.8	10.92437	0.000231352
-55.6	10.96388	0.000233409
-55.4	11.00337	0.000235438
-55.2	11.04287	0.000237512
-55	11.08238	0.000239559
-54.8	11.12187	0.000241683
-54.6	11.16137	0.000243747
-54.4	11.20086	0.000245863
-54.2	11.24039	0.000247937
-54	11.27987	0.000250092
-53.8	11.31936	0.000252202
-53.6	11.35885	0.000254309
-53.4	11.39839	0.0002564
-53.2	11.4379	0.000258497
-53	11.47739	0.000260783
-52.8	11.51687	0.000262799
-52.6	11.55635	0.000265012
-52.4	11.59582	0.000267063
-52.2	11.63529	0.000269217
-52	11.67477	0.000271365
-51.8	11.71423	0.000273433
-51.6	11.75371	0.00027554
-51.4	11.79319	0.000277783
-51.2	11.83265	0.000279858
-51	11.87213	0.000282014
-50.8	11.91169	0.000284096
-50.6	11.95124	0.000286167
-50.4	11.99075	0.000288304
-50.2	12.03031	0.000290453
-50	12.06984	0.000292635
-49.8	12.10938	0.000294749
-49.6	12.14893	0.000296805
-49.4	12.18849	0.00029904
-49.2	12.22806	0.000301113
-49	12.26759	0.000303234
-48.8	12.30713	0.000305353
-48.6	12.34663	0.000307513
-48.4	12.38614	0.00030951
-48.2	12.42559	0.000311669
-48	12.46508	0.000313826
-47.8	12.50455	0.000315938
-47.6	12.54402	0.000318072
-47.4	12.5835	0.000320164
-47.2	12.62295	0.000322258
-47	12.66244	0.000324384
-46.8	12.70188	0.00032652
-46.6	12.74138	0.000328621
-46.4	12.78085	0.000330759
-46.2	12.82032	0.000332858
-46	12.85981	0.000335005
-45.8	12.89932	0.000337092
-45.6	12.93882	0.000339205
-45.4	12.97834	0.00034123
-45.2	13.01787	0.000343467
-45	13.05742	0.00034551
-44.8	13.09698	0.000347576
-44.6	13.13653	0.00034971
-44.4	13.17605	0.000351881
-44.2	13.21566	0.000354004
-44	13.25529	0.000356135
-43.8	13.29487	0.000358259
-43.6	13.3345	0.000360393
-43.4	13.3741	0.000362516
-43.2	13.41372	0.000364607
-43	13.45341	0.000366782
-42.8	13.49308	0.000368834
-42.6	13.53276	0.000370928
-42.4	13.57246	0.000372982
-42.2	13.61214	0.000375111
-42	13.65186	0.0003772
-41.8	13.6916	0.000379305
-41.6	13.73134	0.000381358
-41.4	13.77114	0.000383541
-41.2	13.81091	0.000385607
-41	13.85069	0.000387684
-40.8	13.89045	0.000389815
-40.6	13.93026	0.000391913
-40.4	13.97014	0.000393916
-40.2	14.01008	0.000396036
-40	14.05005	0.00039809
-39.8	14.09007	0.000400164
-39.6	14.13017	0.000402408
-39.4	14.1703	0.000404506
-39.2	14.21049	0.00040661
-39	14.25072	0.000408733
-38.8	14.29103	0.000410907
-38.6	14.33133	0.000412947
-38.4	14.37166	0.000415013
-38.2	14.41194	0.000417171
-38	14.45219	0.000419216
-37.8	14.49244	0.000421345
-37.6	14.53265	0.000423466
-37.4	14.5728	0.000425548
-37.2	14.61287	0.000427751
-37	14.65287	0.000429862
-36.8	14.69279	0.000432019
-36.6	14.73259	0.000434168
-36.4	14.77226	0.000436311
-36.2	14.81187	0.000438447
-36	14.85137	0.000440631
-35.8	14.89072	0.000442719
-35.6	14.92992	0.000444914
-35.4	14.96893	0.000446991
-35.2	15.00777	0.000449035
-35	15.04645	0.000451099
-34.8	15.08496	0.000453201
-34.6	15.12332	0.000455311
-34.4	15.16155	0.000457313
-34.2	15.19974	0.000459381
-34	15.23788	0.000461444
-33.8	15.27602	0.000463436
-33.6	15.31431	0.000465404
-33.4	15.35277	0.000467507
-33.2	15.39143	0.000469524
-33	15.43033	0.000471546
-32.8	15.46954	0.000473545
-32.6	15.50904	0.000475674
-32.4	15.54882	0.000477646
-32.2	15.58888	0.000479772
-32	15.6292	0.00048186
-31.8	15.66977	0.000484016
-31.6	15.71046	0.000485997
-31.4	15.75122	0.00048816
-31.2	15.79197	0.000490303
-31	15.83273	0.000492495
-30.8	15.87342	0.000494675
-30.6	15.91405	0.000496827
-30.4	15.95456	0.000498933
-30.2	15.99504	0.000501175
-30	16.03541	0.000503234
-29.8	16.07563	0.000505438
-29.6	16.11573	0.000507559
-29.4	16.15574	0.000509769
-29.2	16.19571	0.000511858
-29	16.23564	0.000514048
-28.8	16.27546	0.000516188
-28.6	16.31525	0.000518321
-28.4	16.35503	0.000520461
-28.2	16.39477	0.000522647
-28	16.43451	0.000524668
-27.8	16.47424	0.000526807
-27.6	16.51398	0.000528893
-27.4	16.55375	0.00053101
-27.2	16.59351	0.000533168
-27	16.63325	0.000535252
-26.8	16.67303	0.000537427
-26.6	16.71287	0.000539482
-26.4	16.75272	0.000541701
-26.2	16.79257	0.000543805
-26	16.83237	0.000545995
-25.8	16.87221	0.000548126
-25.6	16.9121	0.000550228
-25.4	16.95195	0.000552304
-25.2	16.99185	0.000554413
-25	17.03178	0.000556449
-24.8	17.07169	0.000558588
-24.6	17.11164	0.000560703
-24.4	17.15155	0.000562822
-24.2	17.19148	0.00056502
-24	17.23145	0.000567159
-23.8	17.27142	0.000569244
-23.6	17.3114	0.000571371
-23.4	17.35134	0.000573533
-23.2	17.39126	0.000575526
-23	17.43118	0.000577623
-22.8	17.47108	0.00057972
-22.6	17.51098	0.000581747
-22.4	17.55091	0.000583854
-22.2	17.5908	0.00058606
-22	17.63064	0.000588144
-21.8	17.6705	0.000590198
-21.6	17.71032	0.000592182
-21.4	17.75013	0.000594347
-21.2	17.78996	0.000596363
-21	17.82976	0.000598446
-20.8	17.86955	0.000600455
-20.6	17.90934	0.000602588
-20.4	17.94915	0.000604575
-20.2	17.98899	0.000606704
-20	18.02881	0.000608755
-19.8	18.06869	0.000610834
-19.6	18.10857	0.000612873
-19.4	18.14842	0.000614929
-19.2	18.18833	0.000617001
-19	18.22817	0.000619082
-18.8	18.26808	0.000621118
-18.6	18.30799	0.000623119
-18.4	18.34786	0.000625243
-18.2	18.38774	0.000627213
-18	18.42762	0.000629247
-17.8	18.46746	0.000631205
-17.6	18.50734	0.000633211
-17.4	18.54721	0.00063521
-17.2	18.58712	0.000637335
-17	18.62703	0.000639339
-16.8	18.66698	0.000641387
-16.6	18.70689	0.00064339
-16.4	18.74681	0.000645435
-16.2	18.78672	0.000647438
-16	18.82661	0.000649482
-15.8	18.86653	0.000651361
-15.6	18.90645	0.000653409
-15.4	18.94631	0.00065545
-15.2	18.98615	0.000657491
-15	19.02598	0.000659449
-14.8	19.06578	0.000661529
-14.6	19.10559	0.000663488
-14.4	19.14539	0.000665573
-14.2	19.18522	0.000667485
-14	19.22503	0.000669525
-13.8	19.26487	0.000671539
-13.6	19.30469	0.000673501
-13.4	19.34456	0.000675547
-13.2	19.3845	0.000677639
-13	19.42441	0.00067946
-12.8	19.4644	0.000681553
-12.6	19.50438	0.000683608
-12.4	19.54441	0.000685688
-12.2	19.58439	0.000687753
-12	19.62443	0.000689803
-11.8	19.66444	0.000691939
-11.6	19.7045	0.000693999
-11.4	19.74457	0.000696143
-11.2	19.7846	0.000698116
-11	19.82462	0.000700126
-10.8	19.86457	0.000702173
-10.6	19.90451	0.000704228
-10.4	19.94441	0.000706276
-10.2	19.98434	0.000708368
-10	20.02431	0.00071036
-9.8	20.06417	0.000712419
-9.6	20.10402	0.000714493
-9.4	20.14384	0.000716552
-9.2	20.18368	0.000718527
-9	20.22354	0.00072057
-8.8	20.26344	0.000722545
-8.6	20.30332	0.000724528
-8.4	20.34322	0.000726529
-8.2	20.38313	0.000728585
-8	20.42301	0.000730553
-7.8	20.46289	0.000732537
-7.6	20.5028	0.000734478
-7.4	20.54272	0.000736538
-7.2	20.58265	0.000738447
-7	20.62254	0.000740443
-6.8	20.66244	0.000742422
-6.6	20.70235	0.000744383
-6.4	20.74226	0.00074638
-6.2	20.78216	0.000748388
-6	20.82206	0.000750456
-5.8	20.86196	0.000752354
-5.6	20.90181	0.000754402
-5.4	20.94172	0.000756511
-5.2	20.98161	0.000758495
-5	21.02152	0.000760571
-4.8	21.06144	0.000762603
-4.6	21.10137	0.000764584
-4.4	21.1413	0.000766626
-4.2	21.18124	0.000768522
-4	21.22116	0.000770492
-3.8	21.26106	0.000772489
-3.6	21.30103	0.000774468
-3.4	21.34101	0.000776457
-3.2	21.38092	0.000778461
-3	21.42086	0.000780416
-2.8	21.46081	0.000782419
-2.6	21.50072	0.000784413
-2.4	21.54062	0.000786357
-2.2	21.58055	0.000788384
-2	21.62048	0.00079041
-1.8	21.66045	0.000792244
-1.6	21.70043	0.00079427
-1.4	21.74037	0.000796279
-1.2	21.78034	0.000798229
-1	21.82028	0.000800182
-0.8	21.86025	0.000802101
-0.6	21.9002	0.000804097
-0.4	21.94015	0.000805974
-0.2	21.98011	0.000807917
0	22.02006	0.00080989
0.2	22.06	0.000811824
0.4	22.09993	0.000813813
0.6	22.13983	0.000815749
0.8	22.17974	0.000817682
1	22.21968	0.000819586
1.2	22.25955	0.000821406
1.4	22.29944	0.000823338
1.6	22.33935	0.000825164
1.8	22.37922	0.000827087
2	22.41908	0.000828986
2.2	22.45894	0.0008309
2.4	22.49882	0.000832799
2.6	22.53872	0.000834732
2.8	22.57863	0.000836609
3	22.61854	0.000838512
3.2	22.65848	0.00084029
3.4	22.69842	0.000842193
3.6	22.73837	0.000844079
3.8	22.77835	0.00084598
4	22.81834	0.000847794
4.2	22.85834	0.000849674
4.4	22.89833	0.000851473
4.6	22.93833	0.000853391
4.8	22.97835	0.000855158
5	23.01832	0.000857003
5.2	23.0583	0.000858796
5.4	23.09826	0.000860645
5.6	23.13824	0.000862474
5.8	23.17822	0.000864357
6	23.21817	0.000866127
6.2	23.25809	0.000867921
6.4	23.29801	0.000869752
6.6	23.33794	0.000871535
6.8	23.37782	0.000873313
7	23.41773	0.000875161
7.2	23.45762	0.000876938
7.4	23.49751	0.000878779
7.6	23.53742	0.000880612
7.8	23.57727	0.000882348
8	23.61712	0.000884096
8.2	23.657	0.000885817
8.4	23.69692	0.000887613
8.6	23.73683	0.000889334
8.8	23.77673	0.000891116
9	23.81661	0.000892837
9.2	23.85655	0.000894619
9.4	23.89646	0.000896477
9.6	23.93636	0.00089818
9.8	23.97633	0.000899932
10	24.01632	0.000901666
10.2	24.05629	0.000903363
10.4	24.09625	0.000905139
10.6	24.13621	0.000906889
10.8	24.17616	0.000908613
11	24.21612	0.000910384
11.2	24.25607	0.000912139
11.4	24.29602	0.000913895
11.6	24.33596	0.000915643
11.8	24.37586	0.000917398
12	24.41577	0.000919065
12.2	24.45571	0.000920868
12.4	24.49565	0.000922582
12.6	24.53557	0.000924432
12.8	24.57552	0.000926045
13	24.61546	0.000927836
13.2	24.65539	0.000929576
13.4	24.69539	0.000931349
13.6	24.73536	0.000933024
13.8	24.77536	0.000934798
14	24.81539	0.000936486
14.2	24.85538	0.000938421
14.4	24.89535	0.000940018
14.6	24.93537	0.000941912
14.8	24.97537	0.000943677
15	25.01542	0.000945496
15.2	25.05547	0.00094722
15.4	25.09549	0.000948992
15.6	25.13552	0.000950719
15.8	25.17555	0.000952488
16	25.21557	0.0009543
16.2	25.25557	0.00095611
16.4	25.29559	0.000957914
16.6	25.33558	0.000959634
16.8	25.37555	0.000961484
17	25.41553	0.000963203
17.2	25.45549	0.000964873
17.4	25.49542	0.000966555
17.6	25.53533	0.000968315
17.8	25.57527	0.000969966
18	25.61517	0.00097169
18.2	25.6551	0.000973345
18.4	25.69504	0.000975225
18.6	25.73496	0.000976919
18.8	25.77494	0.000978559
19	25.81488	0.000980197
19.2	25.85485	0.000981929
19.4	25.89487	0.000983488
19.6	25.93484	0.000985247
19.8	25.97482	0.000986807
20	26.01479	0.000988502
20.2	26.05476	0.000990148
20.4	26.09472	0.000991832
20.6	26.13474	0.0009934
20.8	26.17474	0.000995123
21	26.21471	0.000996722
21.2	26.25466	0.000998416
21.4	26.29459	0.001000051
21.6	26.33456	0.001001777
21.8	26.37456	0.001003469
22	26.41458	0.00100516
22.2	26.45462	0.001006813
22.4	26.49465	0.001008451
22.6	26.53468	0.0010101
22.8	26.5747	0.001011712
23	26.61472	0.001013403
23.2	26.65477	0.001015009
23.4	26.69481	0.001016777
23.6	26.73485	0.001018477
23.8	26.77484	0.001020115
24	26.81484	0.001021724
24.2	26.85479	0.001023361
24.4	26.89476	0.001025002
24.6	26.93472	0.001026607
24.8	26.97466	0.001028243
25	27.01462	0.001029822
25.2	27.05453	0.001031381
25.4	27.09441	0.001033024
25.6	27.13433	0.001034628
25.8	27.17425	0.001036233
26	27.21417	0.001037833
26.2	27.25408	0.001039388
26.4	27.29402	0.001041028
26.6	27.33398	0.001042591
26.8	27.37391	0.001044114
27	27.41384	0.001045718
27.2	27.45379	0.001047195
27.4	27.49377	0.001048803
27.6	27.53371	0.001050322
27.8	27.57368	0.001051843
28	27.61364	0.001053406
28.2	27.65362	0.001054928
28.4	27.69363	0.00105649
28.6	27.7336	0.001058056
28.8	27.77358	0.001059578
29	27.81359	0.001061061
29.2	27.85356	0.001062497
29.4	27.89356	0.001064021
29.6	27.93358	0.001065503
29.8	27.97359	0.001066984
30	28.01359	0.001068466
30.2	28.0536	0.001069992
30.4	28.09357	0.001071512
30.6	28.13358	0.001072911
30.8	28.1736	0.001074392
31	28.21357	0.001075875
31.2	28.25355	0.001077189
31.4	28.29357	0.001078585
31.6	28.33356	0.001080112
31.8	28.37354	0.001081421
32	28.41346	0.001082987
32.2	28.45337	0.001084299
32.4	28.49337	0.001085823
32.6	28.53333	0.001087138
32.8	28.57332	0.001088536
33	28.61331	0.001089893
33.2	28.65331	0.001091417
33.4	28.69328	0.00109269
33.6	28.73323	0.001094087
33.8	28.77325	0.001095486
34	28.81333	0.001096804
34.2	28.8534	0.001098164
34.4	28.89341	0.001099439
34.6	28.9334	0.001100839
34.8	28.97337	0.001102194
35	29.01337	0.001103468
35.2	29.05333	0.001104909
35.4	29.09335	0.001106267
35.6	29.13338	0.001107501
35.8	29.17338	0.001108775
36	29.21335	0.00111009
36.2	29.25334	0.001111365
36.4	29.29335	0.001112597
36.6	29.33335	0.001113914
36.8	29.37337	0.001115147
37	29.41337	0.001116463
37.2	29.45339	0.001117655
37.4	29.49338	0.001119013
37.6	29.53337	0.001120246
37.8	29.57336	0.001121522
38	29.61331	0.001122627
38.2	29.65324	0.001123817
38.4	29.69317	0.001125092
38.6	29.73311	0.001126323
38.8	29.77303	0.001127388
39	29.81296	0.001128619
39.2	29.85286	0.001129768
39.4	29.89276	0.001130951
39.6	29.93266	0.001132056
39.8	29.97257	0.001133288
40	30.01253	0.001134395
40.2	30.05248	0.001135591
40.4	30.09243	0.001136705
40.6	30.13239	0.001137806
40.8	30.17234	0.001138876
41	30.21231	0.00114002
41.2	30.25228	0.001141046
41.4	30.29227	0.001142112
41.6	30.33226	0.001143221
41.8	30.37224	0.001144245
42	30.4122	0.001145315
42.2	30.45218	0.00114642
42.4	30.49215	0.001147454
42.6	30.53212	0.001148515
42.8	30.57206	0.001149538
43	30.61203	0.001150524
43.2	30.65197	0.001151591
43.4	30.69192	0.001152535
43.6	30.73186	0.00115352
43.8	30.77181	0.001154542
44	30.81175	0.00115552
44.2	30.85172	0.001156465
44.4	30.89168	0.001157535
44.6	30.93165	0.001158342
44.8	30.97161	0.001159344
45	31.0116	0.00116028
45.2	31.05163	0.001161223
45.4	31.09164	0.001162107
45.6	31.13165	0.001162951
45.8	31.17161	0.001163858
46	31.2116	0.001164704
46.2	31.25156	0.001165519
46.4	31.2915	0.001166415
46.6	31.33146	0.001167219
46.8	31.37142	0.001168086
47	31.41139	0.001168953
47.2	31.45132	0.001169732
47.4	31.49123	0.001170521
47.6	31.53118	0.001171338
47.8	31.57113	0.001172109
48	31.61108	0.001172799
48.2	31.65105	0.001173535
48.4	31.69105	0.001174258
48.6	31.73105	0.001174996
48.8	31.77103	0.001175738
49	31.81103	0.001176429
49.2	31.85102	0.001177129
49.4	31.89103	0.00117791
49.6	31.93101	0.001178508
49.8	31.971	0.00117917
50	32.011	0.001179788
50.2	32.05097	0.00118043
50.4	32.09097	0.001181037
50.6	32.13097	0.001181634
50.8	32.17092	0.001182195
51	32.21086	0.001182839
51.2	32.25081	0.001183312
51.4	32.29075	0.001183962
51.6	32.33071	0.001184439
51.8	32.37068	0.001185051
52	32.41065	0.001185475
52.2	32.45059	0.001185998
52.4	32.49055	0.001186491
52.6	32.5305	0.001186967
52.8	32.57051	0.001187418
53	32.61053	0.001187936
53.2	32.65052	0.0011883
53.4	32.69053	0.001188653
53.6	32.73051	0.001189054
53.8	32.77052	0.001189485
54	32.8105	0.00118979
54.2	32.85049	0.001190185
54.4	32.89045	0.001190593
54.6	32.93039	0.001190801
54.8	32.97035	0.001191119
55	33.01027	0.001191335
55.2	33.05022	0.001191593
55.4	33.09013	0.001191803
55.6	33.13008	0.001191969
55.8	33.17001	0.001192172
56	33.20995	0.001192432
56.2	33.24989	0.00119252
56.4	33.2898	0.001192703
56.6	33.32976	0.001192719
56.8	33.36971	0.001192856
57	33.40965	0.001192841			57	0.001192841
57.2	33.4496	0.001192924			51	-0.001517172	-2.97485E-05
57.4	33.48954	0.00119287
57.6	33.52943	0.001192909
57.8	33.56934	0.001192835
58	33.60925	0.001192764
58.2	33.64916	0.001192666
58.4	33.6891	0.001192639
58.6	33.72904	0.001192467
58.8	33.76898	0.00119235
59	33.80892	0.00119213
59.2	33.84886	0.001191999
59.4	33.88881	0.001191768
59.6	33.92884	0.00119149
59.8	33.96884	0.001191263
60	34.00886	0.001190874
60.2	34.0489	0.001190565
60.4	34.08897	0.001190198
60.6	34.12908	0.001189819
60.8	34.16918	0.001189385
61	34.20926	0.001189032
61.2	34.24938	0.001188502
61.4	34.28947	0.001188039
61.6	34.32953	0.001187511
61.8	34.36959	0.001186928
62	34.40965	0.001186219
62.2	34.44969	0.001185645
62.4	34.4897	0.001184966
62.6	34.52966	0.00118426
62.8	34.56962	0.00118356
63	34.60957	0.001182768
63.2	34.6495	0.001182031
63.4	34.68946	0.001181261
63.6	34.7294	0.001180273
63.8	34.76933	0.001179409
64	34.80929	0.001178411
64.2	34.84928	0.001177486
64.4	34.88922	0.001176456
64.6	34.92917	0.001175376
64.8	34.96916	0.001174243
65	35.00914	0.001173106
65.2	35.04916	0.001172
65.4	35.08913	0.001170691
65.6	35.12914	0.001169556
65.8	35.16918	0.00116817
66	35.20918	0.001166848
66.2	35.24921	0.001165427
66.4	35.28924	0.001164076
66.6	35.32929	0.001162562
66.8	35.3693	0.00116105
67	35.40933	0.001159465
67.2	35.44934	0.001157852
67.4	35.48937	0.001156209
67.6	35.5294	0.001154465
67.8	35.56936	0.001152719
68	35.60939	0.001150987
68.2	35.64942	0.001149071
68.4	35.68941	0.00114728
68.6	35.72943	0.001145243
68.8	35.76945	0.001143238
69	35.8095	0.001141031
69.2	35.84955	0.001138891
69.4	35.8896	0.001136637
69.6	35.92963	0.001134426
69.8	35.96975	0.0011321
70	36.00979	0.001129716
70.2	36.04985	0.001127225
70.4	36.08996	0.001124717
70.6	36.12998	0.001122084
70.8	36.17004	0.001119418
71	36.21004	0.001116593
71.2	36.25002	0.001113793
71.4	36.29002	0.001110878
71.6	36.33003	0.001107904
71.8	36.37002	0.001104869
72	36.41003	0.001101705
72.2	36.44999	0.001098406
72.4	36.48997	0.001095236
72.6	36.52994	0.001091711
72.8	36.56993	0.00108816
73	36.60994	0.001084581
73.2	36.64995	0.001080861
73.4	36.68996	0.001077127
73.6	36.72996	0.001073223
73.8	36.76993	0.001069324
74	36.80989	0.001065159
74.2	36.84984	0.001061009
74.4	36.88982	0.001056757
74.6	36.92976	0.001052544
74.8	36.96971	0.001048057
75	37.00966	0.001043551
75.2	37.04962	0.00103897
75.4	37.08955	0.00103444
75.6	37.12954	0.001029642
75.8	37.16952	0.001025019
76	37.20954	0.001020003
76.2	37.2496	0.001014831
76.4	37.28967	0.001009644
76.6	37.32974	0.001004304
76.8	37.36985	0.000998814
77	37.40998	0.00099323
77.2	37.45013	0.000987514
77.4	37.49027	0.000981822
77.6	37.53043	0.000975966
77.8	37.57058	0.000970116
78	37.61071	0.000964019
78.2	37.6508	0.000958008
78.4	37.69087	0.000951822
78.6	37.73094	0.000945517
78.8	37.77099	0.000939223
79	37.81101	0.000932637
79.2	37.85099	0.000926089
79.4	37.89096	0.000919263
79.6	37.93089	0.000912157
79.8	37.97082	0.000905037
80	38.01076	0.000897762
80.2	38.05069	0.000890318
80.4	38.09063	0.000882823
80.6	38.13057	0.000875095
80.8	38.1705	0.000867123
81	38.21045	0.000859008
81.2	38.25039	0.000850799
81.4	38.29038	0.000842239
81.6	38.33035	0.000833693
81.8	38.37033	0.000824915
82	38.41032	0.000816023
82.2	38.45031	0.00080702
82.4	38.49035	0.000798064
82.6	38.53035	0.000788923
82.8	38.57039	0.000779414
83	38.61047	0.000769642
83.2	38.65054	0.000759854
83.4	38.69058	0.000749983
83.6	38.73067	0.000740151
83.8	38.77074	0.00073028
84	38.81084	0.000720313
84.2	38.8509	0.000710164
84.4	38.89095	0.000699826
84.6	38.93099	0.000689355
84.8	38.97101	0.00067868
85	39.011	0.000667901
85.2	39.05098	0.000656912
85.4	39.09101	0.000645882
85.6	39.13101	0.000634601
85.8	39.17102	0.000623194
86	39.21098	0.00061162
86.2	39.25098	0.000599936
86.4	39.29097	0.000588061
86.6	39.33097	0.000576115
86.8	39.371	0.000564433
87	39.41101	0.000552591
87.2	39.45103	0.000540434
87.4	39.49105	0.000528187
87.6	39.53108	0.000515911
87.8	39.57107	0.000503841
88	39.61103	0.000491604
88.2	39.65098	0.000479326
88.4	39.69093	0.000466886
88.6	39.73087	0.00045445
88.8	39.77078	0.000441736
89	39.81069	0.000429007
89.2	39.8506	0.000416031
89.4	39.89052	0.000403007
89.6	39.93039	0.000389833
89.8	39.97032	0.000376555
90	40.01023	0.000363294
90.2	40.0502	0.000350015
90.4	40.09012	0.000336938
90.6	40.13004	0.000324343
90.8	40.16999	0.000311291
91	40.20996	0.000298118
91.2	40.2499	0.000284966
91.4	40.28982	0.000272253
91.6	40.32977	0.000259481
91.8	40.36968	0.000246689
92	40.40958	0.000233992
92.2	40.4495	0.000221142
92.4	40.48942	0.000208326
92.6	40.52931	0.000195463
92.8	40.56921	0.000182827
93	40.60905	0.000170094
93.2	40.64888	0.000157464
93.4	40.68874	0.000144973
93.6	40.7286	0.00013263
93.8	40.76843	0.000120443
94	40.80822	0.000108438
94.2	40.84805	9.69953E-05
94.4	40.88783	8.53576E-05
94.6	40.92756	7.36776E-05
94.8	40.96731	6.20986E-05
95	41.0071	5.0786E-05
95.2	41.04686	3.96983E-05
95.4	41.08665	2.87735E-05
95.6	41.12645	1.79071E-05
95.8	41.16626	7.01697E-06
96	41.20609	-3.64922E-06
96.2	41.24597	-1.43407E-05
96.4	41.28586	-2.49311E-05
96.6	41.32581	-3.54375E-05
96.8	41.36574	-4.57643E-05
97	41.40568	-5.59389E-05
97.2	41.44562	-6.60346E-05
97.4	41.48561	-7.60614E-05
97.6	41.52554	-8.58731E-05
97.8	41.56546	-9.54358E-05
98	41.60538	-0.000104917
98.2	41.64525	-0.000114129
98.4	41.6851	-0.000123122
98.6	41.72494	-0.000131671
98.8	41.76478	-0.000140094
99	41.80458	-0.000148391
99.2	41.8444	-0.000156664
99.4	41.88416	-0.000164593
99.6	41.92396	-0.000172539
99.8	41.96374	-0.00018012
100	42.00353	-0.000187414
100.2	42.04331	-0.000194542
100.4	42.08315	-0.000201558
100.6	42.12297	-0.000208279
100.8	42.1628	-0.000214793
101	42.20262	-0.000221057
101.2	42.24249	-0.000227063
101.4	42.28238	-0.000233094
101.6	42.32227	-0.000238812
101.8	42.36218	-0.000244584
102	42.40208	-0.000250014
102.2	42.442	-0.000255237
102.4	42.48191	-0.000260336
102.6	42.5218	-0.000265275
102.8	42.56173	-0.000269832
103	42.60167	-0.00027423
103.2	42.64156	-0.00027832
103.4	42.68143	-0.000282376
103.6	42.72127	-0.000286089
103.8	42.76113	-0.000289863
104	42.80098	-0.000293241
104.2	42.84082	-0.000296413
104.4	42.88064	-0.000299548
104.6	42.92049	-0.000302394
104.8	42.96036	-0.000305074
105	43.00017	-0.000307499
105.2	43.04005	-0.000309889
105.4	43.07994	-0.000312113
105.6	43.11982	-0.000314044
105.8	43.15972	-0.000315766
106	43.19961	-0.000317321
106.2	43.23952	-0.000318873
106.4	43.27946	-0.0003201
106.6	43.31937	-0.000321159
106.8	43.35925	-0.000322047
107	43.3992	-0.00032302
107.2	43.43912	-0.000323533
107.4	43.47903	-0.000323955
107.6	43.51899	-0.000324304
107.8	43.55894	-0.000324403
108	43.59894	-0.000324331
108.2	43.63894	-0.000324244
108.4	43.67891	-0.00032446
108.6	43.71887	-0.000324109
108.8	43.75886	-0.000323736
109	43.79882	-0.000323332
109.2	43.83875	-0.000322679
109.4	43.87871	-0.00032185
109.6	43.91865	-0.000320698
109.8	43.95862	-0.000319417
110	43.99858	-0.000318205
110.2	44.03848	-0.000316845
110.4	44.0784	-0.000315307
110.6	44.11837	-0.000313637
110.8	44.15832	-0.000312056
111	44.19829	-0.000310178
111.2	44.23828	-0.000308312
111.4	44.27824	-0.000306162
111.6	44.3182	-0.000304033
111.8	44.35816	-0.000301805
112	44.3981	-0.00029953
112.2	44.43808	-0.000297099
112.4	44.47808	-0.00029461
112.6	44.51811	-0.000292048
112.8	44.5581	-0.000289504
113	44.59813	-0.000286828
113.2	44.63817	-0.000284152
113.4	44.67824	-0.000281315
113.6	44.71831	-0.000278468
113.8	44.75837	-0.000275746
114	44.79845	-0.000272782
114.2	44.83849	-0.000269632
114.4	44.87853	-0.00026663
114.6	44.91852	-0.000263571
114.8	44.95852	-0.000260434
115	44.99847	-0.000257171
115.2	45.03842	-0.000254007
115.4	45.07842	-0.000250735
115.6	45.11841	-0.000247399
115.8	45.15835	-0.000244017
116	45.19827	-0.000240553
116.2	45.23826	-0.00023711
116.4	45.27822	-0.000233735
116.6	45.31823	-0.000230387
116.8	45.35822	-0.000226743
117	45.39821	-0.000223326
117.2	45.43822	-0.000219763
117.4	45.47822	-0.000216052
117.6	45.51821	-0.000212413
117.8	45.55819	-0.000208765
118	45.59825	-0.000205032
118.2	45.63829	-0.000201435
118.4	45.6783	-0.000197586
118.6	45.71828	-0.000193829
118.8	45.7583	-0.000189928
119	45.79833	-0.000186086
119.2	45.83833	-0.000182149
119.4	45.87832	-0.000178298
119.6	45.91833	-0.000174401
119.8	45.9584	-0.000170383
120	45.99844	-0.000166356
120.2	46.03851	-0.000162245
120.4	46.07856	-0.00015822
120.6	46.11866	-0.000154113
120.8	46.15874	-0.000149958
121	46.19886	-0.000145684
121.2	46.23898	-0.000141659
121.4	46.27908	-0.00013737
121.6	46.31916	-0.000133343
121.8	46.35921	-0.000129107
122	46.39922	-0.000125081
122.2	46.43927	-0.000120974
122.4	46.47928	-0.000116875
122.6	46.5193	-0.000112685
122.8	46.5593	-0.000108455
123	46.59928	-0.000104068
123.2	46.63926	-9.97553E-05
123.4	46.67923	-9.54426E-05
123.6	46.71922	-9.11324E-05
123.8	46.75919	-8.67342E-05
124	46.79922	-8.24216E-05
124.2	46.83925	-7.79764E-05
124.4	46.87924	-7.35431E-05
124.6	46.91923	-6.91029E-05
124.8	46.95926	-6.46631E-05
125	46.9993	-6.02204E-05
125.2	47.03936	-5.56908E-05
125.4	47.07946	-5.12789E-05
125.6	47.11954	-4.67443E-05
125.8	47.15965	-4.22921E-05
126	47.19975	-3.77176E-05
126.2	47.23983	-3.32292E-05
126.4	47.27994	-2.87337E-05
126.6	47.32004	-2.42405E-05
126.8	47.36012	-1.97079E-05
127	47.40023	-1.5256E-05
127.2	47.44028	-1.06428E-05
127.4	47.48034	-6.27907E-06
127.6	47.52041	-1.74968E-06
127.8	47.56045	2.73904E-06
128	47.60044	7.3062E-06
128.2	47.64039	1.17825E-05
128.4	47.68035	1.63869E-05
128.6	47.72031	2.08219E-05
128.8	47.76027	2.51715E-05
129	47.80024	2.95679E-05
129.2	47.8402	3.4048E-05
129.4	47.88015	3.84007E-05
129.6	47.92008	4.28758E-05
129.8	47.96005	4.73546E-05
130	48.00003	5.18359E-05
130.2	48.04004	5.62368E-05
130.4	48.08005	6.07207E-05
130.6	48.1201	6.50426E-05
130.8	48.16017	6.95744E-05
131	48.20018	7.39332E-05
131.2	48.24025	7.84232E-05
131.4	48.28032	8.30015E-05
131.6	48.32041	8.7534E-05
131.8	48.36048	9.22359E-05
132	48.40056	9.68121E-05
132.2	48.44059	0.000101343
132.4	48.48061	0.000105954
132.6	48.5206	0.000110605
132.8	48.5606	0.00011504
133	48.6006	0.000119652
133.2	48.64062	0.000124102
133.4	48.68059	0.000128664
133.6	48.72059	0.000133107
133.8	48.76058	0.000137675
134	48.80057	0.000142199
134.2	48.84058	0.000146893
134.4	48.88067	0.000151557
134.6	48.92076	0.000156252
134.8	48.9608	0.000160868
135	49.00087	0.000165615
135.2	49.04096	0.000170284
135.4	49.08101	0.000175115
135.6	49.1211	0.000179728
135.8	49.16118	0.000184636
136	49.20126	0.000189303
136.2	49.24136	0.000194125
136.4	49.28141	0.000198879
136.6	49.32148	0.000203626
136.8	49.36157	0.000208484
137	49.40162	0.000213195
137.2	49.44166	0.000218003
137.4	49.48171	0.000222754
137.6	49.52176	0.000227499
137.8	49.5618	0.000232188
138	49.60179	0.00023702
138.2	49.64179	0.000241707
138.4	49.6818	0.000246456
138.6	49.72178	0.000251174
138.8	49.76175	0.000255921
139	49.80175	0.000260692
139.2	49.84172	0.000265468
139.4	49.88172	0.00027016
139.6	49.92172	0.000274944
139.8	49.9617	0.000279596
140	50.00172	0.000284241
140.2	50.04177	0.000288895
140.4	50.0818	0.0002936
140.6	50.12185	0.000298266
140.8	50.1619	0.00030309
141	50.20198	0.000307708
141.2	50.24203	0.000312405
141.4	50.28213	0.000317123
141.6	50.32219	0.000321808
141.8	50.36225	0.000326555
142	50.40229	0.000331344
142.2	50.44233	0.000336219
142.4	50.4824	0.000341131
142.6	50.52247	0.000345928
142.8	50.56253	0.000350876
143	50.60257	0.000355719
143.2	50.64263	0.000360577
143.4	50.68266	0.000365449
143.6	50.72267	0.000370142
143.8	50.76269	0.00037498
144	50.80271	0.000379813
144.2	50.84275	0.000384591
144.4	50.88278	0.00038942
144.6	50.9228	0.000394333
144.8	50.96288	0.000399361
145	51.00297	0.000404264
145.2	51.04308	0.000409351
145.4	51.08317	0.000414285
145.6	51.12328	0.000419377
145.8	51.16336	0.000424387
146	51.20349	0.000429368
146.2	51.24362	0.000434433
146.4	51.28371	0.000439408
146.6	51.32379	0.000444407
146.8	51.36387	0.000449408
147	51.40392	0.000454416
147.2	51.44394	0.000459471
147.4	51.48399	0.000464359
147.6	51.52401	0.000469398
147.8	51.56408	0.00047438
148	51.60412	0.000479288
148.2	51.64414	0.000484213
148.4	51.68418	0.000489167
148.6	51.72421	0.00049407
148.8	51.76422	0.000499087
149	51.80421	0.000503966
149.2	51.84423	0.000508952
149.4	51.88421	0.000513949
149.6	51.92419	0.000518788
149.8	51.96414	0.000523644
150	52.0041	0.000528595
150.2	52.04405	0.000533498
150.4	52.08399	0.000538371
150.6	52.12393	0.000543325
150.8	52.16388	0.000548099
151	52.2038	0.000552989
151.2	52.24373	0.000557925
151.4	52.28366	0.000562847
151.6	52.32365	0.000567792
151.8	52.36363	0.000572836
152	52.40362	0.000577824
152.2	52.44365	0.000582842
152.4	52.48366	0.000587922
152.6	52.52368	0.000593029
152.8	52.56366	0.000598184
153	52.60374	0.000603289
153.2	52.64378	0.000608303
153.4	52.68381	0.000613463
153.6	52.72384	0.000618358
153.8	52.76388	0.000623432
154	52.80391	0.000628402
154.2	52.84389	0.000633406
154.4	52.88389	0.000638385
154.6	52.92391	0.000643628
154.8	52.96394	0.000648648
155	53.00394	0.000653836
155.2	53.04392	0.000658906
155.4	53.0839	0.000664087
155.6	53.1239	0.00066913
155.8	53.16389	0.000674297
156	53.20391	0.000679466
156.2	53.24391	0.000684593
156.4	53.28392	0.000689714
156.6	53.324	0.000694919
156.8	53.36403	0.000700032
157	53.40407	0.000705178
157.2	53.44412	0.000710269
157.4	53.48419	0.000715423
157.6	53.52423	0.000720411
157.8	53.56426	0.000725545
158	53.60428	0.000730537
158.2	53.64431	0.000735726
158.4	53.68436	0.000740774
158.6	53.72432	0.000745937
158.8	53.76429	0.000750988
159	53.80428	0.000756174
159.2	53.84426	0.000761187
159.4	53.8842	0.000766242
159.6	53.92415	0.000771254
159.8	53.96408	0.000776363
160	54.00402	0.000781402
160.2	54.04396	0.000786559
160.4	54.08384	0.000791584
160.6	54.12374	0.000796661
160.8	54.16366	0.00080171
161	54.20359	0.000806776
161.2	54.24356	0.000811935
161.4	54.28351	0.000816994
161.6	54.32347	0.00082207
161.8	54.36343	0.000827296
162	54.40343	0.000832385
162.2	54.44342	0.000837752
162.4	54.48341	0.000843005
162.6	54.52341	0.00084826
162.8	54.56342	0.000853563
163	54.60345	0.000858787
163.2	54.64343	0.000863966
163.4	54.68345	0.000869109
163.6	54.72345	0.000874154
163.8	54.76347	0.000879286
164	54.80352	0.000884336
164.2	54.84352	0.00088956
164.4	54.88355	0.000894845
164.6	54.92361	0.000900042
164.8	54.96366	0.000905261
165	55.0037	0.000910443
165.2	55.04371	0.000915631
165.4	55.08375	0.000920842
165.6	55.12379	0.000926082
165.8	55.1638	0.000931386
166	55.20381	0.000936563
166.2	55.24388	0.000941729
166.4	55.28393	0.000946963
166.6	55.32395	0.000952091
166.8	55.36398	0.000957278
167	55.404	0.00096236
167.2	55.444	0.000967564
167.4	55.484	0.000972684
167.6	55.52405	0.000977914
167.8	55.56408	0.00098286
168	55.60411	0.000988071
168.2	55.64409	0.000993082
168.4	55.68409	0.000998212
168.6	55.72407	0.001003332
168.8	55.76406	0.001008503
169	55.80405	0.001013533
169.2	55.84402	0.001018707
169.4	55.88405	0.001023731
169.6	55.92403	0.001028851
169.8	55.96398	0.001033924
170	56.00402	0.001038943
170.2	56.04401	0.00104408
170.4	56.084	0.001049185
170.6	56.12398	0.001054186
170.8	56.16396	0.001059301
171	56.20391	0.001064341
171.2	56.24393	0.001069543
171.4	56.28393	0.001074732
171.6	56.32395	0.001080013
171.8	56.36395	0.001085295
172	56.40393	0.001090582
172.2	56.44387	0.001095818
172.4	56.48381	0.001100963
172.6	56.52376	0.001106249
172.8	56.56372	0.001111477
173	56.60368	0.001116526
173.2	56.64364	0.00112173
173.4	56.68355	0.00112686
173.6	56.72345	0.001131919
173.8	56.76337	0.001137132
174	56.80329	0.001142347
174.2	56.84324	0.001147672
174.4	56.88317	0.001152949
174.6	56.92315	0.001158222
174.8	56.96308	0.001163511
175	57.00307	0.00116864
175.2	57.04304	0.001173937
175.4	57.083	0.001179222
175.6	57.12297	0.001184455
175.8	57.16294	0.001189715
176	57.20288	0.001194992
176.2	57.24284	0.00120022
176.4	57.2828	0.001205362
176.6	57.3228	0.001210708
176.8	57.36277	0.001215824
177	57.40273	0.001221098
177.2	57.44269	0.001226254
177.4	57.48269	0.00123148
177.6	57.52271	0.001236712
177.8	57.56269	0.001241922
178	57.60268	0.00124723
178.2	57.64271	0.001252462
178.4	57.68275	0.001257716
178.6	57.72276	0.001262889
178.8	57.7628	0.001268066
179	57.80281	0.00127327
179.2	57.84283	0.001278461
179.4	57.88286	0.001283694
179.6	57.92288	0.001288819
179.8	57.96293	0.001294032
180	58.00297	0.001299291
180.2	58.043	0.001304548
180.4	58.08304	0.001309756
180.6	58.12304	0.001315051
180.8	58.16306	0.00132025
181	58.20312	0.001325697
181.2	58.24316	0.001330973
181.4	58.28323	0.001336373
181.6	58.32332	0.001341777
181.8	58.36341	0.001347136
182	58.40346	0.00135252
182.2	58.44353	0.001357848
182.4	58.48358	0.001363018
182.6	58.52363	0.001368293
182.8	58.56371	0.001373448
183	58.60377	0.001378615
183.2	58.64381	0.001383898
183.4	58.68384	0.001389222
183.6	58.72383	0.001394621
183.8	58.76383	0.001400091
184	58.80383	0.001405516
184.2	58.84384	0.00141092
184.4	58.88386	0.001416293
184.6	58.9239	0.001421675
184.8	58.96394	0.001427106
185	59.00399	0.001432461
185.2	59.04405	0.001437906
185.4	59.0841	0.001443282
185.6	59.12416	0.001448622
185.8	59.1642	0.001453938
186	59.20424	0.001459315
186.2	59.24427	0.001464661
186.4	59.28428	0.001470003
186.6	59.32428	0.001475353
186.8	59.36425	0.00148075
187	59.40421	0.00148602
187.2	59.44419	0.001491353
187.4	59.48413	0.001496679
187.6	59.52409	0.00150206
187.8	59.56403	0.001507218
188	59.60398	0.001512548
188.2	59.64397	0.001517734
188.4	59.68391	0.001522985
188.6	59.72388	0.001528207
188.8	59.76386	0.001533516
189	59.80386	0.001538707
189.2	59.84379	0.001543997
189.4	59.88373	0.001549204
189.6	59.92365	0.001554461
189.8	59.96359	0.001559666
190	60.0035	0.001564962
190.2	60.0434	0.001570174
190.4	60.08328	0.001575517
190.6	60.12324	0.001580913
190.8	60.16314	0.001586329
191	60.2031	0.001591759
191.2	60.24304	0.001597158
191.4	60.28303	0.001602513
191.6	60.32304	0.001607909
191.8	60.36304	0.001613154
192	60.4031	0.001618451
192.2	60.44315	0.001623711
192.4	60.4832	0.001628843
192.6	60.52325	0.001634255
192.8	60.56329	0.00163983
193	60.60331	0.001645239
193.2	60.64336	0.001650681
193.4	60.68337	0.001656222
193.6	60.72339	0.001661662
193.8	60.76333	0.001667101
194	60.80326	0.001672569
194.2	60.8432	0.001678004
194.4	60.88316	0.001683558
194.6	60.92309	0.001689038
194.8	60.96301	0.001694546
195	61.00296	0.001700018
195.2	61.04291	0.001705472
195.4	61.08288	0.001710875
195.6	61.12285	0.001716304
195.8	61.16284	0.001721645
196	61.20289	0.001727091
196.2	61.24294	0.001732415
196.4	61.28298	0.001737839
196.6	61.32304	0.001743248
196.8	61.36313	0.001748593
197	61.40319	0.001753954
197.2	61.44321	0.001759224
197.4	61.48329	0.001764492
197.6	61.52335	0.001769736
197.8	61.56344	0.001774931
198	61.60349	0.001780224
198.2	61.6435	0.001785414
198.4	61.68352	0.00179062
198.6	61.72356	0.0017958
198.8	61.76355	0.001800991
199	61.80358	0.001806265
199.2	61.84359	0.001811386
199.4	61.88354	0.001816689
199.6	61.92351	0.001822044
199.8	61.96349	0.001827467
199.9	61.98349	0.001830105